Workbook

Sheet Tarif
B2: CCП
B3: Nima? | D3: CCП - biznesingizni balanslashgan ko'rsatkichlar tizimi.
B4: Nima uchun kerak? | D4: 1. Biznesingizni har bir bo'limidagi ishlarni necha foiz muhimlikda ekanligini , har bir bo'limning biznes uchun muhimliligi qanchaligini belgilab berish orqali rejada belgilangan vazifalarni faktda qancha foizi bajarilganligi ko'rib turishingiz mumkin. 2. Rejaning qancha qismi bajarilganligiga qarab har bir bo'limga jamoaviy va har bir xodimga individual bonuslar belgilanadi . 3. Qaysidir bo'lim o'z vazifasini yaxshi bajara olmayotgan bo'lsa , o'sha bo'limni muhimlilik darajasini ko'paytirish orqali shu bo'limni ko'rsatkichlarini yaxshilashga erishish mumkin. Xodimlar rejani bajara olishmasa kamroq bonus olishlarini yoki umuman bonus berilmasligini bilib ishga masuliyat bilan yondashishadi.
B12: Agar foydalanilmasa, qanday muammolar yuzaga kelishi mumkin? | D12: 1. Nima raqamga bog'lanmagan bo'lsa uni yaxshilab bo'lmaydi. 2. Ishxonada reja bajarilmayotganligini sababini bilolmay barcha bo'limlarga bir xil jazo belgilanadi , o'z ishini reja bo'yicha zo'r bajarib qo'yganlar ham birdek jazolanadi, tabiiyki bunda ularni ishga bo'lgan motivatsiyasi tushib ketadi . 3. Qaysi bo'limga qancha jamoaviy bonus , qaysi xodimga qancha individual bonus berish kerakligini bilmaysiz , hammaga bir xilda kam bersangiz rejani bajarganlar keyin ishlagisini kelmay qoladi , hammaga bir xilda ko'proq bersangiz rejani bajarmaganlarni dangasaligini , ishga bo'lgan masuliyatsizligini rag'batlantirgan bo'lasiz , keyinchalik ular sh yana shu tarzda davom etaverishadi.

Sheet ССП
E2: Muddatni tanlang → | F2: Chorak 2
E4: Metrika (ko'rsatkichlar) | G4: SUM | H4: % bajarilish | I4: Muhimligi | J4: Foizlari | K4: Bo'lim foizlari | L4: Bo'lim muhimligi | M4: Natija
C5: Marketing | D5: 1 | E5: Ko'rgan odamlar soni | F5: Reja | G5: {=INDEX(Metrika!G8:GZ532, , MATCH(F2, Metrika!$G$7:$GZ$7, 0))} -> 21000 | H5: =IFERROR(G6/G5,"") -> 0.99761905 | I5: 0.2 | J5: =H5*I5 -> 0.19952381 | K5: =SUM(J5:J10) -> 0.89238095 | L5: 0.2 | M5: =K5*L5 -> 0.17847619 | N5: =SUM(M5:M30) -> 0.73224426
F6: Fakt | G6: 20950
D7: 2 | E7: Qiziqqan odamlar soni | F7: Reja | G7: 4200 | H7: =IFERROR(G8/G7,"") -> 0.91666667 | I7: 0.3 | J7: =H7*I7 -> 0.275
F8: Fakt | G8: 3850
D9: 3 | E9: Tushurilgan yangi lidlar soni | F9: Reja | G9: 840 | H9: =IFERROR(G10/G9,"") -> 0.83571429 | I9: 0.5 | J9: =H9*I9 -> 0.41785714
F10: Fakt | G10: 702
C11: Sotuv | D11: 1 | E11: Qilingan yangi qo'ng'iroqlar soni | F11: Reja | G11: 588 | H11: =IFERROR(G12/G11,"") -> 0.78911565 | I11: 0.2 | J11: =H11*I11 -> 0.15782313 | K11: =SUM(J11:J16) -> 0.72603741 | L11: 0.3 | M11: =K11*L11 -> 0.21781122
F12: Fakt | G12: 464
D13: 2 | E13: Probniyga yangi kelganlar soni | F13: Reja | G13: 420 | H13: =IFERROR(G14/G13,"") -> 0.79285714 | I13: 0.3 | J13: =H13*I13 -> 0.23785714
F14: Fakt | G14: 333
D15: 3 | E15: Qilingan yangi to'lovlar soni | F15: Reja | G15: 168 | H15: =IFERROR(G16/G15,"") -> 0.66071429 | I15: 0.5 | J15: =H15*I15 -> 0.33035714
F16: Fakt | G16: 111
C17: Product | D17: 1 | E17: Konsultatsiya olgan mijozlar soni | F17: Reja | G17: 504 | H17: =IFERROR(G18/G17,"") -> 0.77579365 | I17: 0.2 | J17: =H17*I17 -> 0.15515873 | K17: =SUM(J17:J22) -> 0.58998016 | L17: 0.3 | M17: =K17*L17 -> 0.17699405
F18: Fakt | G18: 391
D19: 2 | E19: O'qiyotgan yangi o'quvchilar soni | F19: Reja | G19: 336 | H19: =IFERROR(G20/G19,"") -> 0.72916667 | I19: 0.3 | J19: =H19*I19 -> 0.21875
F20: Fakt | G20: 245
D21: 3 | E21: Sarafan orqali kelgan mijozlar soni | F21: Reja | G21: 168 | H21: =IFERROR(G22/G21,"") -> 0.7202381 | I21: 0.3 | J21: =H21*I21 -> 0.21607143
F22: Fakt | G22: 121
D23: 4 | E23: O'qiyotgan umumiy o'quvchilar soni | F23: Reja | G23: 600 | H23: =IFERROR(G24/G23,"") -> 0.84666667 | I23: 0.2 | J23: =H23*I23 -> 0.16933333
F24: Fakt | G24: 508
C25: Moliya | D25: 1 | E25: Daromadlar | F25: Reja | G25: 84000000 | H25: =IFERROR(G26/G25,"") -> 0.86190476 | I25: 0.45 | J25: =H25*I25 -> 0.38785714 | K25: =SUM(J25:J30) -> 0.79481399 | L25: 0.2 | M25: =K25*L25 -> 0.1589628
F26: Fakt | G26: 72400000
D27: 2 | E27: Xarajatlar | F27: Reja | G27: 16800000 | H27: =IFERROR(G28/G27,"") -> 0.8452381 | I27: 0.1 | J27: =H27*I27 -> 0.08452381
F28: Fakt | G28: 14200000
D29: 3 | E29: Foyda tushumi | F29: Reja | G29: 67200000 | H29: =IFERROR(G30/G29,"") -> 0.71651786 | I29: 0.45 | J29: =H29*I29 -> 0.32243304
F30: Fakt | G30: 48150000

Sheet Metrika
G2: 3 yillik
G3: SUM | H3: Yillik 1 | BW3: Yillik 2 | EL3: Yillik 3
H4: SUM | I4: Yarim yillik 1 | AP4: Yarim yillik 2 | BW4: SUM | BX4: Yarim yillik 3 | DE4: Yarim yillik 4 | EL4: SUM | EM4: Yarim yillik 5 | FT4: Yarim yillik 6
I5: SUM | J5: Chorak 1 | Z5: Chorak 2 | AP5: SUM | AQ5: Chorak 3 | BG5: Chorak 4 | BX5: SUM | BY5: Chorak 5 | CO5: Chorak 6 | DE5: SUM | DF5: Chorak 7 | DV5: Chorak 8 | EM5: SUM | EN5: Chorak 9 | FD5: Chorak 10 | FT5: SUM | FU5: Chorak 11 | GK5: Chorak 12
J6: SUM | K6: Oy 1 | P6: Oy 2 | U6: Oy 3 | Z6: SUM | AA6: Oy 4 | AF6: Oy 5 | AK6: Oy 6 | AQ6: SUM | AR6: Oy 7 | AW6: Oy 8 | BB6: Oy 9 | BG6: SUM | BH6: Oy 10 | BM6: Oy 11 | BR6: Oy 12 | BY6: SUM | BZ6: Oy 13 | CE6: Oy 14 | CJ6: Oy 15 | CO6: SUM | CP6: Oy 16 | CU6: Oy 17 | CZ6: Oy 18 | DF6: SUM | DG6: Oy 19 | DL6: Oy 20 | DQ6: Oy 21 | DV6: SUM | DW6: Oy 22 | EB6: Oy 23 | EG6: Oy 24 | EN6: SUM | EO6: Oy 25 | ET6: Oy 26 | EY6: Oy 27 | FD6: SUM | FE6: Oy 28 | FJ6: Oy 29 | FO6: Oy 30 | FU6: SUM | FV6: Oy 31 | GA6: Oy 32 | GF6: Oy 33 | GK6: SUM | GL6: Oy 34 | GQ6: Oy 35 | GV6: Oy 36
D7: Metrika (ko'rsatkichlar) | G7: 3 yillik | H7: Yillik 1 | I7: Yarim yillik 1 | J7: Chorak 1 | K7: Oy 1 | L7: Hafta 1 | M7: Hafta 2 | N7: Hafta 3 | O7: Hafta 4 | P7: Oy 2 | Q7: Hafta 5 | R7: Hafta 6 | S7: Hafta 7 | T7: Hafta 8 | U7: Oy 3 | V7: Hafta 9 | W7: Hafta 10 | X7: Hafta 11 | Y7: Hafta 12 | Z7: Chorak 2 | AA7: Oy 4 | AB7: Hafta 13 | AC7: Hafta 14 | AD7: Hafta 15 | AE7: Hafta 16 | AF7: Oy 5 | AG7: Hafta 17 | AH7: Hafta 18 | AI7: Hafta 19 | AJ7: Hafta 20 | AK7: Oy 6 | AL7: Hafta 21 | AM7: Hafta 22 | AN7: Hafta 23 | AO7: Hafta 24 | AP7: Yarim yillik 2 | AQ7: Chorak 3 | AR7: Oy 7 | AS7: Hafta 25 | AT7: Hafta 26 | AU7: Hafta 27 | AV7: Hafta 28 | AW7: Oy 8 | AX7: Hafta 29 | AY7: Hafta 30 | AZ7: Hafta 31 | BA7: Hafta 32 | BB7: Oy 9 | BC7: Hafta 33 | BD7: Hafta 34 | BE7: Hafta 35 | BF7: Hafta 36 | BG7: Chorak 4 | BH7: Oy 10 | BI7: Hafta 37 | BJ7: Hafta 38 | BK7: Hafta 39 | BL7: Hafta 40 | BM7: Oy 11 | BN7: Hafta 41 | BO7: Hafta 42 | BP7: Hafta 43 | BQ7: Hafta 44 | BR7: Oy 12 | BS7: Hafta 45 | BT7: Hafta 46 | BU7: Hafta 47 | BV7: Hafta 48 | BW7: Yillik 2 | BX7: Yarim yillik 3 | BY7: Chorak 5 | BZ7: Oy 13 | CA7: Hafta 49 | CB7: Hafta 50 | CC7: Hafta 51 | CD7: Hafta 52 | CE7: Oy 14 | CF7: Hafta 53 | CG7: Hafta 54 | CH7: Hafta 55 | CI7: Hafta 56 | CJ7: Oy 15 | CK7: Hafta 57 | CL7: Hafta 58 | CM7: Hafta 59 | CN7: Hafta 60 | CO7: Chorak 6 | CP7: Oy 16 | CQ7: Hafta 61 | CR7: Hafta 62 | CS7: Hafta 63 | CT7: Hafta 64 | CU7: Oy 17 | CV7: Hafta 65 | CW7: Hafta 66 | CX7: Hafta 67 | CY7: Hafta 68 | CZ7: Oy 18 | DA7: Hafta 69 | DB7: Hafta 70 | DC7: Hafta 71 | DD7: Hafta 72 | DE7: Yarim yillik 4 | DF7: Chorak 7 | DG7: Oy 19 | DH7: Hafta 73 | DI7: Hafta 74 | DJ7: Hafta 75 | DK7: Hafta 76 | DL7: Oy 20 | DM7: Hafta 77 | DN7: Hafta 78 | DO7: Hafta 79 | DP7: Hafta 80 | DQ7: Oy 21 | DR7: Hafta 81 | DS7: Hafta 82 | DT7: Hafta 83 | DU7: Hafta 84 | DV7: Chorak 8 | DW7: Oy 22 | DX7: Hafta 85 | DY7: Hafta 86 | DZ7: Hafta 87 | EA7: Hafta 88 | EB7: Oy 23 | EC7: Hafta 89 | ED7: Hafta 90 | EE7: Hafta 91 | EF7: Hafta 92 | EG7: Oy 24 | EH7: Hafta 93 | EI7: Hafta 94 | EJ7: Hafta 95 | EK7: Hafta 96 | EL7: Yillik 3 | EM7: Yarim yillik 5 | EN7: Chorak 9 | EO7: Oy 25 | EP7: Hafta 97 | EQ7: Hafta 98 | ER7: Hafta 99 | ES7: Hafta 100 | ET7: Oy 26 | EU7: Hafta 101 | EV7: Hafta 102 | EW7: Hafta 103 | EX7: Hafta 104 | EY7: Oy 27 | EZ7: Hafta 105 | FA7: Hafta 106 | FB7: Hafta 107 | FC7: Hafta 108 | FD7: Chorak 10 | FE7: Oy 28 | FF7: Hafta 109 | FG7: Hafta 110 | FH7: Hafta 111 | FI7: Hafta 112 | FJ7: Oy 29 | FK7: Hafta 113 | FL7: Hafta 114 | FM7: Hafta 115 | FN7: Hafta 116 | FO7: Oy 30 | FP7: Hafta 117 | FQ7: Hafta 118 | FR7: Hafta 119 | FS7: Hafta 120 | FT7: Yarim yillik 6 | FU7: Chorak 11 | FV7: Oy 31 | FW7: Hafta 121 | FX7: Hafta 122 | FY7: Hafta 123 | FZ7: Hafta 124 | GA7: Oy 32 | GB7: Hafta 125 | GC7: Hafta 126 | GD7: Hafta 127 | GE7: Hafta 128 | GF7: Oy 33 | GG7: Hafta 129 | GH7: Hafta 130 | GI7: Hafta 131 | GJ7: Hafta 132 | GK7: Chorak 12 | GL7: Oy 34 | GM7: Hafta 133 | GN7: Hafta 134 | GO7: Hafta 135 | GP7: Hafta 136 | GQ7: Oy 35 | GR7: Hafta 137 | GS7: Hafta 138 | GT7: Hafta 139 | GU7: Hafta 140 | GV7: Oy 36 | GW7: Hafta 141 | GX7: Hafta 142 | GY7: Hafta 143 | GZ7: Hafta 144
B8: Marketing | C8: 1 | D8: Ko'rgan odamlar soni | E8: Reja | G8: =SUM(H8:GZ8)/5 -> 252000 | H8: =SUM(I8:BV8)/4 -> 84000 | I8: =SUM(J8:AO8)/3 -> 42000 | J8: =SUM(K8:Y8)/2 -> 21000 | K8: =SUM(L8:O8) -> 7000 | L8: 1750 | M8: 1750 | N8: 1750 | O8: 1750 | P8: =SUM(Q8:T8) -> 7000 | Q8: 1750 | R8: 1750 | S8: 1750 | T8: 1750 | U8: =SUM(V8:Y8) -> 7000 | V8: 1750 | W8: 1750 | X8: 1750 | Y8: 1750 | Z8: =SUM(AA8:AO8)/2 -> 21000 | AA8: =SUM(AB8:AE8) -> 7000 | AB8: 1750 | AC8: 1750 | AD8: 1750 | AE8: 1750 | AF8: =SUM(AG8:AJ8) -> 7000 | AG8: 1750 | AH8: 1750 | AI8: 1750 | AJ8: 1750 | AK8: =SUM(AL8:AO8) -> 7000 | AL8: 1750 | AM8: 1750 | AN8: 1750 | AO8: 1750 | AP8: =SUM(AQ8:BV8)/3 -> 42000 | AQ8: =SUM(AR8:BF8)/2 -> 21000 | AR8: =SUM(AS8:AV8) -> 7000 | AS8: 1750 | AT8: 1750 | AU8: 1750 | AV8: 1750 | AW8: =SUM(AX8:BA8) -> 7000 | AX8: 1750 | AY8: 1750 | AZ8: 1750 | BA8: 1750 | BB8: =SUM(BC8:BF8) -> 7000 | BC8: 1750 | BD8: 1750 | BE8: 1750 | BF8: 1750 | BG8: =SUM(BH8:BV8)/2 -> 21000 | BH8: =SUM(BI8:BL8) -> 7000 | BI8: 1750 | BJ8: 1750 | BK8: 1750 | BL8: 1750 | BM8: =SUM(BN8:BQ8) -> 7000 | BN8: 1750 | BO8: 1750 | BP8: 1750 | BQ8: 1750 | BR8: =SUM(BS8:BV8) -> 7000 | BS8: 1750 | BT8: 1750 | BU8: 1750 | BV8: 1750 | BW8: =SUM(BX8:EK8)/4 -> 84000 | BX8: =SUM(BY8:DD8)/3 -> 42000 | BY8: =SUM(BZ8:CN8)/2 -> 21000 | BZ8: =SUM(CA8:CD8) -> 7000 | CA8: 1750 | CB8: 1750 | CC8: 1750 | CD8: 1750 | CE8: =SUM(CF8:CI8) -> 7000 | CF8: 1750 | CG8: 1750 | CH8: 1750 | CI8: 1750 | CJ8: =SUM(CK8:CN8) -> 7000 | CK8: 1750 | CL8: 1750 | CM8: 1750 | CN8: 1750 | CO8: =SUM(CP8:DD8)/2 -> 21000 | CP8: =SUM(CQ8:CT8) -> 7000 | CQ8: 1750 | CR8: 1750 | CS8: 1750 | CT8: 1750 | CU8: =SUM(CV8:CY8) -> 7000 | CV8: 1750 | CW8: 1750 | CX8: 1750 | CY8: 1750 | CZ8: =SUM(DA8:DD8) -> 7000 | DA8: 1750 | DB8: 1750 | DC8: 1750 | DD8: 1750 | DE8: =SUM(DF8:EK8)/3 -> 42000 | DF8: =SUM(DG8:DU8)/2 -> 21000 | DG8: =SUM(DH8:DK8) -> 7000 | DH8: 1750 | DI8: 1750 | DJ8: 1750 | DK8: 1750 | DL8: =SUM(DM8:DP8) -> 7000 | DM8: 1750 | DN8: 1750 | DO8: 1750 | DP8: 1750 | DQ8: =SUM(DR8:DU8) -> 7000 | DR8: 1750 | DS8: 1750 | DT8: 1750 | DU8: 1750 | DV8: =SUM(DW8:EK8)/2 -> 21000 | DW8: =SUM(DX8:EA8) -> 7000 | DX8: 1750 | DY8: 1750 | DZ8: 1750 | EA8: 1750 | EB8: =SUM(EC8:EF8) -> 7000 | EC8: 1750 | ED8: 1750 | EE8: 1750 | EF8: 1750 | EG8: =SUM(EH8:EK8) -> 7000 | EH8: 1750 | EI8: 1750 | EJ8: 1750 | EK8: 1750 | EL8: =SUM(EM8:GZ8)/4 -> 84000 | EM8: =SUM(EN8:FS8)/3 -> 42000 | EN8: =SUM(EO8:FC8)/2 -> 21000 | EO8: =SUM(EP8:ES8) -> 7000 | EP8: 1750 | EQ8: 1750 | ER8: 1750 | ES8: 1750 | ET8: =SUM(EU8:EX8) -> 7000 | EU8: 1750 | EV8: 1750 | EW8: 1750 | EX8: 1750 | EY8: =SUM(EZ8:FC8) -> 7000 | EZ8: 1750 | FA8: 1750 | FB8: 1750 | FC8: 1750 | FD8: =SUM(FE8:FS8)/2 -> 21000 | FE8: =SUM(FF8:FI8) -> 7000 | FF8: 1750 | FG8: 1750 | FH8: 1750 | FI8: 1750 | FJ8: =SUM(FK8:FN8) -> 7000 | FK8: 1750 | FL8: 1750 | FM8: 1750 | FN8: 1750 | FO8: =SUM(FP8:FS8) -> 7000 | FP8: 1750 | FQ8: 1750 | FR8: 1750 | FS8: 1750 | FT8: =SUM(FU8:GZ8)/3 -> 42000 | FU8: =SUM(FV8:GJ8)/2 -> 21000 | FV8: =SUM(FW8:FZ8) -> 7000 | FW8: 1750 | FX8: 1750 | FY8: 1750 | FZ8: 1750 | GA8: =SUM(GB8:GE8) -> 7000 | GB8: 1750 | GC8: 1750 | GD8: 1750 | GE8: 1750 | GF8: =SUM(GG8:GJ8) -> 7000 | GG8: 1750 | GH8: 1750 | GI8: 1750 | GJ8: 1750 | GK8: =SUM(GL8:GZ8)/2 -> 21000 | GL8: =SUM(GM8:GP8) -> 7000 | GM8: 1750 | GN8: 1750 | GO8: 1750 | GP8: 1750 | GQ8: =SUM(GR8:GU8) -> 7000 | GR8: 1750 | GS8: 1750 | GT8: 1750 | GU8: 1750 | GV8: =SUM(GW8:GZ8) -> 7000 | GW8: 1750 | GX8: 1750 | GY8: 1750 | GZ8: 1750
E9: Fakt | G9: =SUM(H9:GZ9)/5 -> 251940 | H9: =SUM(I9:BV9)/4 -> 83980 | I9: =SUM(J9:AO9)/3 -> 41990 | J9: =SUM(K9:Y9)/2 -> 21040 | K9: =SUM(L9:O9) -> 6950 | L9: 1700 | M9: 1740 | N9: 1760 | O9: 1750 | P9: =SUM(Q9:T9) -> 7010 | Q9: 1800 | R9: 1780 | S9: 1700 | T9: 1730 | U9: =SUM(V9:Y9) -> 7080 | V9: 1770 | W9: 1810 | X9: 1800 | Y9: 1700 | Z9: =SUM(AA9:AO9)/2 -> 20950 | AA9: =SUM(AB9:AE9) -> 7040 | AB9: 1740 | AC9: 1750 | AD9: 1770 | AE9: 1780 | AF9: =SUM(AG9:AJ9) -> 6900 | AG9: 1700 | AH9: 1710 | AI9: 1730 | AJ9: 1760 | AK9: =SUM(AL9:AO9) -> 7010 | AL9: 1740 | AM9: 1770 | AN9: 1720 | AO9: 1780 | AP9: =SUM(AQ9:BV9)/3 -> 41990 | AQ9: =SUM(AR9:BF9)/2 -> 20950 | AR9: =SUM(AS9:AV9) -> 7010 | AS9: 1740 | AT9: 1770 | AU9: 1720 | AV9: 1780 | AW9: =SUM(AX9:BA9) -> 7040 | AX9: 1740 | AY9: 1750 | AZ9: 1770 | BA9: 1780 | BB9: =SUM(BC9:BF9) -> 6900 | BC9: 1700 | BD9: 1710 | BE9: 1730 | BF9: 1760 | BG9: =SUM(BH9:BV9)/2 -> 21040 | BH9: =SUM(BI9:BL9) -> 7010 | BI9: 1800 | BJ9: 1780 | BK9: 1700 | BL9: 1730 | BM9: =SUM(BN9:BQ9) -> 7080 | BN9: 1770 | BO9: 1810 | BP9: 1800 | BQ9: 1700 | BR9: =SUM(BS9:BV9) -> 6950 | BS9: 1700 | BT9: 1740 | BU9: 1760 | BV9: 1750 | BW9: =SUM(BX9:EK9)/4 -> 83980 | BX9: =SUM(BY9:DD9)/3 -> 41990 | BY9: =SUM(BZ9:CN9)/2 -> 20950 | BZ9: =SUM(CA9:CD9) -> 6900 | CA9: 1700 | CB9: 1710 | CC9: 1730 | CD9: 1760 | CE9: =SUM(CF9:CI9) -> 7010 | CF9: 1740 | CG9: 1770 | CH9: 1720 | CI9: 1780 | CJ9: =SUM(CK9:CN9) -> 7040 | CK9: 1740 | CL9: 1750 | CM9: 1770 | CN9: 1780 | CO9: =SUM(CP9:DD9)/2 -> 21040 | CP9: =SUM(CQ9:CT9) -> 6950 | CQ9: 1700 | CR9: 1740 | CS9: 1760 | CT9: 1750 | CU9: =SUM(CV9:CY9) -> 7010 | CV9: 1800 | CW9: 1780 | CX9: 1700 | CY9: 1730 | CZ9: =SUM(DA9:DD9) -> 7080 | DA9: 1770 | DB9: 1810 | DC9: 1800 | DD9: 1700 | DE9: =SUM(DF9:EK9)/3 -> 41990 | DF9: =SUM(DG9:DU9)/2 -> 21040 | DG9: =SUM(DH9:DK9) -> 7080 | DH9: 1770 | DI9: 1810 | DJ9: 1800 | DK9: 1700 | DL9: =SUM(DM9:DP9) -> 6950 | DM9: 1700 | DN9: 1740 | DO9: 1760 | DP9: 1750 | DQ9: =SUM(DR9:DU9) -> 7010 | DR9: 1800 | DS9: 1780 | DT9: 1700 | DU9: 1730 | DV9: =SUM(DW9:EK9)/2 -> 20950 | DW9: =SUM(DX9:EA9) -> 7010 | DX9: 1740 | DY9: 1770 | DZ9: 1720 | EA9: 1780 | EB9: =SUM(EC9:EF9) -> 6900 | EC9: 1700 | ED9: 1710 | EE9: 1730 | EF9: 1760 | EG9: =SUM(EH9:EK9) -> 7040 | EH9: 1740 | EI9: 1750 | EJ9: 1770 | EK9: 1780 | EL9: =SUM(EM9:GZ9)/4 -> 83980 | EM9: =SUM(EN9:FS9)/3 -> 41990 | EN9: =SUM(EO9:FC9)/2 -> 20950 | EO9: =SUM(EP9:ES9) -> 6900 | EP9: 1700 | EQ9: 1710 | ER9: 1730 | ES9: 1760 | ET9: =SUM(EU9:EX9) -> 7040 | EU9: 1740 | EV9: 1750 | EW9: 1770 | EX9: 1780 | EY9: =SUM(EZ9:FC9) -> 7010 | EZ9: 1740 | FA9: 1770 | FB9: 1720 | FC9: 1780 | FD9: =SUM(FE9:FS9)/2 -> 21040 | FE9: =SUM(FF9:FI9) -> 6950 | FF9: 1700 | FG9: 1740 | FH9: 1760 | FI9: 1750 | FJ9: =SUM(FK9:FN9) -> 7010 | FK9: 1800 | FL9: 1780 | FM9: 1700 | FN9: 1730 | FO9: =SUM(FP9:FS9) -> 7080 | FP9: 1770 | FQ9: 1810 | FR9: 1800 | FS9: 1700 | FT9: =SUM(FU9:GZ9)/3 -> 41990 | FU9: =SUM(FV9:GJ9)/2 -> 21040 | FV9: =SUM(FW9:FZ9) -> 7080 | FW9: 1770 | FX9: 1810 | FY9: 1800 | FZ9: 1700 | GA9: =SUM(GB9:GE9) -> 6950 | GB9: 1700 | GC9: 1740 | GD9: 1760 | GE9: 1750 | GF9: =SUM(GG9:GJ9) -> 7010 | GG9: 1800 | GH9: 1780 | GI9: 1700 | GJ9: 1730 | GK9: =SUM(GL9:GZ9)/2 -> 20950 | GL9: =SUM(GM9:GP9) -> 7040 | GM9: 1740 | GN9: 1750 | GO9: 1770 | GP9: 1780 | GQ9: =SUM(GR9:GU9) -> 6900 | GR9: 1700 | GS9: 1710 | GT9: 1730 | GU9: 1760 | GV9: =SUM(GW9:GZ9) -> 7010 | GW9: 1740 | GX9: 1770 | GY9: 1720 | GZ9: 1780
C10: 2 | D10: Qiziqqan odamlar soni | E10: Reja | G10: =SUM(H10:GZ10)/5 -> 50400 | H10: =SUM(I10:BV10)/4 -> 16800 | I10: =SUM(J10:AO10)/3 -> 8400 | J10: =SUM(K10:Y10)/2 -> 4200 | K10: =SUM(L10:O10) -> 1400 | L10: 350 | M10: 350 | N10: 350 | O10: 350 | P10: =SUM(Q10:T10) -> 1400 | Q10: 350 | R10: 350 | S10: 350 | T10: 350 | U10: =SUM(V10:Y10) -> 1400 | V10: 350 | W10: 350 | X10: 350 | Y10: 350 | Z10: =SUM(AA10:AO10)/2 -> 4200 | AA10: =SUM(AB10:AE10) -> 1400 | AB10: 350 | AC10: 350 | AD10: 350 | AE10: 350 | AF10: =SUM(AG10:AJ10) -> 1400 | AG10: 350 | AH10: 350 | AI10: 350 | AJ10: 350 | AK10: =SUM(AL10:AO10) -> 1400 | AL10: 350 | AM10: 350 | AN10: 350 | AO10: 350 | AP10: =SUM(AQ10:BV10)/3 -> 8400 | AQ10: =SUM(AR10:BF10)/2 -> 4200 | AR10: =SUM(AS10:AV10) -> 1400 | AS10: 350 | AT10: 350 | AU10: 350 | AV10: 350 | AW10: =SUM(AX10:BA10) -> 1400 | AX10: 350 | AY10: 350 | AZ10: 350 | BA10: 350 | BB10: =SUM(BC10:BF10) -> 1400 | BC10: 350 | BD10: 350 | BE10: 350 | BF10: 350 | BG10: =SUM(BH10:BV10)/2 -> 4200 | BH10: =SUM(BI10:BL10) -> 1400 | BI10: 350 | BJ10: 350 | BK10: 350 | BL10: 350 | BM10: =SUM(BN10:BQ10) -> 1400 | BN10: 350 | BO10: 350 | BP10: 350 | BQ10: 350 | BR10: =SUM(BS10:BV10) -> 1400 | BS10: 350 | BT10: 350 | BU10: 350 | BV10: 350 | BW10: =SUM(BX10:EK10)/4 -> 16800 | BX10: =SUM(BY10:DD10)/3 -> 8400 | BY10: =SUM(BZ10:CN10)/2 -> 4200 | BZ10: =SUM(CA10:CD10) -> 1400 | CA10: 350 | CB10: 350 | CC10: 350 | CD10: 350 | CE10: =SUM(CF10:CI10) -> 1400 | CF10: 350 | CG10: 350 | CH10: 350 | CI10: 350 | CJ10: =SUM(CK10:CN10) -> 1400 | CK10: 350 | CL10: 350 | CM10: 350 | CN10: 350 | CO10: =SUM(CP10:DD10)/2 -> 4200 | CP10: =SUM(CQ10:CT10) -> 1400 | CQ10: 350 | CR10: 350 | CS10: 350 | CT10: 350 | CU10: =SUM(CV10:CY10) -> 1400 | CV10: 350 | CW10: 350 | CX10: 350 | CY10: 350 | CZ10: =SUM(DA10:DD10) -> 1400 | DA10: 350 | DB10: 350 | DC10: 350 | DD10: 350 | DE10: =SUM(DF10:EK10)/3 -> 8400 | DF10: =SUM(DG10:DU10)/2 -> 4200 | DG10: =SUM(DH10:DK10) -> 1400 | DH10: 350 | DI10: 350 | DJ10: 350 | DK10: 350 | DL10: =SUM(DM10:DP10) -> 1400 | DM10: 350 | DN10: 350 | DO10: 350 | DP10: 350 | DQ10: =SUM(DR10:DU10) -> 1400 | DR10: 350 | DS10: 350 | DT10: 350 | DU10: 350 | DV10: =SUM(DW10:EK10)/2 -> 4200 | DW10: =SUM(DX10:EA10) -> 1400 | DX10: 350 | DY10: 350 | DZ10: 350 | EA10: 350 | EB10: =SUM(EC10:EF10) -> 1400 | EC10: 350 | ED10: 350 | EE10: 350 | EF10: 350 | EG10: =SUM(EH10:EK10) -> 1400 | EH10: 350 | EI10: 350 | EJ10: 350 | EK10: 350 | EL10: =SUM(EM10:GZ10)/4 -> 16800 | EM10: =SUM(EN10:FS10)/3 -> 8400 | EN10: =SUM(EO10:FC10)/2 -> 4200 | EO10: =SUM(EP10:ES10) -> 1400 | EP10: 350 | EQ10: 350 | ER10: 350 | ES10: 350 | ET10: =SUM(EU10:EX10) -> 1400 | EU10: 350 | EV10: 350 | EW10: 350 | EX10: 350 | EY10: =SUM(EZ10:FC10) -> 1400 | EZ10: 350 | FA10: 350 | FB10: 350 | FC10: 350 | FD10: =SUM(FE10:FS10)/2 -> 4200 | FE10: =SUM(FF10:FI10) -> 1400 | FF10: 350 | FG10: 350 | FH10: 350 | FI10: 350 | FJ10: =SUM(FK10:FN10) -> 1400 | FK10: 350 | FL10: 350 | FM10: 350 | FN10: 350 | FO10: =SUM(FP10:FS10) -> 1400 | FP10: 350 | FQ10: 350 | FR10: 350 | FS10: 350 | FT10: =SUM(FU10:GZ10)/3 -> 8400 | FU10: =SUM(FV10:GJ10)/2 -> 4200 | FV10: =SUM(FW10:FZ10) -> 1400 | FW10: 350 | FX10: 350 | FY10: 350 | FZ10: 350 | GA10: =SUM(GB10:GE10) -> 1400 | GB10: 350 | GC10: 350 | GD10: 350 | GE10: 350 | GF10: =SUM(GG10:GJ10) -> 1400 | GG10: 350 | GH10: 350 | GI10: 350 | GJ10: 350 | GK10: =SUM(GL10:GZ10)/2 -> 4200 | GL10: =SUM(GM10:GP10) -> 1400 | GM10: 350 | GN10: 350 | GO10: 350 | GP10: 350 | GQ10: =SUM(GR10:GU10) -> 1400 | GR10: 350 | GS10: 350 | GT10: 350 | GU10: 350 | GV10: =SUM(GW10:GZ10) -> 1400 | GW10: 350 | GX10: 350 | GY10: 350 | GZ10: 350
E11: Fakt | G11: =SUM(H11:GZ11)/5 -> 48312 | H11: =SUM(I11:BV11)/4 -> 16104 | I11: =SUM(J11:AO11)/3 -> 8052 | J11: =SUM(K11:Y11)/2 -> 4202 | K11: =SUM(L11:O11) -> 1385 | L11: 330 | M11: 345 | N11: 360 | O11: 350 | P11: =SUM(Q11:T11) -> 1400 | Q11: 355 | R11: 360 | S11: 340 | T11: 345 | U11: =SUM(V11:Y11) -> 1417 | V11: 352 | W11: 365 | X11: 355 | Y11: 345 | Z11: =SUM(AA11:AO11)/2 -> 3850 | AA11: =SUM(AB11:AE11) -> 1310 | AB11: 330 | AC11: 335 | AD11: 320 | AE11: 325 | AF11: =SUM(AG11:AJ11) -> 1230 | AG11: 300 | AH11: 310 | AI11: 305 | AJ11: 315 | AK11: =SUM(AL11:AO11) -> 1310 | AL11: 320 | AM11: 325 | AN11: 330 | AO11: 335 | AP11: =SUM(AQ11:BV11)/3 -> 8052 | AQ11: =SUM(AR11:BF11)/2 -> 3850 | AR11: =SUM(AS11:AV11) -> 1310 | AS11: 320 | AT11: 325 | AU11: 330 | AV11: 335 | AW11: =SUM(AX11:BA11) -> 1310 | AX11: 330 | AY11: 335 | AZ11: 320 | BA11: 325 | BB11: =SUM(BC11:BF11) -> 1230 | BC11: 300 | BD11: 310 | BE11: 305 | BF11: 315 | BG11: =SUM(BH11:BV11)/2 -> 4202 | BH11: =SUM(BI11:BL11) -> 1400 | BI11: 355 | BJ11: 360 | BK11: 340 | BL11: 345 | BM11: =SUM(BN11:BQ11) -> 1417 | BN11: 352 | BO11: 365 | BP11: 355 | BQ11: 345 | BR11: =SUM(BS11:BV11) -> 1385 | BS11: 330 | BT11: 345 | BU11: 360 | BV11: 350 | BW11: =SUM(BX11:EK11)/4 -> 16104 | BX11: =SUM(BY11:DD11)/3 -> 8052 | BY11: =SUM(BZ11:CN11)/2 -> 3850 | BZ11: =SUM(CA11:CD11) -> 1230 | CA11: 300 | CB11: 310 | CC11: 305 | CD11: 315 | CE11: =SUM(CF11:CI11) -> 1310 | CF11: 320 | CG11: 325 | CH11: 330 | CI11: 335 | CJ11: =SUM(CK11:CN11) -> 1310 | CK11: 330 | CL11: 335 | CM11: 320 | CN11: 325 | CO11: =SUM(CP11:DD11)/2 -> 4202 | CP11: =SUM(CQ11:CT11) -> 1385 | CQ11: 330 | CR11: 345 | CS11: 360 | CT11: 350 | CU11: =SUM(CV11:CY11) -> 1400 | CV11: 355 | CW11: 360 | CX11: 340 | CY11: 345 | CZ11: =SUM(DA11:DD11) -> 1417 | DA11: 352 | DB11: 365 | DC11: 355 | DD11: 345 | DE11: =SUM(DF11:EK11)/3 -> 8052 | DF11: =SUM(DG11:DU11)/2 -> 4202 | DG11: =SUM(DH11:DK11) -> 1417 | DH11: 352 | DI11: 365 | DJ11: 355 | DK11: 345 | DL11: =SUM(DM11:DP11) -> 1385 | DM11: 330 | DN11: 345 | DO11: 360 | DP11: 350 | DQ11: =SUM(DR11:DU11) -> 1400 | DR11: 355 | DS11: 360 | DT11: 340 | DU11: 345 | DV11: =SUM(DW11:EK11)/2 -> 3850 | DW11: =SUM(DX11:EA11) -> 1310 | DX11: 320 | DY11: 325 | DZ11: 330 | EA11: 335 | EB11: =SUM(EC11:EF11) -> 1230 | EC11: 300 | ED11: 310 | EE11: 305 | EF11: 315 | EG11: =SUM(EH11:EK11) -> 1310 | EH11: 330 | EI11: 335 | EJ11: 320 | EK11: 325 | EL11: =SUM(EM11:GZ11)/4 -> 16104 | EM11: =SUM(EN11:FS11)/3 -> 8052 | EN11: =SUM(EO11:FC11)/2 -> 3850 | EO11: =SUM(EP11:ES11) -> 1230 | EP11: 300 | EQ11: 310 | ER11: 305 | ES11: 315 | ET11: =SUM(EU11:EX11) -> 1310 | EU11: 330 | EV11: 335 | EW11: 320 | EX11: 325 | EY11: =SUM(EZ11:FC11) -> 1310 | EZ11: 320 | FA11: 325 | FB11: 330 | FC11: 335 | FD11: =SUM(FE11:FS11)/2 -> 4202 | FE11: =SUM(FF11:FI11) -> 1385 | FF11: 330 | FG11: 345 | FH11: 360 | FI11: 350 | FJ11: =SUM(FK11:FN11) -> 1400 | FK11: 355 | FL11: 360 | FM11: 340 | FN11: 345 | FO11: =SUM(FP11:FS11) -> 1417 | FP11: 352 | FQ11: 365 | FR11: 355 | FS11: 345 | FT11: =SUM(FU11:GZ11)/3 -> 8052 | FU11: =SUM(FV11:GJ11)/2 -> 4202 | FV11: =SUM(FW11:FZ11) -> 1417 | FW11: 352 | FX11: 365 | FY11: 355 | FZ11: 345 | GA11: =SUM(GB11:GE11) -> 1385 | GB11: 330 | GC11: 345 | GD11: 360 | GE11: 350 | GF11: =SUM(GG11:GJ11) -> 1400 | GG11: 355 | GH11: 360 | GI11: 340 | GJ11: 345 | GK11: =SUM(GL11:GZ11)/2 -> 3850 | GL11: =SUM(GM11:GP11) -> 1310 | GM11: 330 | GN11: 335 | GO11: 320 | GP11: 325 | GQ11: =SUM(GR11:GU11) -> 1230 | GR11: 300 | GS11: 310 | GT11: 305 | GU11: 315 | GV11: =SUM(GW11:GZ11) -> 1310 | GW11: 320 | GX11: 325 | GY11: 330 | GZ11: 335
C12: 3 | D12: Tushurilgan yangi lidlar soni | E12: Reja | G12: =SUM(H12:GZ12)/5 -> 10080 | H12: =SUM(I12:BV12)/4 -> 3360 | I12: =SUM(J12:AO12)/3 -> 1680 | J12: =SUM(K12:Y12)/2 -> 840 | K12: =SUM(L12:O12) -> 280 | L12: 70 | M12: 70 | N12: 70 | O12: 70 | P12: =SUM(Q12:T12) -> 280 | Q12: 70 | R12: 70 | S12: 70 | T12: 70 | U12: =SUM(V12:Y12) -> 280 | V12: 70 | W12: 70 | X12: 70 | Y12: 70 | Z12: =SUM(AA12:AO12)/2 -> 840 | AA12: =SUM(AB12:AE12) -> 280 | AB12: 70 | AC12: 70 | AD12: 70 | AE12: 70 | AF12: =SUM(AG12:AJ12) -> 280 | AG12: 70 | AH12: 70 | AI12: 70 | AJ12: 70 | AK12: =SUM(AL12:AO12) -> 280 | AL12: 70 | AM12: 70 | AN12: 70 | AO12: 70 | AP12: =SUM(AQ12:BV12)/3 -> 1680 | AQ12: =SUM(AR12:BF12)/2 -> 840 | AR12: =SUM(AS12:AV12) -> 280 | AS12: 70 | AT12: 70 | AU12: 70 | AV12: 70 | AW12: =SUM(AX12:BA12) -> 280 | AX12: 70 | AY12: 70 | AZ12: 70 | BA12: 70 | BB12: =SUM(BC12:BF12) -> 280 | BC12: 70 | BD12: 70 | BE12: 70 | BF12: 70 | BG12: =SUM(BH12:BV12)/2 -> 840 | BH12: =SUM(BI12:BL12) -> 280 | BI12: 70 | BJ12: 70 | BK12: 70 | BL12: 70 | BM12: =SUM(BN12:BQ12) -> 280 | BN12: 70 | BO12: 70 | BP12: 70 | BQ12: 70 | BR12: =SUM(BS12:BV12) -> 280 | BS12: 70 | BT12: 70 | BU12: 70 | BV12: 70 | BW12: =SUM(BX12:EK12)/4 -> 3360 | BX12: =SUM(BY12:DD12)/3 -> 1680 | BY12: =SUM(BZ12:CN12)/2 -> 840 | BZ12: =SUM(CA12:CD12) -> 280 | CA12: 70 | CB12: 70 | CC12: 70 | CD12: 70 | CE12: =SUM(CF12:CI12) -> 280 | CF12: 70 | CG12: 70 | CH12: 70 | CI12: 70 | CJ12: =SUM(CK12:CN12) -> 280 | CK12: 70 | CL12: 70 | CM12: 70 | CN12: 70 | CO12: =SUM(CP12:DD12)/2 -> 840 | CP12: =SUM(CQ12:CT12) -> 280 | CQ12: 70 | CR12: 70 | CS12: 70 | CT12: 70 | CU12: =SUM(CV12:CY12) -> 280 | CV12: 70 | CW12: 70 | CX12: 70 | CY12: 70 | CZ12: =SUM(DA12:DD12) -> 280 | DA12: 70 | DB12: 70 | DC12: 70 | DD12: 70 | DE12: =SUM(DF12:EK12)/3 -> 1680 | DF12: =SUM(DG12:DU12)/2 -> 840 | DG12: =SUM(DH12:DK12) -> 280 | DH12: 70 | DI12: 70 | DJ12: 70 | DK12: 70 | DL12: =SUM(DM12:DP12) -> 280 | DM12: 70 | DN12: 70 | DO12: 70 | DP12: 70 | DQ12: =SUM(DR12:DU12) -> 280 | DR12: 70 | DS12: 70 | DT12: 70 | DU12: 70 | DV12: =SUM(DW12:EK12)/2 -> 840 | DW12: =SUM(DX12:EA12) -> 280 | DX12: 70 | DY12: 70 | DZ12: 70 | EA12: 70 | EB12: =SUM(EC12:EF12) -> 280 | EC12: 70 | ED12: 70 | EE12: 70 | EF12: 70 | EG12: =SUM(EH12:EK12) -> 280 | EH12: 70 | EI12: 70 | EJ12: 70 | EK12: 70 | EL12: =SUM(EM12:GZ12)/4 -> 3360 | EM12: =SUM(EN12:FS12)/3 -> 1680 | EN12: =SUM(EO12:FC12)/2 -> 840 | EO12: =SUM(EP12:ES12) -> 280 | EP12: 70 | EQ12: 70 | ER12: 70 | ES12: 70 | ET12: =SUM(EU12:EX12) -> 280 | EU12: 70 | EV12: 70 | EW12: 70 | EX12: 70 | EY12: =SUM(EZ12:FC12) -> 280 | EZ12: 70 | FA12: 70 | FB12: 70 | FC12: 70 | FD12: =SUM(FE12:FS12)/2 -> 840 | FE12: =SUM(FF12:FI12) -> 280 | FF12: 70 | FG12: 70 | FH12: 70 | FI12: 70 | FJ12: =SUM(FK12:FN12) -> 280 | FK12: 70 | FL12: 70 | FM12: 70 | FN12: 70 | FO12: =SUM(FP12:FS12) -> 280 | FP12: 70 | FQ12: 70 | FR12: 70 | FS12: 70 | FT12: =SUM(FU12:GZ12)/3 -> 1680 | FU12: =SUM(FV12:GJ12)/2 -> 840 | FV12: =SUM(FW12:FZ12) -> 280 | FW12: 70 | FX12: 70 | FY12: 70 | FZ12: 70 | GA12: =SUM(GB12:GE12) -> 280 | GB12: 70 | GC12: 70 | GD12: 70 | GE12: 70 | GF12: =SUM(GG12:GJ12) -> 280 | GG12: 70 | GH12: 70 | GI12: 70 | GJ12: 70 | GK12: =SUM(GL12:GZ12)/2 -> 840 | GL12: =SUM(GM12:GP12) -> 280 | GM12: 70 | GN12: 70 | GO12: 70 | GP12: 70 | GQ12: =SUM(GR12:GU12) -> 280 | GR12: 70 | GS12: 70 | GT12: 70 | GU12: 70 | GV12: =SUM(GW12:GZ12) -> 280 | GW12: 70 | GX12: 70 | GY12: 70 | GZ12: 70
E13: Fakt | G13: =SUM(H13:GZ13)/5 -> 9222 | H13: =SUM(I13:BV13)/4 -> 3074 | I13: =SUM(J13:AO13)/3 -> 1537 | J13: =SUM(K13:Y13)/2 -> 835 | K13: =SUM(L13:O13) -> 270 | L13: 60 | M13: 65 | N13: 70 | O13: 75 | P13: =SUM(Q13:T13) -> 255 | Q13: 70 | R13: 60 | S13: 55 | T13: 70 | U13: =SUM(V13:Y13) -> 310 | V13: 75 | W13: 80 | X13: 70 | Y13: 85 | Z13: =SUM(AA13:AO13)/2 -> 702 | AA13: =SUM(AB13:AE13) -> 237 | AB13: 55 | AC13: 56 | AD13: 62 | AE13: 64 | AF13: =SUM(AG13:AJ13) -> 214 | AG13: 50 | AH13: 52 | AI13: 54 | AJ13: 58 | AK13: =SUM(AL13:AO13) -> 251 | AL13: 60 | AM13: 62 | AN13: 65 | AO13: 64 | AP13: =SUM(AQ13:BV13)/3 -> 1537 | AQ13: =SUM(AR13:BF13)/2 -> 702 | AR13: =SUM(AS13:AV13) -> 251 | AS13: 60 | AT13: 62 | AU13: 65 | AV13: 64 | AW13: =SUM(AX13:BA13) -> 237 | AX13: 55 | AY13: 56 | AZ13: 62 | BA13: 64 | BB13: =SUM(BC13:BF13) -> 214 | BC13: 50 | BD13: 52 | BE13: 54 | BF13: 58 | BG13: =SUM(BH13:BV13)/2 -> 835 | BH13: =SUM(BI13:BL13) -> 255 | BI13: 70 | BJ13: 60 | BK13: 55 | BL13: 70 | BM13: =SUM(BN13:BQ13) -> 310 | BN13: 75 | BO13: 80 | BP13: 70 | BQ13: 85 | BR13: =SUM(BS13:BV13) -> 270 | BS13: 60 | BT13: 65 | BU13: 70 | BV13: 75 | BW13: =SUM(BX13:EK13)/4 -> 3074 | BX13: =SUM(BY13:DD13)/3 -> 1537 | BY13: =SUM(BZ13:CN13)/2 -> 702 | BZ13: =SUM(CA13:CD13) -> 214 | CA13: 50 | CB13: 52 | CC13: 54 | CD13: 58 | CE13: =SUM(CF13:CI13) -> 251 | CF13: 60 | CG13: 62 | CH13: 65 | CI13: 64 | CJ13: =SUM(CK13:CN13) -> 237 | CK13: 55 | CL13: 56 | CM13: 62 | CN13: 64 | CO13: =SUM(CP13:DD13)/2 -> 835 | CP13: =SUM(CQ13:CT13) -> 270 | CQ13: 60 | CR13: 65 | CS13: 70 | CT13: 75 | CU13: =SUM(CV13:CY13) -> 255 | CV13: 70 | CW13: 60 | CX13: 55 | CY13: 70 | CZ13: =SUM(DA13:DD13) -> 310 | DA13: 75 | DB13: 80 | DC13: 70 | DD13: 85 | DE13: =SUM(DF13:EK13)/3 -> 1537 | DF13: =SUM(DG13:DU13)/2 -> 835 | DG13: =SUM(DH13:DK13) -> 310 | DH13: 75 | DI13: 80 | DJ13: 70 | DK13: 85 | DL13: =SUM(DM13:DP13) -> 270 | DM13: 60 | DN13: 65 | DO13: 70 | DP13: 75 | DQ13: =SUM(DR13:DU13) -> 255 | DR13: 70 | DS13: 60 | DT13: 55 | DU13: 70 | DV13: =SUM(DW13:EK13)/2 -> 702 | DW13: =SUM(DX13:EA13) -> 251 | DX13: 60 | DY13: 62 | DZ13: 65 | EA13: 64 | EB13: =SUM(EC13:EF13) -> 214 | EC13: 50 | ED13: 52 | EE13: 54 | EF13: 58 | EG13: =SUM(EH13:EK13) -> 237 | EH13: 55 | EI13: 56 | EJ13: 62 | EK13: 64 | EL13: =SUM(EM13:GZ13)/4 -> 3074 | EM13: =SUM(EN13:FS13)/3 -> 1537 | EN13: =SUM(EO13:FC13)/2 -> 702 | EO13: =SUM(EP13:ES13) -> 214 | EP13: 50 | EQ13: 52 | ER13: 54 | ES13: 58 | ET13: =SUM(EU13:EX13) -> 237 | EU13: 55 | EV13: 56 | EW13: 62 | EX13: 64 | EY13: =SUM(EZ13:FC13) -> 251 | EZ13: 60 | FA13: 62 | FB13: 65 | FC13: 64 | FD13: =SUM(FE13:FS13)/2 -> 835 | FE13: =SUM(FF13:FI13) -> 270 | FF13: 60 | FG13: 65 | FH13: 70 | FI13: 75 | FJ13: =SUM(FK13:FN13) -> 255 | FK13: 70 | FL13: 60 | FM13: 55 | FN13: 70 | FO13: =SUM(FP13:FS13) -> 310 | FP13: 75 | FQ13: 80 | FR13: 70 | FS13: 85 | FT13: =SUM(FU13:GZ13)/3 -> 1537 | FU13: =SUM(FV13:GJ13)/2 -> 835 | FV13: =SUM(FW13:FZ13) -> 310 | FW13: 75 | FX13: 80 | FY13: 70 | FZ13: 85 | GA13: =SUM(GB13:GE13) -> 270 | GB13: 60 | GC13: 65 | GD13: 70 | GE13: 75 | GF13: =SUM(GG13:GJ13) -> 255 | GG13: 70 | GH13: 60 | GI13: 55 | GJ13: 70 | GK13: =SUM(GL13:GZ13)/2 -> 702 | GL13: =SUM(GM13:GP13) -> 237 | GM13: 55 | GN13: 56 | GO13: 62 | GP13: 64 | GQ13: =SUM(GR13:GU13) -> 214 | GR13: 50 | GS13: 52 | GT13: 54 | GU13: 58 | GV13: =SUM(GW13:GZ13) -> 251 | GW13: 60 | GX13: 62 | GY13: 65 | GZ13: 64
B14: Sotuv | C14: 1 | D14: Qilingan yangi qo'ng'iroqlar soni | E14: Reja | G14: =SUM(H14:GZ14)/5 -> 7056 | H14: =SUM(I14:BV14)/4 -> 2352 | I14: =SUM(J14:AO14)/3 -> 1176 | J14: =SUM(K14:Y14)/2 -> 588 | K14: =SUM(L14:O14) -> 196 | L14: 49 | M14: 49 | N14: 49 | O14: 49 | P14: =SUM(Q14:T14) -> 196 | Q14: 49 | R14: 49 | S14: 49 | T14: 49 | U14: =SUM(V14:Y14) -> 196 | V14: 49 | W14: 49 | X14: 49 | Y14: 49 | Z14: =SUM(AA14:AO14)/2 -> 588 | AA14: =SUM(AB14:AE14) -> 196 | AB14: 49 | AC14: 49 | AD14: 49 | AE14: 49 | AF14: =SUM(AG14:AJ14) -> 196 | AG14: 49 | AH14: 49 | AI14: 49 | AJ14: 49 | AK14: =SUM(AL14:AO14) -> 196 | AL14: 49 | AM14: 49 | AN14: 49 | AO14: 49 | AP14: =SUM(AQ14:BV14)/3 -> 1176 | AQ14: =SUM(AR14:BF14)/2 -> 588 | AR14: =SUM(AS14:AV14) -> 196 | AS14: 49 | AT14: 49 | AU14: 49 | AV14: 49 | AW14: =SUM(AX14:BA14) -> 196 | AX14: 49 | AY14: 49 | AZ14: 49 | BA14: 49 | BB14: =SUM(BC14:BF14) -> 196 | BC14: 49 | BD14: 49 | BE14: 49 | BF14: 49 | BG14: =SUM(BH14:BV14)/2 -> 588 | BH14: =SUM(BI14:BL14) -> 196 | BI14: 49 | BJ14: 49 | BK14: 49 | BL14: 49 | BM14: =SUM(BN14:BQ14) -> 196 | BN14: 49 | BO14: 49 | BP14: 49 | BQ14: 49 | BR14: =SUM(BS14:BV14) -> 196 | BS14: 49 | BT14: 49 | BU14: 49 | BV14: 49 | BW14: =SUM(BX14:EK14)/4 -> 2352 | BX14: =SUM(BY14:DD14)/3 -> 1176 | BY14: =SUM(BZ14:CN14)/2 -> 588 | BZ14: =SUM(CA14:CD14) -> 196 | CA14: 49 | CB14: 49 | CC14: 49 | CD14: 49 | CE14: =SUM(CF14:CI14) -> 196 | CF14: 49 | CG14: 49 | CH14: 49 | CI14: 49 | CJ14: =SUM(CK14:CN14) -> 196 | CK14: 49 | CL14: 49 | CM14: 49 | CN14: 49 | CO14: =SUM(CP14:DD14)/2 -> 588 | CP14: =SUM(CQ14:CT14) -> 196 | CQ14: 49 | CR14: 49 | CS14: 49 | CT14: 49 | CU14: =SUM(CV14:CY14) -> 196 | CV14: 49 | CW14: 49 | CX14: 49 | CY14: 49 | CZ14: =SUM(DA14:DD14) -> 196 | DA14: 49 | DB14: 49 | DC14: 49 | DD14: 49 | DE14: =SUM(DF14:EK14)/3 -> 1176 | DF14: =SUM(DG14:DU14)/2 -> 588 | DG14: =SUM(DH14:DK14) -> 196 | DH14: 49 | DI14: 49 | DJ14: 49 | DK14: 49 | DL14: =SUM(DM14:DP14) -> 196 | DM14: 49 | DN14: 49 | DO14: 49 | DP14: 49 | DQ14: =SUM(DR14:DU14) -> 196 | DR14: 49 | DS14: 49 | DT14: 49 | DU14: 49 | DV14: =SUM(DW14:EK14)/2 -> 588 | DW14: =SUM(DX14:EA14) -> 196 | DX14: 49 | DY14: 49 | DZ14: 49 | EA14: 49 | EB14: =SUM(EC14:EF14) -> 196 | EC14: 49 | ED14: 49 | EE14: 49 | EF14: 49 | EG14: =SUM(EH14:EK14) -> 196 | EH14: 49 | EI14: 49 | EJ14: 49 | EK14: 49 | EL14: =SUM(EM14:GZ14)/4 -> 2352 | EM14: =SUM(EN14:FS14)/3 -> 1176 | EN14: =SUM(EO14:FC14)/2 -> 588 | EO14: =SUM(EP14:ES14) -> 196 | EP14: 49 | EQ14: 49 | ER14: 49 | ES14: 49 | ET14: =SUM(EU14:EX14) -> 196 | EU14: 49 | EV14: 49 | EW14: 49 | EX14: 49 | EY14: =SUM(EZ14:FC14) -> 196 | EZ14: 49 | FA14: 49 | FB14: 49 | FC14: 49 | FD14: =SUM(FE14:FS14)/2 -> 588 | FE14: =SUM(FF14:FI14) -> 196 | FF14: 49 | FG14: 49 | FH14: 49 | FI14: 49 | FJ14: =SUM(FK14:FN14) -> 196 | FK14: 49 | FL14: 49 | FM14: 49 | FN14: 49 | FO14: =SUM(FP14:FS14) -> 196 | FP14: 49 | FQ14: 49 | FR14: 49 | FS14: 49 | FT14: =SUM(FU14:GZ14)/3 -> 1176 | FU14: =SUM(FV14:GJ14)/2 -> 588 | FV14: =SUM(FW14:FZ14) -> 196 | FW14: 49 | FX14: 49 | FY14: 49 | FZ14: 49 | GA14: =SUM(GB14:GE14) -> 196 | GB14: 49 | GC14: 49 | GD14: 49 | GE14: 49 | GF14: =SUM(GG14:GJ14) -> 196 | GG14: 49 | GH14: 49 | GI14: 49 | GJ14: 49 | GK14: =SUM(GL14:GZ14)/2 -> 588 | GL14: =SUM(GM14:GP14) -> 196 | GM14: 49 | GN14: 49 | GO14: 49 | GP14: 49 | GQ14: =SUM(GR14:GU14) -> 196 | GR14: 49 | GS14: 49 | GT14: 49 | GU14: 49 | GV14: =SUM(GW14:GZ14) -> 196 | GW14: 49 | GX14: 49 | GY14: 49 | GZ14: 49
E15: Fakt | G15: =SUM(H15:GZ15)/5 -> 6162 | H15: =SUM(I15:BV15)/4 -> 2054 | I15: =SUM(J15:AO15)/3 -> 1027 | J15: =SUM(K15:Y15)/2 -> 563 | K15: =SUM(L15:O15) -> 185 | L15: 45 | M15: 50 | N15: 44 | O15: 46 | P15: =SUM(Q15:T15) -> 190 | Q15: 40 | R15: 48 | S15: 52 | T15: 50 | U15: =SUM(V15:Y15) -> 188 | V15: 45 | W15: 46 | X15: 47 | Y15: 50 | Z15: =SUM(AA15:AO15)/2 -> 464 | AA15: =SUM(AB15:AE15) -> 162 | AB15: 39 | AC15: 42 | AD15: 40 | AE15: 41 | AF15: =SUM(AG15:AJ15) -> 155 | AG15: 40 | AH15: 41 | AI15: 39 | AJ15: 35 | AK15: =SUM(AL15:AO15) -> 147 | AL15: 34 | AM15: 32 | AN15: 39 | AO15: 42 | AP15: =SUM(AQ15:BV15)/3 -> 1027 | AQ15: =SUM(AR15:BF15)/2 -> 464 | AR15: =SUM(AS15:AV15) -> 147 | AS15: 34 | AT15: 32 | AU15: 39 | AV15: 42 | AW15: =SUM(AX15:BA15) -> 162 | AX15: 39 | AY15: 42 | AZ15: 40 | BA15: 41 | BB15: =SUM(BC15:BF15) -> 155 | BC15: 40 | BD15: 41 | BE15: 39 | BF15: 35 | BG15: =SUM(BH15:BV15)/2 -> 563 | BH15: =SUM(BI15:BL15) -> 190 | BI15: 40 | BJ15: 48 | BK15: 52 | BL15: 50 | BM15: =SUM(BN15:BQ15) -> 188 | BN15: 45 | BO15: 46 | BP15: 47 | BQ15: 50 | BR15: =SUM(BS15:BV15) -> 185 | BS15: 45 | BT15: 50 | BU15: 44 | BV15: 46 | BW15: =SUM(BX15:EK15)/4 -> 2054 | BX15: =SUM(BY15:DD15)/3 -> 1027 | BY15: =SUM(BZ15:CN15)/2 -> 464 | BZ15: =SUM(CA15:CD15) -> 155 | CA15: 40 | CB15: 41 | CC15: 39 | CD15: 35 | CE15: =SUM(CF15:CI15) -> 147 | CF15: 34 | CG15: 32 | CH15: 39 | CI15: 42 | CJ15: =SUM(CK15:CN15) -> 162 | CK15: 39 | CL15: 42 | CM15: 40 | CN15: 41 | CO15: =SUM(CP15:DD15)/2 -> 563 | CP15: =SUM(CQ15:CT15) -> 185 | CQ15: 45 | CR15: 50 | CS15: 44 | CT15: 46 | CU15: =SUM(CV15:CY15) -> 190 | CV15: 40 | CW15: 48 | CX15: 52 | CY15: 50 | CZ15: =SUM(DA15:DD15) -> 188 | DA15: 45 | DB15: 46 | DC15: 47 | DD15: 50 | DE15: =SUM(DF15:EK15)/3 -> 1027 | DF15: =SUM(DG15:DU15)/2 -> 563 | DG15: =SUM(DH15:DK15) -> 188 | DH15: 45 | DI15: 46 | DJ15: 47 | DK15: 50 | DL15: =SUM(DM15:DP15) -> 185 | DM15: 45 | DN15: 50 | DO15: 44 | DP15: 46 | DQ15: =SUM(DR15:DU15) -> 190 | DR15: 40 | DS15: 48 | DT15: 52 | DU15: 50 | DV15: =SUM(DW15:EK15)/2 -> 464 | DW15: =SUM(DX15:EA15) -> 147 | DX15: 34 | DY15: 32 | DZ15: 39 | EA15: 42 | EB15: =SUM(EC15:EF15) -> 155 | EC15: 40 | ED15: 41 | EE15: 39 | EF15: 35 | EG15: =SUM(EH15:EK15) -> 162 | EH15: 39 | EI15: 42 | EJ15: 40 | EK15: 41 | EL15: =SUM(EM15:GZ15)/4 -> 2054 | EM15: =SUM(EN15:FS15)/3 -> 1027 | EN15: =SUM(EO15:FC15)/2 -> 464 | EO15: =SUM(EP15:ES15) -> 155 | EP15: 40 | EQ15: 41 | ER15: 39 | ES15: 35 | ET15: =SUM(EU15:EX15) -> 162 | EU15: 39 | EV15: 42 | EW15: 40 | EX15: 41 | EY15: =SUM(EZ15:FC15) -> 147 | EZ15: 34 | FA15: 32 | FB15: 39 | FC15: 42 | FD15: =SUM(FE15:FS15)/2 -> 563 | FE15: =SUM(FF15:FI15) -> 185 | FF15: 45 | FG15: 50 | FH15: 44 | FI15: 46 | FJ15: =SUM(FK15:FN15) -> 190 | FK15: 40 | FL15: 48 | FM15: 52 | FN15: 50 | FO15: =SUM(FP15:FS15) -> 188 | FP15: 45 | FQ15: 46 | FR15: 47 | FS15: 50 | FT15: =SUM(FU15:GZ15)/3 -> 1027 | FU15: =SUM(FV15:GJ15)/2 -> 563 | FV15: =SUM(FW15:FZ15) -> 188 | FW15: 45 | FX15: 46 | FY15: 47 | FZ15: 50 | GA15: =SUM(GB15:GE15) -> 185 | GB15: 45 | GC15: 50 | GD15: 44 | GE15: 46 | GF15: =SUM(GG15:GJ15) -> 190 | GG15: 40 | GH15: 48 | GI15: 52 | GJ15: 50 | GK15: =SUM(GL15:GZ15)/2 -> 464 | GL15: =SUM(GM15:GP15) -> 162 | GM15: 39 | GN15: 42 | GO15: 40 | GP15: 41 | GQ15: =SUM(GR15:GU15) -> 155 | GR15: 40 | GS15: 41 | GT15: 39 | GU15: 35 | GV15: =SUM(GW15:GZ15) -> 147 | GW15: 34 | GX15: 32 | GY15: 39 | GZ15: 42
C16: 2 | D16: Probniyga yangi kelganlar soni | E16: Reja | G16: =SUM(H16:GZ16)/5 -> 5040 | H16: =SUM(I16:BV16)/4 -> 1680 | I16: =SUM(J16:AO16)/3 -> 840 | J16: =SUM(K16:Y16)/2 -> 420 | K16: =SUM(L16:O16) -> 140 | L16: 35 | M16: 35 | N16: 35 | O16: 35 | P16: =SUM(Q16:T16) -> 140 | Q16: 35 | R16: 35 | S16: 35 | T16: 35 | U16: =SUM(V16:Y16) -> 140 | V16: 35 | W16: 35 | X16: 35 | Y16: 35 | Z16: =SUM(AA16:AO16)/2 -> 420 | AA16: =SUM(AB16:AE16) -> 140 | AB16: 35 | AC16: 35 | AD16: 35 | AE16: 35 | AF16: =SUM(AG16:AJ16) -> 140 | AG16: 35 | AH16: 35 | AI16: 35 | AJ16: 35 | AK16: =SUM(AL16:AO16) -> 140 | AL16: 35 | AM16: 35 | AN16: 35 | AO16: 35 | AP16: =SUM(AQ16:BV16)/3 -> 840 | AQ16: =SUM(AR16:BF16)/2 -> 420 | AR16: =SUM(AS16:AV16) -> 140 | AS16: 35 | AT16: 35 | AU16: 35 | AV16: 35 | AW16: =SUM(AX16:BA16) -> 140 | AX16: 35 | AY16: 35 | AZ16: 35 | BA16: 35 | BB16: =SUM(BC16:BF16) -> 140 | BC16: 35 | BD16: 35 | BE16: 35 | BF16: 35 | BG16: =SUM(BH16:BV16)/2 -> 420 | BH16: =SUM(BI16:BL16) -> 140 | BI16: 35 | BJ16: 35 | BK16: 35 | BL16: 35 | BM16: =SUM(BN16:BQ16) -> 140 | BN16: 35 | BO16: 35 | BP16: 35 | BQ16: 35 | BR16: =SUM(BS16:BV16) -> 140 | BS16: 35 | BT16: 35 | BU16: 35 | BV16: 35 | BW16: =SUM(BX16:EK16)/4 -> 1680 | BX16: =SUM(BY16:DD16)/3 -> 840 | BY16: =SUM(BZ16:CN16)/2 -> 420 | BZ16: =SUM(CA16:CD16) -> 140 | CA16: 35 | CB16: 35 | CC16: 35 | CD16: 35 | CE16: =SUM(CF16:CI16) -> 140 | CF16: 35 | CG16: 35 | CH16: 35 | CI16: 35 | CJ16: =SUM(CK16:CN16) -> 140 | CK16: 35 | CL16: 35 | CM16: 35 | CN16: 35 | CO16: =SUM(CP16:DD16)/2 -> 420 | CP16: =SUM(CQ16:CT16) -> 140 | CQ16: 35 | CR16: 35 | CS16: 35 | CT16: 35 | CU16: =SUM(CV16:CY16) -> 140 | CV16: 35 | CW16: 35 | CX16: 35 | CY16: 35 | CZ16: =SUM(DA16:DD16) -> 140 | DA16: 35 | DB16: 35 | DC16: 35 | DD16: 35 | DE16: =SUM(DF16:EK16)/3 -> 840 | DF16: =SUM(DG16:DU16)/2 -> 420 | DG16: =SUM(DH16:DK16) -> 140 | DH16: 35 | DI16: 35 | DJ16: 35 | DK16: 35 | DL16: =SUM(DM16:DP16) -> 140 | DM16: 35 | DN16: 35 | DO16: 35 | DP16: 35 | DQ16: =SUM(DR16:DU16) -> 140 | DR16: 35 | DS16: 35 | DT16: 35 | DU16: 35 | DV16: =SUM(DW16:EK16)/2 -> 420 | DW16: =SUM(DX16:EA16) -> 140 | DX16: 35 | DY16: 35 | DZ16: 35 | EA16: 35 | EB16: =SUM(EC16:EF16) -> 140 | EC16: 35 | ED16: 35 | EE16: 35 | EF16: 35 | EG16: =SUM(EH16:EK16) -> 140 | EH16: 35 | EI16: 35 | EJ16: 35 | EK16: 35 | EL16: =SUM(EM16:GZ16)/4 -> 1680 | EM16: =SUM(EN16:FS16)/3 -> 840 | EN16: =SUM(EO16:FC16)/2 -> 420 | EO16: =SUM(EP16:ES16) -> 140 | EP16: 35 | EQ16: 35 | ER16: 35 | ES16: 35 | ET16: =SUM(EU16:EX16) -> 140 | EU16: 35 | EV16: 35 | EW16: 35 | EX16: 35 | EY16: =SUM(EZ16:FC16) -> 140 | EZ16: 35 | FA16: 35 | FB16: 35 | FC16: 35 | FD16: =SUM(FE16:FS16)/2 -> 420 | FE16: =SUM(FF16:FI16) -> 140 | FF16: 35 | FG16: 35 | FH16: 35 | FI16: 35 | FJ16: =SUM(FK16:FN16) -> 140 | FK16: 35 | FL16: 35 | FM16: 35 | FN16: 35 | FO16: =SUM(FP16:FS16) -> 140 | FP16: 35 | FQ16: 35 | FR16: 35 | FS16: 35 | FT16: =SUM(FU16:GZ16)/3 -> 840 | FU16: =SUM(FV16:GJ16)/2 -> 420 | FV16: =SUM(FW16:FZ16) -> 140 | FW16: 35 | FX16: 35 | FY16: 35 | FZ16: 35 | GA16: =SUM(GB16:GE16) -> 140 | GB16: 35 | GC16: 35 | GD16: 35 | GE16: 35 | GF16: =SUM(GG16:GJ16) -> 140 | GG16: 35 | GH16: 35 | GI16: 35 | GJ16: 35 | GK16: =SUM(GL16:GZ16)/2 -> 420 | GL16: =SUM(GM16:GP16) -> 140 | GM16: 35 | GN16: 35 | GO16: 35 | GP16: 35 | GQ16: =SUM(GR16:GU16) -> 140 | GR16: 35 | GS16: 35 | GT16: 35 | GU16: 35 | GV16: =SUM(GW16:GZ16) -> 140 | GW16: 35 | GX16: 35 | GY16: 35 | GZ16: 35
E17: Fakt | G17: =SUM(H17:GZ17)/5 -> 4434 | H17: =SUM(I17:BV17)/4 -> 1478 | I17: =SUM(J17:AO17)/3 -> 739 | J17: =SUM(K17:Y17)/2 -> 406 | K17: =SUM(L17:O17) -> 133 | L17: 30 | M17: 35 | N17: 32 | O17: 36 | P17: =SUM(Q17:T17) -> 152 | Q17: 35 | R17: 40 | S17: 42 | T17: 35 | U17: =SUM(V17:Y17) -> 121 | V17: 34 | W17: 30 | X17: 25 | Y17: 32 | Z17: =SUM(AA17:AO17)/2 -> 333 | AA17: =SUM(AB17:AE17) -> 110 | AB17: 29 | AC17: 28 | AD17: 27 | AE17: 26 | AF17: =SUM(AG17:AJ17) -> 102 | AG17: 25 | AH17: 24 | AI17: 26 | AJ17: 27 | AK17: =SUM(AL17:AO17) -> 121 | AL17: 28 | AM17: 30 | AN17: 31 | AO17: 32 | AP17: =SUM(AQ17:BV17)/3 -> 739 | AQ17: =SUM(AR17:BF17)/2 -> 333 | AR17: =SUM(AS17:AV17) -> 121 | AS17: 28 | AT17: 30 | AU17: 31 | AV17: 32 | AW17: =SUM(AX17:BA17) -> 110 | AX17: 29 | AY17: 28 | AZ17: 27 | BA17: 26 | BB17: =SUM(BC17:BF17) -> 102 | BC17: 25 | BD17: 24 | BE17: 26 | BF17: 27 | BG17: =SUM(BH17:BV17)/2 -> 406 | BH17: =SUM(BI17:BL17) -> 152 | BI17: 35 | BJ17: 40 | BK17: 42 | BL17: 35 | BM17: =SUM(BN17:BQ17) -> 121 | BN17: 34 | BO17: 30 | BP17: 25 | BQ17: 32 | BR17: =SUM(BS17:BV17) -> 133 | BS17: 30 | BT17: 35 | BU17: 32 | BV17: 36 | BW17: =SUM(BX17:EK17)/4 -> 1478 | BX17: =SUM(BY17:DD17)/3 -> 739 | BY17: =SUM(BZ17:CN17)/2 -> 333 | BZ17: =SUM(CA17:CD17) -> 102 | CA17: 25 | CB17: 24 | CC17: 26 | CD17: 27 | CE17: =SUM(CF17:CI17) -> 121 | CF17: 28 | CG17: 30 | CH17: 31 | CI17: 32 | CJ17: =SUM(CK17:CN17) -> 110 | CK17: 29 | CL17: 28 | CM17: 27 | CN17: 26 | CO17: =SUM(CP17:DD17)/2 -> 406 | CP17: =SUM(CQ17:CT17) -> 133 | CQ17: 30 | CR17: 35 | CS17: 32 | CT17: 36 | CU17: =SUM(CV17:CY17) -> 152 | CV17: 35 | CW17: 40 | CX17: 42 | CY17: 35 | CZ17: =SUM(DA17:DD17) -> 121 | DA17: 34 | DB17: 30 | DC17: 25 | DD17: 32 | DE17: =SUM(DF17:EK17)/3 -> 739 | DF17: =SUM(DG17:DU17)/2 -> 406 | DG17: =SUM(DH17:DK17) -> 121 | DH17: 34 | DI17: 30 | DJ17: 25 | DK17: 32 | DL17: =SUM(DM17:DP17) -> 133 | DM17: 30 | DN17: 35 | DO17: 32 | DP17: 36 | DQ17: =SUM(DR17:DU17) -> 152 | DR17: 35 | DS17: 40 | DT17: 42 | DU17: 35 | DV17: =SUM(DW17:EK17)/2 -> 333 | DW17: =SUM(DX17:EA17) -> 121 | DX17: 28 | DY17: 30 | DZ17: 31 | EA17: 32 | EB17: =SUM(EC17:EF17) -> 102 | EC17: 25 | ED17: 24 | EE17: 26 | EF17: 27 | EG17: =SUM(EH17:EK17) -> 110 | EH17: 29 | EI17: 28 | EJ17: 27 | EK17: 26 | EL17: =SUM(EM17:GZ17)/4 -> 1478 | EM17: =SUM(EN17:FS17)/3 -> 739 | EN17: =SUM(EO17:FC17)/2 -> 333 | EO17: =SUM(EP17:ES17) -> 102 | EP17: 25 | EQ17: 24 | ER17: 26 | ES17: 27 | ET17: =SUM(EU17:EX17) -> 110 | EU17: 29 | EV17: 28 | EW17: 27 | EX17: 26 | EY17: =SUM(EZ17:FC17) -> 121 | EZ17: 28 | FA17: 30 | FB17: 31 | FC17: 32 | FD17: =SUM(FE17:FS17)/2 -> 406 | FE17: =SUM(FF17:FI17) -> 133 | FF17: 30 | FG17: 35 | FH17: 32 | FI17: 36 | FJ17: =SUM(FK17:FN17) -> 152 | FK17: 35 | FL17: 40 | FM17: 42 | FN17: 35 | FO17: =SUM(FP17:FS17) -> 121 | FP17: 34 | FQ17: 30 | FR17: 25 | FS17: 32 | FT17: =SUM(FU17:GZ17)/3 -> 739 | FU17: =SUM(FV17:GJ17)/2 -> 406 | FV17: =SUM(FW17:FZ17) -> 121 | FW17: 34 | FX17: 30 | FY17: 25 | FZ17: 32 | GA17: =SUM(GB17:GE17) -> 133 | GB17: 30 | GC17: 35 | GD17: 32 | GE17: 36 | GF17: =SUM(GG17:GJ17) -> 152 | GG17: 35 | GH17: 40 | GI17: 42 | GJ17: 35 | GK17: =SUM(GL17:GZ17)/2 -> 333 | GL17: =SUM(GM17:GP17) -> 110 | GM17: 29 | GN17: 28 | GO17: 27 | GP17: 26 | GQ17: =SUM(GR17:GU17) -> 102 | GR17: 25 | GS17: 24 | GT17: 26 | GU17: 27 | GV17: =SUM(GW17:GZ17) -> 121 | GW17: 28 | GX17: 30 | GY17: 31 | GZ17: 32
C18: 3 | D18: Qilingan yangi to'lovlar soni | E18: Reja | G18: =SUM(H18:GZ18)/5 -> 2016 | H18: =SUM(I18:BV18)/4 -> 672 | I18: =SUM(J18:AO18)/3 -> 336 | J18: =SUM(K18:Y18)/2 -> 168 | K18: =SUM(L18:O18) -> 56 | L18: 14 | M18: 14 | N18: 14 | O18: 14 | P18: =SUM(Q18:T18) -> 56 | Q18: 14 | R18: 14 | S18: 14 | T18: 14 | U18: =SUM(V18:Y18) -> 56 | V18: 14 | W18: 14 | X18: 14 | Y18: 14 | Z18: =SUM(AA18:AO18)/2 -> 168 | AA18: =SUM(AB18:AE18) -> 56 | AB18: 14 | AC18: 14 | AD18: 14 | AE18: 14 | AF18: =SUM(AG18:AJ18) -> 56 | AG18: 14 | AH18: 14 | AI18: 14 | AJ18: 14 | AK18: =SUM(AL18:AO18) -> 56 | AL18: 14 | AM18: 14 | AN18: 14 | AO18: 14 | AP18: =SUM(AQ18:BV18)/3 -> 336 | AQ18: =SUM(AR18:BF18)/2 -> 168 | AR18: =SUM(AS18:AV18) -> 56 | AS18: 14 | AT18: 14 | AU18: 14 | AV18: 14 | AW18: =SUM(AX18:BA18) -> 56 | AX18: 14 | AY18: 14 | AZ18: 14 | BA18: 14 | BB18: =SUM(BC18:BF18) -> 56 | BC18: 14 | BD18: 14 | BE18: 14 | BF18: 14 | BG18: =SUM(BH18:BV18)/2 -> 168 | BH18: =SUM(BI18:BL18) -> 56 | BI18: 14 | BJ18: 14 | BK18: 14 | BL18: 14 | BM18: =SUM(BN18:BQ18) -> 56 | BN18: 14 | BO18: 14 | BP18: 14 | BQ18: 14 | BR18: =SUM(BS18:BV18) -> 56 | BS18: 14 | BT18: 14 | BU18: 14 | BV18: 14 | BW18: =SUM(BX18:EK18)/4 -> 672 | BX18: =SUM(BY18:DD18)/3 -> 336 | BY18: =SUM(BZ18:CN18)/2 -> 168 | BZ18: =SUM(CA18:CD18) -> 56 | CA18: 14 | CB18: 14 | CC18: 14 | CD18: 14 | CE18: =SUM(CF18:CI18) -> 56 | CF18: 14 | CG18: 14 | CH18: 14 | CI18: 14 | CJ18: =SUM(CK18:CN18) -> 56 | CK18: 14 | CL18: 14 | CM18: 14 | CN18: 14 | CO18: =SUM(CP18:DD18)/2 -> 168 | CP18: =SUM(CQ18:CT18) -> 56 | CQ18: 14 | CR18: 14 | CS18: 14 | CT18: 14 | CU18: =SUM(CV18:CY18) -> 56 | CV18: 14 | CW18: 14 | CX18: 14 | CY18: 14 | CZ18: =SUM(DA18:DD18) -> 56 | DA18: 14 | DB18: 14 | DC18: 14 | DD18: 14 | DE18: =SUM(DF18:EK18)/3 -> 336 | DF18: =SUM(DG18:DU18)/2 -> 168 | DG18: =SUM(DH18:DK18) -> 56 | DH18: 14 | DI18: 14 | DJ18: 14 | DK18: 14 | DL18: =SUM(DM18:DP18) -> 56 | DM18: 14 | DN18: 14 | DO18: 14 | DP18: 14 | DQ18: =SUM(DR18:DU18) -> 56 | DR18: 14 | DS18: 14 | DT18: 14 | DU18: 14 | DV18: =SUM(DW18:EK18)/2 -> 168 | DW18: =SUM(DX18:EA18) -> 56 | DX18: 14 | DY18: 14 | DZ18: 14 | EA18: 14 | EB18: =SUM(EC18:EF18) -> 56 | EC18: 14 | ED18: 14 | EE18: 14 | EF18: 14 | EG18: =SUM(EH18:EK18) -> 56 | EH18: 14 | EI18: 14 | EJ18: 14 | EK18: 14 | EL18: =SUM(EM18:GZ18)/4 -> 672 | EM18: =SUM(EN18:FS18)/3 -> 336 | EN18: =SUM(EO18:FC18)/2 -> 168 | EO18: =SUM(EP18:ES18) -> 56 | EP18: 14 | EQ18: 14 | ER18: 14 | ES18: 14 | ET18: =SUM(EU18:EX18) -> 56 | EU18: 14 | EV18: 14 | EW18: 14 | EX18: 14 | EY18: =SUM(EZ18:FC18) -> 56 | EZ18: 14 | FA18: 14 | FB18: 14 | FC18: 14 | FD18: =SUM(FE18:FS18)/2 -> 168 | FE18: =SUM(FF18:FI18) -> 56 | FF18: 14 | FG18: 14 | FH18: 14 | FI18: 14 | FJ18: =SUM(FK18:FN18) -> 56 | FK18: 14 | FL18: 14 | FM18: 14 | FN18: 14 | FO18: =SUM(FP18:FS18) -> 56 | FP18: 14 | FQ18: 14 | FR18: 14 | FS18: 14 | FT18: =SUM(FU18:GZ18)/3 -> 336 | FU18: =SUM(FV18:GJ18)/2 -> 168 | FV18: =SUM(FW18:FZ18) -> 56 | FW18: 14 | FX18: 14 | FY18: 14 | FZ18: 14 | GA18: =SUM(GB18:GE18) -> 56 | GB18: 14 | GC18: 14 | GD18: 14 | GE18: 14 | GF18: =SUM(GG18:GJ18) -> 56 | GG18: 14 | GH18: 14 | GI18: 14 | GJ18: 14 | GK18: =SUM(GL18:GZ18)/2 -> 168 | GL18: =SUM(GM18:GP18) -> 56 | GM18: 14 | GN18: 14 | GO18: 14 | GP18: 14 | GQ18: =SUM(GR18:GU18) -> 56 | GR18: 14 | GS18: 14 | GT18: 14 | GU18: 14 | GV18: =SUM(GW18:GZ18) -> 56 | GW18: 14 | GX18: 14 | GY18: 14 | GZ18: 14
E19: Fakt | G19: =SUM(H19:GZ19)/5 -> 1614 | H19: =SUM(I19:BV19)/4 -> 538 | I19: =SUM(J19:AO19)/3 -> 269 | J19: =SUM(K19:Y19)/2 -> 158 | K19: =SUM(L19:O19) -> 51 | L19: 12 | M19: 14 | N19: 15 | O19: 10 | P19: =SUM(Q19:T19) -> 56 | Q19: 15 | R19: 15 | S19: 14 | T19: 12 | U19: =SUM(V19:Y19) -> 51 | V19: 12 | W19: 13 | X19: 14 | Y19: 12 | Z19: =SUM(AA19:AO19)/2 -> 111 | AA19: =SUM(AB19:AE19) -> 42 | AB19: 10 | AC19: 11 | AD19: 12 | AE19: 9 | AF19: =SUM(AG19:AJ19) -> 30 | AG19: 8 | AH19: 7 | AI19: 6 | AJ19: 9 | AK19: =SUM(AL19:AO19) -> 39 | AL19: 10 | AM19: 9 | AN19: 8 | AO19: 12 | AP19: =SUM(AQ19:BV19)/3 -> 269 | AQ19: =SUM(AR19:BF19)/2 -> 111 | AR19: =SUM(AS19:AV19) -> 39 | AS19: 10 | AT19: 9 | AU19: 8 | AV19: 12 | AW19: =SUM(AX19:BA19) -> 42 | AX19: 10 | AY19: 11 | AZ19: 12 | BA19: 9 | BB19: =SUM(BC19:BF19) -> 30 | BC19: 8 | BD19: 7 | BE19: 6 | BF19: 9 | BG19: =SUM(BH19:BV19)/2 -> 158 | BH19: =SUM(BI19:BL19) -> 56 | BI19: 15 | BJ19: 15 | BK19: 14 | BL19: 12 | BM19: =SUM(BN19:BQ19) -> 51 | BN19: 12 | BO19: 13 | BP19: 14 | BQ19: 12 | BR19: =SUM(BS19:BV19) -> 51 | BS19: 12 | BT19: 14 | BU19: 15 | BV19: 10 | BW19: =SUM(BX19:EK19)/4 -> 538 | BX19: =SUM(BY19:DD19)/3 -> 269 | BY19: =SUM(BZ19:CN19)/2 -> 111 | BZ19: =SUM(CA19:CD19) -> 30 | CA19: 8 | CB19: 7 | CC19: 6 | CD19: 9 | CE19: =SUM(CF19:CI19) -> 39 | CF19: 10 | CG19: 9 | CH19: 8 | CI19: 12 | CJ19: =SUM(CK19:CN19) -> 42 | CK19: 10 | CL19: 11 | CM19: 12 | CN19: 9 | CO19: =SUM(CP19:DD19)/2 -> 158 | CP19: =SUM(CQ19:CT19) -> 51 | CQ19: 12 | CR19: 14 | CS19: 15 | CT19: 10 | CU19: =SUM(CV19:CY19) -> 56 | CV19: 15 | CW19: 15 | CX19: 14 | CY19: 12 | CZ19: =SUM(DA19:DD19) -> 51 | DA19: 12 | DB19: 13 | DC19: 14 | DD19: 12 | DE19: =SUM(DF19:EK19)/3 -> 269 | DF19: =SUM(DG19:DU19)/2 -> 158 | DG19: =SUM(DH19:DK19) -> 51 | DH19: 12 | DI19: 13 | DJ19: 14 | DK19: 12 | DL19: =SUM(DM19:DP19) -> 51 | DM19: 12 | DN19: 14 | DO19: 15 | DP19: 10 | DQ19: =SUM(DR19:DU19) -> 56 | DR19: 15 | DS19: 15 | DT19: 14 | DU19: 12 | DV19: =SUM(DW19:EK19)/2 -> 111 | DW19: =SUM(DX19:EA19) -> 39 | DX19: 10 | DY19: 9 | DZ19: 8 | EA19: 12 | EB19: =SUM(EC19:EF19) -> 30 | EC19: 8 | ED19: 7 | EE19: 6 | EF19: 9 | EG19: =SUM(EH19:EK19) -> 42 | EH19: 10 | EI19: 11 | EJ19: 12 | EK19: 9 | EL19: =SUM(EM19:GZ19)/4 -> 538 | EM19: =SUM(EN19:FS19)/3 -> 269 | EN19: =SUM(EO19:FC19)/2 -> 111 | EO19: =SUM(EP19:ES19) -> 30 | EP19: 8 | EQ19: 7 | ER19: 6 | ES19: 9 | ET19: =SUM(EU19:EX19) -> 42 | EU19: 10 | EV19: 11 | EW19: 12 | EX19: 9 | EY19: =SUM(EZ19:FC19) -> 39 | EZ19: 10 | FA19: 9 | FB19: 8 | FC19: 12 | FD19: =SUM(FE19:FS19)/2 -> 158 | FE19: =SUM(FF19:FI19) -> 51 | FF19: 12 | FG19: 14 | FH19: 15 | FI19: 10 | FJ19: =SUM(FK19:FN19) -> 56 | FK19: 15 | FL19: 15 | FM19: 14 | FN19: 12 | FO19: =SUM(FP19:FS19) -> 51 | FP19: 12 | FQ19: 13 | FR19: 14 | FS19: 12 | FT19: =SUM(FU19:GZ19)/3 -> 269 | FU19: =SUM(FV19:GJ19)/2 -> 158 | FV19: =SUM(FW19:FZ19) -> 51 | FW19: 12 | FX19: 13 | FY19: 14 | FZ19: 12 | GA19: =SUM(GB19:GE19) -> 51 | GB19: 12 | GC19: 14 | GD19: 15 | GE19: 10 | GF19: =SUM(GG19:GJ19) -> 56 | GG19: 15 | GH19: 15 | GI19: 14 | GJ19: 12 | GK19: =SUM(GL19:GZ19)/2 -> 111 | GL19: =SUM(GM19:GP19) -> 42 | GM19: 10 | GN19: 11 | GO19: 12 | GP19: 9 | GQ19: =SUM(GR19:GU19) -> 30 | GR19: 8 | GS19: 7 | GT19: 6 | GU19: 9 | GV19: =SUM(GW19:GZ19) -> 39 | GW19: 10 | GX19: 9 | GY19: 8 | GZ19: 12
B20: Product | C20: 1 | D20: Konsultatsiya olgan mijozlar soni | E20: Reja | G20: =SUM(H20:GZ20)/5 -> 6048 | H20: =SUM(I20:BV20)/4 -> 2016 | I20: =SUM(J20:AO20)/3 -> 1008 | J20: =SUM(K20:Y20)/2 -> 504 | K20: =SUM(L20:O20) -> 168 | L20: 42 | M20: 42 | N20: 42 | O20: 42 | P20: =SUM(Q20:T20) -> 168 | Q20: 42 | R20: 42 | S20: 42 | T20: 42 | U20: =SUM(V20:Y20) -> 168 | V20: 42 | W20: 42 | X20: 42 | Y20: 42 | Z20: =SUM(AA20:AO20)/2 -> 504 | AA20: =SUM(AB20:AE20) -> 168 | AB20: 42 | AC20: 42 | AD20: 42 | AE20: 42 | AF20: =SUM(AG20:AJ20) -> 168 | AG20: 42 | AH20: 42 | AI20: 42 | AJ20: 42 | AK20: =SUM(AL20:AO20) -> 168 | AL20: 42 | AM20: 42 | AN20: 42 | AO20: 42 | AP20: =SUM(AQ20:BV20)/3 -> 1008 | AQ20: =SUM(AR20:BF20)/2 -> 504 | AR20: =SUM(AS20:AV20) -> 168 | AS20: 42 | AT20: 42 | AU20: 42 | AV20: 42 | AW20: =SUM(AX20:BA20) -> 168 | AX20: 42 | AY20: 42 | AZ20: 42 | BA20: 42 | BB20: =SUM(BC20:BF20) -> 168 | BC20: 42 | BD20: 42 | BE20: 42 | BF20: 42 | BG20: =SUM(BH20:BV20)/2 -> 504 | BH20: =SUM(BI20:BL20) -> 168 | BI20: 42 | BJ20: 42 | BK20: 42 | BL20: 42 | BM20: =SUM(BN20:BQ20) -> 168 | BN20: 42 | BO20: 42 | BP20: 42 | BQ20: 42 | BR20: =SUM(BS20:BV20) -> 168 | BS20: 42 | BT20: 42 | BU20: 42 | BV20: 42 | BW20: =SUM(BX20:EK20)/4 -> 2016 | BX20: =SUM(BY20:DD20)/3 -> 1008 | BY20: =SUM(BZ20:CN20)/2 -> 504 | BZ20: =SUM(CA20:CD20) -> 168 | CA20: 42 | CB20: 42 | CC20: 42 | CD20: 42 | CE20: =SUM(CF20:CI20) -> 168 | CF20: 42 | CG20: 42 | CH20: 42 | CI20: 42 | CJ20: =SUM(CK20:CN20) -> 168 | CK20: 42 | CL20: 42 | CM20: 42 | CN20: 42 | CO20: =SUM(CP20:DD20)/2 -> 504 | CP20: =SUM(CQ20:CT20) -> 168 | CQ20: 42 | CR20: 42 | CS20: 42 | CT20: 42 | CU20: =SUM(CV20:CY20) -> 168 | CV20: 42 | CW20: 42 | CX20: 42 | CY20: 42 | CZ20: =SUM(DA20:DD20) -> 168 | DA20: 42 | DB20: 42 | DC20: 42 | DD20: 42 | DE20: =SUM(DF20:EK20)/3 -> 1008 | DF20: =SUM(DG20:DU20)/2 -> 504 | DG20: =SUM(DH20:DK20) -> 168 | DH20: 42 | DI20: 42 | DJ20: 42 | DK20: 42 | DL20: =SUM(DM20:DP20) -> 168 | DM20: 42 | DN20: 42 | DO20: 42 | DP20: 42 | DQ20: =SUM(DR20:DU20) -> 168 | DR20: 42 | DS20: 42 | DT20: 42 | DU20: 42 | DV20: =SUM(DW20:EK20)/2 -> 504 | DW20: =SUM(DX20:EA20) -> 168 | DX20: 42 | DY20: 42 | DZ20: 42 | EA20: 42 | EB20: =SUM(EC20:EF20) -> 168 | EC20: 42 | ED20: 42 | EE20: 42 | EF20: 42 | EG20: =SUM(EH20:EK20) -> 168 | EH20: 42 | EI20: 42 | EJ20: 42 | EK20: 42 | EL20: =SUM(EM20:GZ20)/4 -> 2016 | EM20: =SUM(EN20:FS20)/3 -> 1008 | EN20: =SUM(EO20:FC20)/2 -> 504 | EO20: =SUM(EP20:ES20) -> 168 | EP20: 42 | EQ20: 42 | ER20: 42 | ES20: 42 | ET20: =SUM(EU20:EX20) -> 168 | EU20: 42 | EV20: 42 | EW20: 42 | EX20: 42 | EY20: =SUM(EZ20:FC20) -> 168 | EZ20: 42 | FA20: 42 | FB20: 42 | FC20: 42 | FD20: =SUM(FE20:FS20)/2 -> 504 | FE20: =SUM(FF20:FI20) -> 168 | FF20: 42 | FG20: 42 | FH20: 42 | FI20: 42 | FJ20: =SUM(FK20:FN20) -> 168 | FK20: 42 | FL20: 42 | FM20: 42 | FN20: 42 | FO20: =SUM(FP20:FS20) -> 168 | FP20: 42 | FQ20: 42 | FR20: 42 | FS20: 42 | FT20: =SUM(FU20:GZ20)/3 -> 1008 | FU20: =SUM(FV20:GJ20)/2 -> 504 | FV20: =SUM(FW20:FZ20) -> 168 | FW20: 42 | FX20: 42 | FY20: 42 | FZ20: 42 | GA20: =SUM(GB20:GE20) -> 168 | GB20: 42 | GC20: 42 | GD20: 42 | GE20: 42 | GF20: =SUM(GG20:GJ20) -> 168 | GG20: 42 | GH20: 42 | GI20: 42 | GJ20: 42 | GK20: =SUM(GL20:GZ20)/2 -> 504 | GL20: =SUM(GM20:GP20) -> 168 | GM20: 42 | GN20: 42 | GO20: 42 | GP20: 42 | GQ20: =SUM(GR20:GU20) -> 168 | GR20: 42 | GS20: 42 | GT20: 42 | GU20: 42 | GV20: =SUM(GW20:GZ20) -> 168 | GW20: 42 | GX20: 42 | GY20: 42 | GZ20: 42
E21: Fakt | G21: =SUM(H21:GZ21)/5 -> 4980 | H21: =SUM(I21:BV21)/4 -> 1660 | I21: =SUM(J21:AO21)/3 -> 830 | J21: =SUM(K21:Y21)/2 -> 439 | K21: =SUM(L21:O21) -> 141 | L21: 35 | M21: 34 | N21: 32 | O21: 40 | P21: =SUM(Q21:T21) -> 140 | Q21: 32 | R21: 34 | S21: 36 | T21: 38 | U21: =SUM(V21:Y21) -> 158 | V21: 38 | W21: 38 | X21: 40 | Y21: 42 | Z21: =SUM(AA21:AO21)/2 -> 391 | AA21: =SUM(AB21:AE21) -> 132 | AB21: 32 | AC21: 34 | AD21: 31 | AE21: 35 | AF21: =SUM(AG21:AJ21) -> 128 | AG21: 30 | AH21: 31 | AI21: 33 | AJ21: 34 | AK21: =SUM(AL21:AO21) -> 131 | AL21: 34 | AM21: 35 | AN21: 32 | AO21: 30 | AP21: =SUM(AQ21:BV21)/3 -> 830 | AQ21: =SUM(AR21:BF21)/2 -> 391 | AR21: =SUM(AS21:AV21) -> 131 | AS21: 34 | AT21: 35 | AU21: 32 | AV21: 30 | AW21: =SUM(AX21:BA21) -> 132 | AX21: 32 | AY21: 34 | AZ21: 31 | BA21: 35 | BB21: =SUM(BC21:BF21) -> 128 | BC21: 30 | BD21: 31 | BE21: 33 | BF21: 34 | BG21: =SUM(BH21:BV21)/2 -> 439 | BH21: =SUM(BI21:BL21) -> 140 | BI21: 32 | BJ21: 34 | BK21: 36 | BL21: 38 | BM21: =SUM(BN21:BQ21) -> 158 | BN21: 38 | BO21: 38 | BP21: 40 | BQ21: 42 | BR21: =SUM(BS21:BV21) -> 141 | BS21: 35 | BT21: 34 | BU21: 32 | BV21: 40 | BW21: =SUM(BX21:EK21)/4 -> 1660 | BX21: =SUM(BY21:DD21)/3 -> 830 | BY21: =SUM(BZ21:CN21)/2 -> 391 | BZ21: =SUM(CA21:CD21) -> 128 | CA21: 30 | CB21: 31 | CC21: 33 | CD21: 34 | CE21: =SUM(CF21:CI21) -> 131 | CF21: 34 | CG21: 35 | CH21: 32 | CI21: 30 | CJ21: =SUM(CK21:CN21) -> 132 | CK21: 32 | CL21: 34 | CM21: 31 | CN21: 35 | CO21: =SUM(CP21:DD21)/2 -> 439 | CP21: =SUM(CQ21:CT21) -> 141 | CQ21: 35 | CR21: 34 | CS21: 32 | CT21: 40 | CU21: =SUM(CV21:CY21) -> 140 | CV21: 32 | CW21: 34 | CX21: 36 | CY21: 38 | CZ21: =SUM(DA21:DD21) -> 158 | DA21: 38 | DB21: 38 | DC21: 40 | DD21: 42 | DE21: =SUM(DF21:EK21)/3 -> 830 | DF21: =SUM(DG21:DU21)/2 -> 439 | DG21: =SUM(DH21:DK21) -> 158 | DH21: 38 | DI21: 38 | DJ21: 40 | DK21: 42 | DL21: =SUM(DM21:DP21) -> 141 | DM21: 35 | DN21: 34 | DO21: 32 | DP21: 40 | DQ21: =SUM(DR21:DU21) -> 140 | DR21: 32 | DS21: 34 | DT21: 36 | DU21: 38 | DV21: =SUM(DW21:EK21)/2 -> 391 | DW21: =SUM(DX21:EA21) -> 131 | DX21: 34 | DY21: 35 | DZ21: 32 | EA21: 30 | EB21: =SUM(EC21:EF21) -> 128 | EC21: 30 | ED21: 31 | EE21: 33 | EF21: 34 | EG21: =SUM(EH21:EK21) -> 132 | EH21: 32 | EI21: 34 | EJ21: 31 | EK21: 35 | EL21: =SUM(EM21:GZ21)/4 -> 1660 | EM21: =SUM(EN21:FS21)/3 -> 830 | EN21: =SUM(EO21:FC21)/2 -> 391 | EO21: =SUM(EP21:ES21) -> 128 | EP21: 30 | EQ21: 31 | ER21: 33 | ES21: 34 | ET21: =SUM(EU21:EX21) -> 132 | EU21: 32 | EV21: 34 | EW21: 31 | EX21: 35 | EY21: =SUM(EZ21:FC21) -> 131 | EZ21: 34 | FA21: 35 | FB21: 32 | FC21: 30 | FD21: =SUM(FE21:FS21)/2 -> 439 | FE21: =SUM(FF21:FI21) -> 141 | FF21: 35 | FG21: 34 | FH21: 32 | FI21: 40 | FJ21: =SUM(FK21:FN21) -> 140 | FK21: 32 | FL21: 34 | FM21: 36 | FN21: 38 | FO21: =SUM(FP21:FS21) -> 158 | FP21: 38 | FQ21: 38 | FR21: 40 | FS21: 42 | FT21: =SUM(FU21:GZ21)/3 -> 830 | FU21: =SUM(FV21:GJ21)/2 -> 439 | FV21: =SUM(FW21:FZ21) -> 158 | FW21: 38 | FX21: 38 | FY21: 40 | FZ21: 42 | GA21: =SUM(GB21:GE21) -> 141 | GB21: 35 | GC21: 34 | GD21: 32 | GE21: 40 | GF21: =SUM(GG21:GJ21) -> 140 | GG21: 32 | GH21: 34 | GI21: 36 | GJ21: 38 | GK21: =SUM(GL21:GZ21)/2 -> 391 | GL21: =SUM(GM21:GP21) -> 132 | GM21: 32 | GN21: 34 | GO21: 31 | GP21: 35 | GQ21: =SUM(GR21:GU21) -> 128 | GR21: 30 | GS21: 31 | GT21: 33 | GU21: 34 | GV21: =SUM(GW21:GZ21) -> 131 | GW21: 34 | GX21: 35 | GY21: 32 | GZ21: 30
