Workbook

Sheet ССП
E2: Muddatni tanlang → | F2: Oy 1
E4: Metrika (ko'rsatkichlar) | G4: SUM | H4: % bajarilish | I4: Muhimligi | J4: Fozilari | K4: Bo'lim foizlari | L4: Bo'lim muhimligi | M4: Natija
C5: Marketing | D5: 1 | E5: [Metrika] | F5: Reja | G5: {=INDEX(Metrika!G8:GZ31, , MATCH(F2, Metrika!$G$7:$GZ$7, 0))} -> 0 | H5: =IFERROR(G6/G5,"") | I5: 0 | J5: =H5*I5 -> 0 | K5: =SUM(J5:J10) -> 0 | L5: 0 | M5: =K5*L5 -> 0 | N5: =SUM(M5:M30) -> 0
F6: Fakt | G6: 0
D7: 2 | E7: [Metrika] | F7: Reja | G7: 0 | H7: =IFERROR(G8/G7,"") | I7: 0 | J7: =H7*I7 -> 0
F8: Fakt | G8: 0
D9: 3 | E9: [Metrika] | F9: Reja | G9: 0 | H9: =IFERROR(G10/G9,"") | I9: 0 | J9: =H9*I9 -> 0
F10: Fakt | G10: 0
C11: Sotuv | D11: 1 | E11: [Metrika] | F11: Reja | G11: 0 | H11: =IFERROR(G12/G11,"") | I11: 0 | J11: =H11*I11 -> 0 | K11: =SUM(J11:J16) -> 0 | L11: 0 | M11: =K11*L11 -> 0
F12: Fakt | G12: 0
D13: 2 | E13: [Metrika] | F13: Reja | G13: 0 | H13: =IFERROR(G14/G13,"") | I13: 0 | J13: =H13*I13 -> 0
F14: Fakt | G14: 0
D15: 3 | E15: [Metrika] | F15: Reja | G15: 0 | H15: =IFERROR(G16/G15,"") | I15: 0 | J15: =H15*I15 -> 0
F16: Fakt | G16: 0
C17: Product | D17: 1 | E17: [Metrika] | F17: Reja | G17: 0 | H17: =IFERROR(G18/G17,"") | I17: 0 | J17: =H17*I17 -> 0 | K17: =SUM(J17:J24) -> 0 | L17: 0 | M17: =K17*L17 -> 0
F18: Fakt | G18: 0
D19: 2 | E19: [Metrika] | F19: Reja | G19: 0 | H19: =IFERROR(G20/G19,"") | I19: 0 | J19: =H19*I19 -> 0
F20: Fakt | G20: 0
D21: 3 | E21: [Metrika] | F21: Reja | G21: 0 | H21: =IFERROR(G22/G21,"") | I21: 0 | J21: =H21*I21 -> 0
F22: Fakt | G22: 0
D23: 4 | E23: [Metrika] | F23: Reja | G23: 0 | H23: =IFERROR(G24/G23,"") | I23: 0 | J23: =H23*I23 -> 0
F24: Fakt | G24: 0
C25: Moliya | D25: 1 | E25: [Metrika] | F25: Reja | G25: 0 | H25: =IFERROR(G26/G25,"") | I25: 0 | J25: =H25*I25 -> 0 | K25: =SUM(J25:J30) -> 0 | L25: 0 | M25: =K25*L25 -> 0
F26: Fakt | G26: 0
D27: 2 | E27: [Metrika] | F27: Reja | G27: 0 | H27: =IFERROR(G28/G27,"") | I27: 0 | J27: =H27*I27 -> 0
F28: Fakt | G28: 0
D29: 3 | E29: [Metrika] | F29: Reja | G29: 0 | H29: =IFERROR(G30/G29,"") | I29: 0 | J29: =H29*I29 -> 0
F30: Fakt | G30: 0

Sheet Metrika
G2: 3 yillik
G3: SUM | H3: Yillik 1 | BW3: Yillik 2 | EL3: Yillik 3
H4: SUM | I4: Yarim yillik 1 | AP4: Yarim yillik 2 | BW4: SUM | BX4: Yarim yillik 3 | DE4: Yarim yillik 4 | EL4: SUM | EM4: Yarim yillik 5 | FT4: Yarim yillik 6
I5: SUM | J5: Chorak 1 | Z5: Chorak 2 | AP5: SUM | AQ5: Chorak 3 | BG5: Chorak 4 | BX5: SUM | BY5: Chorak 5 | CO5: Chorak 6 | DE5: SUM | DF5: Chorak 7 | DV5: Chorak 8 | EM5: SUM | EN5: Chorak 9 | FD5: Chorak 10 | FT5: SUM | FU5: Chorak 11 | GK5: Chorak 12
J6: SUM | K6: Oy 1 | P6: Oy 2 | U6: Oy 3 | Z6: SUM | AA6: Oy 4 | AF6: Oy 5 | AK6: Oy 6 | AQ6: SUM | AR6: Oy 7 | AW6: Oy 8 | BB6: Oy 9 | BG6: SUM | BH6: Oy 10 | BM6: Oy 11 | BR6: Oy 12 | BY6: SUM | BZ6: Oy 13 | CE6: Oy 14 | CJ6: Oy 15 | CO6: SUM | CP6: Oy 16 | CU6: Oy 17 | CZ6: Oy 18 | DF6: SUM | DG6: Oy 19 | DL6: Oy 20 | DQ6: Oy | DV6: SUM | DW6: Oy 22 | EB6: Oy 23 | EG6: Oy 24 | EN6: SUM | EO6: Oy 25 | ET6: Oy 26 | EY6: Oy 27 | FD6: SUM | FE6: Oy 28 | FJ6: Oy 29 | FO6: Oy 30 | FU6: SUM | FV6: Oy 31 | GA6: Oy 32 | GF6: Oy 33 | GK6: SUM | GL6: Oy 34 | GQ6: Oy 35 | GV6: Oy 36
D7: Metrika (ko'rsatkichlar) | G7: 3 yillik | H7: Yillik 1 | I7: Yarim yillik 1 | J7: Chorak 1 | K7: Oy 1 | L7: Hafta 1 | M7: Hafta 2 | N7: Hafta 3 | O7: Hafta 4 | P7: Oy 2 | Q7: Hafta 5 | R7: Hafta 6 | S7: Hafta 7 | T7: Hafta 8 | U7: Oy 3 | V7: Hafta 9 | W7: Hafta 10 | X7: Hafta 11 | Y7: Hafta 12 | Z7: Chorak 2 | AA7: Oy 4 | AB7: Hafta 13 | AC7: Hafta 14 | AD7: Hafta 15 | AE7: Hafta 16 | AF7: Oy 5 | AG7: Hafta 17 | AH7: Hafta 18 | AI7: Hafta 19 | AJ7: Hafta 20 | AK7: Oy 6 | AL7: Hafta | AM7: Hafta 22 | AN7: Hafta 23 | AO7: Hafta 24 | AP7: Yarim yillik 2 | AQ7: Chorak 3 | AR7: Oy 7 | AS7: Hafta 25 | AT7: Hafta 26 | AU7: Hafta 27 | AV7: Hafta 28 | AW7: Oy 8 | AX7: Hafta 29 | AY7: Hafta 30 | AZ7: Hafta 31 | BA7: Hafta 32 | BB7: Oy 9 | BC7: Hafta 33 | BD7: Hafta 34 | BE7: Hafta 35 | BF7: Hafta 36 | BG7: Chorak 4 | BH7: Oy 10 | BI7: Hafta 37 | BJ7: Hafta 38 | BK7: Hafta 39 | BL7: Hafta 40 | BM7: Oy 11 | BN7: Hafta 41 | BO7: Hafta 42 | BP7: Hafta 43 | BQ7: Hafta 44 | BR7: Oy 12 | BS7: Hafta 45 | BT7: Hafta 46 | BU7: Hafta 47 | BV7: Hafta 48 | BW7: Yillik 2 | BX7: Yarim yillik 3 | BY7: Chorak 5 | BZ7: Oy 13 | CA7: Hafta 49 | CB7: Hafta 50 | CC7: Hafta 51 | CD7: Hafta 52 | CE7: Oy 14 | CF7: Hafta 53 | CG7: Hafta 54 | CH7: Hafta 55 | CI7: Hafta 56 | CJ7: Oy 15 | CK7: Hafta 57 | CL7: Hafta 58 | CM7: Hafta 59 | CN7: Hafta 60 | CO7: Chorak 6 | CP7: Oy 16 | CQ7: Hafta 61 | CR7: Hafta 62 | CS7: Hafta 63 | CT7: Hafta 64 | CU7: Oy 17 | CV7: Hafta 65 | CW7: Hafta 66 | CX7: Hafta 67 | CY7: Hafta 68 | CZ7: Oy 18 | DA7: Hafta 69 | DB7: Hafta 70 | DC7: Hafta 71 | DD7: Hafta 72 | DE7: Yarim yillik 4 | DF7: Chorak 7 | DG7: Oy 19 | DH7: Hafta 73 | DI7: Hafta 74 | DJ7: Hafta 75 | DK7: Hafta 76 | DL7: Oy 20 | DM7: Hafta 77 | DN7: Hafta 78 | DO7: Hafta 79 | DP7: Hafta 80 | DQ7: Oy | DR7: Hafta 81 | DS7: Hafta 82 | DT7: Hafta 83 | DU7: Hafta 84 | DV7: Chorak 8 | DW7: Oy 22 | DX7: Hafta 85 | DY7: Hafta 86 | DZ7: Hafta 87 | EA7: Hafta 88 | EB7: Oy 23 | EC7: Hafta 89 | ED7: Hafta 90 | EE7: Hafta 91 | EF7: Hafta 92 | EG7: Oy 24 | EH7: Hafta 93 | EI7: Hafta 94 | EJ7: Hafta 95 | EK7: Hafta 96 | EL7: Yillik 3 | EM7: Yarim yillik 5 | EN7: Chorak 9 | EO7: Oy 25 | EP7: Hafta 97 | EQ7: Hafta 98 | ER7: Hafta 99 | ES7: Hafta 100 | ET7: Oy 26 | EU7: Hafta 101 | EV7: Hafta 102 | EW7: Hafta 103 | EX7: Hafta 104 | EY7: Oy 27 | EZ7: Hafta 105 | FA7: Hafta 106 | FB7: Hafta 107 | FC7: Hafta 108 | FD7: Chorak 10 | FE7: Oy 28 | FF7: Hafta 109 | FG7: Hafta 110 | FH7: Hafta 111 | FI7: Hafta 112 | FJ7: Oy 29 | FK7: Hafta 113 | FL7: Hafta 114 | FM7: Hafta 115 | FN7: Hafta 116 | FO7: Oy 30 | FP7: Hafta 117 | FQ7: Hafta 118 | FR7: Hafta 119 | FS7: Hafta 120 | FT7: Yarim yillik 6 | FU7: Chorak 11 | FV7: Oy 31 | FW7: Hafta 1 | FX7: Hafta 122 | FY7: Hafta 123 | FZ7: Hafta 124 | GA7: Oy 32 | GB7: Hafta 125 | GC7: Hafta 126 | GD7: Hafta 127 | GE7: Hafta 128 | GF7: Oy 33 | GG7: Hafta 129 | GH7: Hafta 130 | GI7: Hafta 131 | GJ7: Hafta 132 | GK7: Chorak 12 | GL7: Oy 34 | GM7: Hafta 133 | GN7: Hafta 134 | GO7: Hafta 135 | GP7: Hafta 136 | GQ7: Oy 35 | GR7: Hafta 137 | GS7: Hafta 138 | GT7: Hafta 139 | GU7: Hafta 140 | GV7: Oy 36 | GW7: Hafta 141 | GX7: Hafta 142 | GY7: Hafta 143 | GZ7: Hafta 144
B8: Marketing | C8: 1 | D8: [Metrika] | E8: Reja | G8: =SUM(H8:GZ8)/5 -> 0 | H8: =SUM(I8:BV8)/4 -> 0 | I8: =SUM(J8:AO8)/3 -> 0 | J8: =SUM(K8:Y8)/2 -> 0 | K8: =SUM(L8:O8) -> 0 | P8: =SUM(Q8:T8) -> 0 | U8: =SUM(V8:Y8) -> 0 | Z8: =SUM(AA8:AO8)/2 -> 0 | AA8: =SUM(AB8:AE8) -> 0 | AF8: =SUM(AG8:AJ8) -> 0 | AK8: =SUM(AL8:AO8) -> 0 | AP8: =SUM(AQ8:BV8)/3 -> 0 | AQ8: =SUM(AR8:BF8)/2 -> 0 | AR8: =SUM(AS8:AV8) -> 0 | AW8: =SUM(AX8:BA8) -> 0 | BB8: =SUM(BC8:BF8) -> 0 | BG8: =SUM(BH8:BV8)/2 -> 0 | BH8: =SUM(BI8:BL8) -> 0 | BM8: =SUM(BN8:BQ8) -> 0 | BR8: =SUM(BS8:BV8) -> 0 | BW8: =SUM(BX8:EK8)/4 -> 0 | BX8: =SUM(BY8:DD8)/3 -> 0 | BY8: =SUM(BZ8:CN8)/2 -> 0 | BZ8: =SUM(CA8:CD8) -> 0 | CE8: =SUM(CF8:CI8) -> 0 | CJ8: =SUM(CK8:CN8) -> 0 | CO8: =SUM(CP8:DD8)/2 -> 0 | CP8: =SUM(CQ8:CT8) -> 0 | CU8: =SUM(CV8:CY8) -> 0 | CZ8: =SUM(DA8:DD8) -> 0 | DE8: =SUM(DF8:EK8)/3 -> 0 | DF8: =SUM(DG8:DU8)/2 -> 0 | DG8: =SUM(DH8:DK8) -> 0 | DL8: =SUM(DM8:DP8) -> 0 | DQ8: =SUM(DR8:DU8) -> 0 | DV8: =SUM(DW8:EK8)/2 -> 0 | DW8: =SUM(DX8:EA8) -> 0 | EB8: =SUM(EC8:EF8) -> 0 | EG8: =SUM(EH8:EK8) -> 0 | EL8: =SUM(EM8:GZ8)/4 -> 0 | EM8: =SUM(EN8:FS8)/3 -> 0 | EN8: =SUM(EO8:FC8)/2 -> 0 | EO8: =SUM(EP8:ES8) -> 0 | ET8: =SUM(EU8:EX8) -> 0 | EY8: =SUM(EZ8:FC8) -> 0 | FD8: =SUM(FE8:FS8)/2 -> 0 | FE8: =SUM(FF8:FI8) -> 0 | FJ8: =SUM(FK8:FN8) -> 0 | FO8: =SUM(FP8:FS8) -> 0 | FT8: =SUM(FU8:GZ8)/3 -> 0 | FU8: =SUM(FV8:GJ8)/2 -> 0 | FV8: =SUM(FW8:FZ8) -> 0 | GA8: =SUM(GB8:GE8) -> 0 | GF8: =SUM(GG8:GJ8) -> 0 | GK8: =SUM(GL8:GZ8)/2 -> 0 | GL8: =SUM(GM8:GP8) -> 0 | GQ8: =SUM(GR8:GU8) -> 0 | GV8: =SUM(GW8:GZ8) -> 0
E9: Fakt | G9: =SUM(H9:GZ9)/5 -> 0 | H9: =SUM(I9:BV9)/4 -> 0 | I9: =SUM(J9:AO9)/3 -> 0 | J9: =SUM(K9:Y9)/2 -> 0 | K9: =SUM(L9:O9) -> 0 | P9: =SUM(Q9:T9) -> 0 | U9: =SUM(V9:Y9) -> 0 | Z9: =SUM(AA9:AO9)/2 -> 0 | AA9: =SUM(AB9:AE9) -> 0 | AF9: =SUM(AG9:AJ9) -> 0 | AK9: =SUM(AL9:AO9) -> 0 | AP9: =SUM(AQ9:BV9)/3 -> 0 | AQ9: =SUM(AR9:BF9)/2 -> 0 | AR9: =SUM(AS9:AV9) -> 0 | AW9: =SUM(AX9:BA9) -> 0 | BB9: =SUM(BC9:BF9) -> 0 | BG9: =SUM(BH9:BV9)/2 -> 0 | BH9: =SUM(BI9:BL9) -> 0 | BM9: =SUM(BN9:BQ9) -> 0 | BR9: =SUM(BS9:BV9) -> 0 | BW9: =SUM(BX9:EK9)/4 -> 0 | BX9: =SUM(BY9:DD9)/3 -> 0 | BY9: =SUM(BZ9:CN9)/2 -> 0 | BZ9: =SUM(CA9:CD9) -> 0 | CE9: =SUM(CF9:CI9) -> 0 | CJ9: =SUM(CK9:CN9) -> 0 | CO9: =SUM(CP9:DD9)/2 -> 0 | CP9: =SUM(CQ9:CT9) -> 0 | CU9: =SUM(CV9:CY9) -> 0 | CZ9: =SUM(DA9:DD9) -> 0 | DE9: =SUM(DF9:EK9)/3 -> 0 | DF9: =SUM(DG9:DU9)/2 -> 0 | DG9: =SUM(DH9:DK9) -> 0 | DL9: =SUM(DM9:DP9) -> 0 | DQ9: =SUM(DR9:DU9) -> 0 | DV9: =SUM(DW9:EK9)/2 -> 0 | DW9: =SUM(DX9:EA9) -> 0 | EB9: =SUM(EC9:EF9) -> 0 | EG9: =SUM(EH9:EK9) -> 0 | EL9: =SUM(EM9:GZ9)/4 -> 0 | EM9: =SUM(EN9:FS9)/3 -> 0 | EN9: =SUM(EO9:FC9)/2 -> 0 | EO9: =SUM(EP9:ES9) -> 0 | ET9: =SUM(EU9:EX9) -> 0 | EY9: =SUM(EZ9:FC9) -> 0 | FD9: =SUM(FE9:FS9)/2 -> 0 | FE9: =SUM(FF9:FI9) -> 0 | FJ9: =SUM(FK9:FN9) -> 0 | FO9: =SUM(FP9:FS9) -> 0 | FT9: =SUM(FU9:GZ9)/3 -> 0 | FU9: =SUM(FV9:GJ9)/2 -> 0 | FV9: =SUM(FW9:FZ9) -> 0 | GA9: =SUM(GB9:GE9) -> 0 | GF9: =SUM(GG9:GJ9) -> 0 | GK9: =SUM(GL9:GZ9)/2 -> 0 | GL9: =SUM(GM9:GP9) -> 0 | GQ9: =SUM(GR9:GU9) -> 0 | GV9: =SUM(GW9:GZ9) -> 0
C10: 2 | D10: [Metrika] | E10: Reja | G10: =SUM(H10:GZ10)/5 -> 0 | H10: =SUM(I10:BV10)/4 -> 0 | I10: =SUM(J10:AO10)/3 -> 0 | J10: =SUM(K10:Y10)/2 -> 0 | K10: =SUM(L10:O10) -> 0 | P10: =SUM(Q10:T10) -> 0 | U10: =SUM(V10:Y10) -> 0 | Z10: =SUM(AA10:AO10)/2 -> 0 | AA10: =SUM(AB10:AE10) -> 0 | AF10: =SUM(AG10:AJ10) -> 0 | AK10: =SUM(AL10:AO10) -> 0 | AP10: =SUM(AQ10:BV10)/3 -> 0 | AQ10: =SUM(AR10:BF10)/2 -> 0 | AR10: =SUM(AS10:AV10) -> 0 | AW10: =SUM(AX10:BA10) -> 0 | BB10: =SUM(BC10:BF10) -> 0 | BG10: =SUM(BH10:BV10)/2 -> 0 | BH10: =SUM(BI10:BL10) -> 0 | BM10: =SUM(BN10:BQ10) -> 0 | BR10: =SUM(BS10:BV10) -> 0 | BW10: =SUM(BX10:EK10)/4 -> 0 | BX10: =SUM(BY10:DD10)/3 -> 0 | BY10: =SUM(BZ10:CN10)/2 -> 0 | BZ10: =SUM(CA10:CD10) -> 0 | CE10: =SUM(CF10:CI10) -> 0 | CJ10: =SUM(CK10:CN10) -> 0 | CO10: =SUM(CP10:DD10)/2 -> 0 | CP10: =SUM(CQ10:CT10) -> 0 | CU10: =SUM(CV10:CY10) -> 0 | CZ10: =SUM(DA10:DD10) -> 0 | DE10: =SUM(DF10:EK10)/3 -> 0 | DF10: =SUM(DG10:DU10)/2 -> 0 | DG10: =SUM(DH10:DK10) -> 0 | DL10: =SUM(DM10:DP10) -> 0 | DQ10: =SUM(DR10:DU10) -> 0 | DV10: =SUM(DW10:EK10)/2 -> 0 | DW10: =SUM(DX10:EA10) -> 0 | EB10: =SUM(EC10:EF10) -> 0 | EG10: =SUM(EH10:EK10) -> 0 | EL10: =SUM(EM10:GZ10)/4 -> 0 | EM10: =SUM(EN10:FS10)/3 -> 0 | EN10: =SUM(EO10:FC10)/2 -> 0 | EO10: =SUM(EP10:ES10) -> 0 | ET10: =SUM(EU10:EX10) -> 0 | EY10: =SUM(EZ10:FC10) -> 0 | FD10: =SUM(FE10:FS10)/2 -> 0 | FE10: =SUM(FF10:FI10) -> 0 | FJ10: =SUM(FK10:FN10) -> 0 | FO10: =SUM(FP10:FS10) -> 0 | FT10: =SUM(FU10:GZ10)/3 -> 0 | FU10: =SUM(FV10:GJ10)/2 -> 0 | FV10: =SUM(FW10:FZ10) -> 0 | GA10: =SUM(GB10:GE10) -> 0 | GF10: =SUM(GG10:GJ10) -> 0 | GK10: =SUM(GL10:GZ10)/2 -> 0 | GL10: =SUM(GM10:GP10) -> 0 | GQ10: =SUM(GR10:GU10) -> 0 | GV10: =SUM(GW10:GZ10) -> 0
E11: Fakt | G11: =SUM(H11:GZ11)/5 -> 0 | H11: =SUM(I11:BV11)/4 -> 0 | I11: =SUM(J11:AO11)/3 -> 0 | J11: =SUM(K11:Y11)/2 -> 0 | K11: =SUM(L11:O11) -> 0 | P11: =SUM(Q11:T11) -> 0 | U11: =SUM(V11:Y11) -> 0 | Z11: =SUM(AA11:AO11)/2 -> 0 | AA11: =SUM(AB11:AE11) -> 0 | AF11: =SUM(AG11:AJ11) -> 0 | AK11: =SUM(AL11:AO11) -> 0 | AP11: =SUM(AQ11:BV11)/3 -> 0 | AQ11: =SUM(AR11:BF11)/2 -> 0 | AR11: =SUM(AS11:AV11) -> 0 | AW11: =SUM(AX11:BA11) -> 0 | BB11: =SUM(BC11:BF11) -> 0 | BG11: =SUM(BH11:BV11)/2 -> 0 | BH11: =SUM(BI11:BL11) -> 0 | BM11: =SUM(BN11:BQ11) -> 0 | BR11: =SUM(BS11:BV11) -> 0 | BW11: =SUM(BX11:EK11)/4 -> 0 | BX11: =SUM(BY11:DD11)/3 -> 0 | BY11: =SUM(BZ11:CN11)/2 -> 0 | BZ11: =SUM(CA11:CD11) -> 0 | CE11: =SUM(CF11:CI11) -> 0 | CJ11: =SUM(CK11:CN11) -> 0 | CO11: =SUM(CP11:DD11)/2 -> 0 | CP11: =SUM(CQ11:CT11) -> 0 | CU11: =SUM(CV11:CY11) -> 0 | CZ11: =SUM(DA11:DD11) -> 0 | DE11: =SUM(DF11:EK11)/3 -> 0 | DF11: =SUM(DG11:DU11)/2 -> 0 | DG11: =SUM(DH11:DK11) -> 0 | DL11: =SUM(DM11:DP11) -> 0 | DQ11: =SUM(DR11:DU11) -> 0 | DV11: =SUM(DW11:EK11)/2 -> 0 | DW11: =SUM(DX11:EA11) -> 0 | EB11: =SUM(EC11:EF11) -> 0 | EG11: =SUM(EH11:EK11) -> 0 | EL11: =SUM(EM11:GZ11)/4 -> 0 | EM11: =SUM(EN11:FS11)/3 -> 0 | EN11: =SUM(EO11:FC11)/2 -> 0 | EO11: =SUM(EP11:ES11) -> 0 | ET11: =SUM(EU11:EX11) -> 0 | EY11: =SUM(EZ11:FC11) -> 0 | FD11: =SUM(FE11:FS11)/2 -> 0 | FE11: =SUM(FF11:FI11) -> 0 | FJ11: =SUM(FK11:FN11) -> 0 | FO11: =SUM(FP11:FS11) -> 0 | FT11: =SUM(FU11:GZ11)/3 -> 0 | FU11: =SUM(FV11:GJ11)/2 -> 0 | FV11: =SUM(FW11:FZ11) -> 0 | GA11: =SUM(GB11:GE11) -> 0 | GF11: =SUM(GG11:GJ11) -> 0 | GK11: =SUM(GL11:GZ11)/2 -> 0 | GL11: =SUM(GM11:GP11) -> 0 | GQ11: =SUM(GR11:GU11) -> 0 | GV11: =SUM(GW11:GZ11) -> 0
C12: 3 | D12: [Metrika] | E12: Reja | G12: =SUM(H12:GZ12)/5 -> 0 | H12: =SUM(I12:BV12)/4 -> 0 | I12: =SUM(J12:AO12)/3 -> 0 | J12: =SUM(K12:Y12)/2 -> 0 | K12: =SUM(L12:O12) -> 0 | P12: =SUM(Q12:T12) -> 0 | U12: =SUM(V12:Y12) -> 0 | Z12: =SUM(AA12:AO12)/2 -> 0 | AA12: =SUM(AB12:AE12) -> 0 | AF12: =SUM(AG12:AJ12) -> 0 | AK12: =SUM(AL12:AO12) -> 0 | AP12: =SUM(AQ12:BV12)/3 -> 0 | AQ12: =SUM(AR12:BF12)/2 -> 0 | AR12: =SUM(AS12:AV12) -> 0 | AW12: =SUM(AX12:BA12) -> 0 | BB12: =SUM(BC12:BF12) -> 0 | BG12: =SUM(BH12:BV12)/2 -> 0 | BH12: =SUM(BI12:BL12) -> 0 | BM12: =SUM(BN12:BQ12) -> 0 | BR12: =SUM(BS12:BV12) -> 0 | BW12: =SUM(BX12:EK12)/4 -> 0 | BX12: =SUM(BY12:DD12)/3 -> 0 | BY12: =SUM(BZ12:CN12)/2 -> 0 | BZ12: =SUM(CA12:CD12) -> 0 | CE12: =SUM(CF12:CI12) -> 0 | CJ12: =SUM(CK12:CN12) -> 0 | CO12: =SUM(CP12:DD12)/2 -> 0 | CP12: =SUM(CQ12:CT12) -> 0 | CU12: =SUM(CV12:CY12) -> 0 | CZ12: =SUM(DA12:DD12) -> 0 | DE12: =SUM(DF12:EK12)/3 -> 0 | DF12: =SUM(DG12:DU12)/2 -> 0 | DG12: =SUM(DH12:DK12) -> 0 | DL12: =SUM(DM12:DP12) -> 0 | DQ12: =SUM(DR12:DU12) -> 0 | DV12: =SUM(DW12:EK12)/2 -> 0 | DW12: =SUM(DX12:EA12) -> 0 | EB12: =SUM(EC12:EF12) -> 0 | EG12: =SUM(EH12:EK12) -> 0 | EL12: =SUM(EM12:GZ12)/4 -> 0 | EM12: =SUM(EN12:FS12)/3 -> 0 | EN12: =SUM(EO12:FC12)/2 -> 0 | EO12: =SUM(EP12:ES12) -> 0 | ET12: =SUM(EU12:EX12) -> 0 | EY12: =SUM(EZ12:FC12) -> 0 | FD12: =SUM(FE12:FS12)/2 -> 0 | FE12: =SUM(FF12:FI12) -> 0 | FJ12: =SUM(FK12:FN12) -> 0 | FO12: =SUM(FP12:FS12) -> 0 | FT12: =SUM(FU12:GZ12)/3 -> 0 | FU12: =SUM(FV12:GJ12)/2 -> 0 | FV12: =SUM(FW12:FZ12) -> 0 | GA12: =SUM(GB12:GE12) -> 0 | GF12: =SUM(GG12:GJ12) -> 0 | GK12: =SUM(GL12:GZ12)/2 -> 0 | GL12: =SUM(GM12:GP12) -> 0 | GQ12: =SUM(GR12:GU12) -> 0 | GV12: =SUM(GW12:GZ12) -> 0
E13: Fakt | G13: =SUM(H13:GZ13)/5 -> 0 | H13: =SUM(I13:BV13)/4 -> 0 | I13: =SUM(J13:AO13)/3 -> 0 | J13: =SUM(K13:Y13)/2 -> 0 | K13: =SUM(L13:O13) -> 0 | P13: =SUM(Q13:T13) -> 0 | U13: =SUM(V13:Y13) -> 0 | Z13: =SUM(AA13:AO13)/2 -> 0 | AA13: =SUM(AB13:AE13) -> 0 | AF13: =SUM(AG13:AJ13) -> 0 | AK13: =SUM(AL13:AO13) -> 0 | AP13: =SUM(AQ13:BV13)/3 -> 0 | AQ13: =SUM(AR13:BF13)/2 -> 0 | AR13: =SUM(AS13:AV13) -> 0 | AW13: =SUM(AX13:BA13) -> 0 | BB13: =SUM(BC13:BF13) -> 0 | BG13: =SUM(BH13:BV13)/2 -> 0 | BH13: =SUM(BI13:BL13) -> 0 | BM13: =SUM(BN13:BQ13) -> 0 | BR13: =SUM(BS13:BV13) -> 0 | BW13: =SUM(BX13:EK13)/4 -> 0 | BX13: =SUM(BY13:DD13)/3 -> 0 | BY13: =SUM(BZ13:CN13)/2 -> 0 | BZ13: =SUM(CA13:CD13) -> 0 | CE13: =SUM(CF13:CI13) -> 0 | CJ13: =SUM(CK13:CN13) -> 0 | CO13: =SUM(CP13:DD13)/2 -> 0 | CP13: =SUM(CQ13:CT13) -> 0 | CU13: =SUM(CV13:CY13) -> 0 | CZ13: =SUM(DA13:DD13) -> 0 | DE13: =SUM(DF13:EK13)/3 -> 0 | DF13: =SUM(DG13:DU13)/2 -> 0 | DG13: =SUM(DH13:DK13) -> 0 | DL13: =SUM(DM13:DP13) -> 0 | DQ13: =SUM(DR13:DU13) -> 0 | DV13: =SUM(DW13:EK13)/2 -> 0 | DW13: =SUM(DX13:EA13) -> 0 | EB13: =SUM(EC13:EF13) -> 0 | EG13: =SUM(EH13:EK13) -> 0 | EL13: =SUM(EM13:GZ13)/4 -> 0 | EM13: =SUM(EN13:FS13)/3 -> 0 | EN13: =SUM(EO13:FC13)/2 -> 0 | EO13: =SUM(EP13:ES13) -> 0 | ET13: =SUM(EU13:EX13) -> 0 | EY13: =SUM(EZ13:FC13) -> 0 | FD13: =SUM(FE13:FS13)/2 -> 0 | FE13: =SUM(FF13:FI13) -> 0 | FJ13: =SUM(FK13:FN13) -> 0 | FO13: =SUM(FP13:FS13) -> 0 | FT13: =SUM(FU13:GZ13)/3 -> 0 | FU13: =SUM(FV13:GJ13)/2 -> 0 | FV13: =SUM(FW13:FZ13) -> 0 | GA13: =SUM(GB13:GE13) -> 0 | GF13: =SUM(GG13:GJ13) -> 0 | GK13: =SUM(GL13:GZ13)/2 -> 0 | GL13: =SUM(GM13:GP13) -> 0 | GQ13: =SUM(GR13:GU13) -> 0 | GV13: =SUM(GW13:GZ13) -> 0
B14: Sotuv | C14: 1 | D14: [Metrika] | E14: Reja | G14: =SUM(H14:GZ14)/5 -> 0 | H14: =SUM(I14:BV14)/4 -> 0 | I14: =SUM(J14:AO14)/3 -> 0 | J14: =SUM(K14:Y14)/2 -> 0 | K14: =SUM(L14:O14) -> 0 | P14: =SUM(Q14:T14) -> 0 | U14: =SUM(V14:Y14) -> 0 | Z14: =SUM(AA14:AO14)/2 -> 0 | AA14: =SUM(AB14:AE14) -> 0 | AF14: =SUM(AG14:AJ14) -> 0 | AK14: =SUM(AL14:AO14) -> 0 | AP14: =SUM(AQ14:BV14)/3 -> 0 | AQ14: =SUM(AR14:BF14)/2 -> 0 | AR14: =SUM(AS14:AV14) -> 0 | AW14: =SUM(AX14:BA14) -> 0 | BB14: =SUM(BC14:BF14) -> 0 | BG14: =SUM(BH14:BV14)/2 -> 0 | BH14: =SUM(BI14:BL14) -> 0 | BM14: =SUM(BN14:BQ14) -> 0 | BR14: =SUM(BS14:BV14) -> 0 | BW14: =SUM(BX14:EK14)/4 -> 0 | BX14: =SUM(BY14:DD14)/3 -> 0 | BY14: =SUM(BZ14:CN14)/2 -> 0 | BZ14: =SUM(CA14:CD14) -> 0 | CE14: =SUM(CF14:CI14) -> 0 | CJ14: =SUM(CK14:CN14) -> 0 | CO14: =SUM(CP14:DD14)/2 -> 0 | CP14: =SUM(CQ14:CT14) -> 0 | CU14: =SUM(CV14:CY14) -> 0 | CZ14: =SUM(DA14:DD14) -> 0 | DE14: =SUM(DF14:EK14)/3 -> 0 | DF14: =SUM(DG14:DU14)/2 -> 0 | DG14: =SUM(DH14:DK14) -> 0 | DL14: =SUM(DM14:DP14) -> 0 | DQ14: =SUM(DR14:DU14) -> 0 | DV14: =SUM(DW14:EK14)/2 -> 0 | DW14: =SUM(DX14:EA14) -> 0 | EB14: =SUM(EC14:EF14) -> 0 | EG14: =SUM(EH14:EK14) -> 0 | EL14: =SUM(EM14:GZ14)/4 -> 0 | EM14: =SUM(EN14:FS14)/3 -> 0 | EN14: =SUM(EO14:FC14)/2 -> 0 | EO14: =SUM(EP14:ES14) -> 0 | ET14: =SUM(EU14:EX14) -> 0 | EY14: =SUM(EZ14:FC14) -> 0 | FD14: =SUM(FE14:FS14)/2 -> 0 | FE14: =SUM(FF14:FI14) -> 0 | FJ14: =SUM(FK14:FN14) -> 0 | FO14: =SUM(FP14:FS14) -> 0 | FT14: =SUM(FU14:GZ14)/3 -> 0 | FU14: =SUM(FV14:GJ14)/2 -> 0 | FV14: =SUM(FW14:FZ14) -> 0 | GA14: =SUM(GB14:GE14) -> 0 | GF14: =SUM(GG14:GJ14) -> 0 | GK14: =SUM(GL14:GZ14)/2 -> 0 | GL14: =SUM(GM14:GP14) -> 0 | GQ14: =SUM(GR14:GU14) -> 0 | GV14: =SUM(GW14:GZ14) -> 0
E15: Fakt | G15: =SUM(H15:GZ15)/5 -> 0 | H15: =SUM(I15:BV15)/4 -> 0 | I15: =SUM(J15:AO15)/3 -> 0 | J15: =SUM(K15:Y15)/2 -> 0 | K15: =SUM(L15:O15) -> 0 | P15: =SUM(Q15:T15) -> 0 | U15: =SUM(V15:Y15) -> 0 | Z15: =SUM(AA15:AO15)/2 -> 0 | AA15: =SUM(AB15:AE15) -> 0 | AF15: =SUM(AG15:AJ15) -> 0 | AK15: =SUM(AL15:AO15) -> 0 | AP15: =SUM(AQ15:BV15)/3 -> 0 | AQ15: =SUM(AR15:BF15)/2 -> 0 | AR15: =SUM(AS15:AV15) -> 0 | AW15: =SUM(AX15:BA15) -> 0 | BB15: =SUM(BC15:BF15) -> 0 | BG15: =SUM(BH15:BV15)/2 -> 0 | BH15: =SUM(BI15:BL15) -> 0 | BM15: =SUM(BN15:BQ15) -> 0 | BR15: =SUM(BS15:BV15) -> 0 | BW15: =SUM(BX15:EK15)/4 -> 0 | BX15: =SUM(BY15:DD15)/3 -> 0 | BY15: =SUM(BZ15:CN15)/2 -> 0 | BZ15: =SUM(CA15:CD15) -> 0 | CE15: =SUM(CF15:CI15) -> 0 | CJ15: =SUM(CK15:CN15) -> 0 | CO15: =SUM(CP15:DD15)/2 -> 0 | CP15: =SUM(CQ15:CT15) -> 0 | CU15: =SUM(CV15:CY15) -> 0 | CZ15: =SUM(DA15:DD15) -> 0 | DE15: =SUM(DF15:EK15)/3 -> 0 | DF15: =SUM(DG15:DU15)/2 -> 0 | DG15: =SUM(DH15:DK15) -> 0 | DL15: =SUM(DM15:DP15) -> 0 | DQ15: =SUM(DR15:DU15) -> 0 | DV15: =SUM(DW15:EK15)/2 -> 0 | DW15: =SUM(DX15:EA15) -> 0 | EB15: =SUM(EC15:EF15) -> 0 | EG15: =SUM(EH15:EK15) -> 0 | EL15: =SUM(EM15:GZ15)/4 -> 0 | EM15: =SUM(EN15:FS15)/3 -> 0 | EN15: =SUM(EO15:FC15)/2 -> 0 | EO15: =SUM(EP15:ES15) -> 0 | ET15: =SUM(EU15:EX15) -> 0 | EY15: =SUM(EZ15:FC15) -> 0 | FD15: =SUM(FE15:FS15)/2 -> 0 | FE15: =SUM(FF15:FI15) -> 0 | FJ15: =SUM(FK15:FN15) -> 0 | FO15: =SUM(FP15:FS15) -> 0 | FT15: =SUM(FU15:GZ15)/3 -> 0 | FU15: =SUM(FV15:GJ15)/2 -> 0 | FV15: =SUM(FW15:FZ15) -> 0 | GA15: =SUM(GB15:GE15) -> 0 | GF15: =SUM(GG15:GJ15) -> 0 | GK15: =SUM(GL15:GZ15)/2 -> 0 | GL15: =SUM(GM15:GP15) -> 0 | GQ15: =SUM(GR15:GU15) -> 0 | GV15: =SUM(GW15:GZ15) -> 0
C16: 2 | D16: [Metrika] | E16: Reja | G16: =SUM(H16:GZ16)/5 -> 0 | H16: =SUM(I16:BV16)/4 -> 0 | I16: =SUM(J16:AO16)/3 -> 0 | J16: =SUM(K16:Y16)/2 -> 0 | K16: =SUM(L16:O16) -> 0 | P16: =SUM(Q16:T16) -> 0 | U16: =SUM(V16:Y16) -> 0 | Z16: =SUM(AA16:AO16)/2 -> 0 | AA16: =SUM(AB16:AE16) -> 0 | AF16: =SUM(AG16:AJ16) -> 0 | AK16: =SUM(AL16:AO16) -> 0 | AP16: =SUM(AQ16:BV16)/3 -> 0 | AQ16: =SUM(AR16:BF16)/2 -> 0 | AR16: =SUM(AS16:AV16) -> 0 | AW16: =SUM(AX16:BA16) -> 0 | BB16: =SUM(BC16:BF16) -> 0 | BG16: =SUM(BH16:BV16)/2 -> 0 | BH16: =SUM(BI16:BL16) -> 0 | BM16: =SUM(BN16:BQ16) -> 0 | BR16: =SUM(BS16:BV16) -> 0 | BW16: =SUM(BX16:EK16)/4 -> 0 | BX16: =SUM(BY16:DD16)/3 -> 0 | BY16: =SUM(BZ16:CN16)/2 -> 0 | BZ16: =SUM(CA16:CD16) -> 0 | CE16: =SUM(CF16:CI16) -> 0 | CJ16: =SUM(CK16:CN16) -> 0 | CO16: =SUM(CP16:DD16)/2 -> 0 | CP16: =SUM(CQ16:CT16) -> 0 | CU16: =SUM(CV16:CY16) -> 0 | CZ16: =SUM(DA16:DD16) -> 0 | DE16: =SUM(DF16:EK16)/3 -> 0 | DF16: =SUM(DG16:DU16)/2 -> 0 | DG16: =SUM(DH16:DK16) -> 0 | DL16: =SUM(DM16:DP16) -> 0 | DQ16: =SUM(DR16:DU16) -> 0 | DV16: =SUM(DW16:EK16)/2 -> 0 | DW16: =SUM(DX16:EA16) -> 0 | EB16: =SUM(EC16:EF16) -> 0 | EG16: =SUM(EH16:EK16) -> 0 | EL16: =SUM(EM16:GZ16)/4 -> 0 | EM16: =SUM(EN16:FS16)/3 -> 0 | EN16: =SUM(EO16:FC16)/2 -> 0 | EO16: =SUM(EP16:ES16) -> 0 | ET16: =SUM(EU16:EX16) -> 0 | EY16: =SUM(EZ16:FC16) -> 0 | FD16: =SUM(FE16:FS16)/2 -> 0 | FE16: =SUM(FF16:FI16) -> 0 | FJ16: =SUM(FK16:FN16) -> 0 | FO16: =SUM(FP16:FS16) -> 0 | FT16: =SUM(FU16:GZ16)/3 -> 0 | FU16: =SUM(FV16:GJ16)/2 -> 0 | FV16: =SUM(FW16:FZ16) -> 0 | GA16: =SUM(GB16:GE16) -> 0 | GF16: =SUM(GG16:GJ16) -> 0 | GK16: =SUM(GL16:GZ16)/2 -> 0 | GL16: =SUM(GM16:GP16) -> 0 | GQ16: =SUM(GR16:GU16) -> 0 | GV16: =SUM(GW16:GZ16) -> 0
E17: Fakt | G17: =SUM(H17:GZ17)/5 -> 0 | H17: =SUM(I17:BV17)/4 -> 0 | I17: =SUM(J17:AO17)/3 -> 0 | J17: =SUM(K17:Y17)/2 -> 0 | K17: =SUM(L17:O17) -> 0 | P17: =SUM(Q17:T17) -> 0 | U17: =SUM(V17:Y17) -> 0 | Z17: =SUM(AA17:AO17)/2 -> 0 | AA17: =SUM(AB17:AE17) -> 0 | AF17: =SUM(AG17:AJ17) -> 0 | AK17: =SUM(AL17:AO17) -> 0 | AP17: =SUM(AQ17:BV17)/3 -> 0 | AQ17: =SUM(AR17:BF17)/2 -> 0 | AR17: =SUM(AS17:AV17) -> 0 | AW17: =SUM(AX17:BA17) -> 0 | BB17: =SUM(BC17:BF17) -> 0 | BG17: =SUM(BH17:BV17)/2 -> 0 | BH17: =SUM(BI17:BL17) -> 0 | BM17: =SUM(BN17:BQ17) -> 0 | BR17: =SUM(BS17:BV17) -> 0 | BW17: =SUM(BX17:EK17)/4 -> 0 | BX17: =SUM(BY17:DD17)/3 -> 0 | BY17: =SUM(BZ17:CN17)/2 -> 0 | BZ17: =SUM(CA17:CD17) -> 0 | CE17: =SUM(CF17:CI17) -> 0 | CJ17: =SUM(CK17:CN17) -> 0 | CO17: =SUM(CP17:DD17)/2 -> 0 | CP17: =SUM(CQ17:CT17) -> 0 | CU17: =SUM(CV17:CY17) -> 0 | CZ17: =SUM(DA17:DD17) -> 0 | DE17: =SUM(DF17:EK17)/3 -> 0 | DF17: =SUM(DG17:DU17)/2 -> 0 | DG17: =SUM(DH17:DK17) -> 0 | DL17: =SUM(DM17:DP17) -> 0 | DQ17: =SUM(DR17:DU17) -> 0 | DV17: =SUM(DW17:EK17)/2 -> 0 | DW17: =SUM(DX17:EA17) -> 0 | EB17: =SUM(EC17:EF17) -> 0 | EG17: =SUM(EH17:EK17) -> 0 | EL17: =SUM(EM17:GZ17)/4 -> 0 | EM17: =SUM(EN17:FS17)/3 -> 0 | EN17: =SUM(EO17:FC17)/2 -> 0 | EO17: =SUM(EP17:ES17) -> 0 | ET17: =SUM(EU17:EX17) -> 0 | EY17: =SUM(EZ17:FC17) -> 0 | FD17: =SUM(FE17:FS17)/2 -> 0 | FE17: =SUM(FF17:FI17) -> 0 | FJ17: =SUM(FK17:FN17) -> 0 | FO17: =SUM(FP17:FS17) -> 0 | FT17: =SUM(FU17:GZ17)/3 -> 0 | FU17: =SUM(FV17:GJ17)/2 -> 0 | FV17: =SUM(FW17:FZ17) -> 0 | GA17: =SUM(GB17:GE17) -> 0 | GF17: =SUM(GG17:GJ17) -> 0 | GK17: =SUM(GL17:GZ17)/2 -> 0 | GL17: =SUM(GM17:GP17) -> 0 | GQ17: =SUM(GR17:GU17) -> 0 | GV17: =SUM(GW17:GZ17) -> 0
C18: 3 | D18: [Metrika] | E18: Reja | G18: =SUM(H18:GZ18)/5 -> 0 | H18: =SUM(I18:BV18)/4 -> 0 | I18: =SUM(J18:AO18)/3 -> 0 | J18: =SUM(K18:Y18)/2 -> 0 | K18: =SUM(L18:O18) -> 0 | P18: =SUM(Q18:T18) -> 0 | U18: =SUM(V18:Y18) -> 0 | Z18: =SUM(AA18:AO18)/2 -> 0 | AA18: =SUM(AB18:AE18) -> 0 | AF18: =SUM(AG18:AJ18) -> 0 | AK18: =SUM(AL18:AO18) -> 0 | AP18: =SUM(AQ18:BV18)/3 -> 0 | AQ18: =SUM(AR18:BF18)/2 -> 0 | AR18: =SUM(AS18:AV18) -> 0 | AW18: =SUM(AX18:BA18) -> 0 | BB18: =SUM(BC18:BF18) -> 0 | BG18: =SUM(BH18:BV18)/2 -> 0 | BH18: =SUM(BI18:BL18) -> 0 | BM18: =SUM(BN18:BQ18) -> 0 | BR18: =SUM(BS18:BV18) -> 0 | BW18: =SUM(BX18:EK18)/4 -> 0 | BX18: =SUM(BY18:DD18)/3 -> 0 | BY18: =SUM(BZ18:CN18)/2 -> 0 | BZ18: =SUM(CA18:CD18) -> 0 | CE18: =SUM(CF18:CI18) -> 0 | CJ18: =SUM(CK18:CN18) -> 0 | CO18: =SUM(CP18:DD18)/2 -> 0 | CP18: =SUM(CQ18:CT18) -> 0 | CU18: =SUM(CV18:CY18) -> 0 | CZ18: =SUM(DA18:DD18) -> 0 | DE18: =SUM(DF18:EK18)/3 -> 0 | DF18: =SUM(DG18:DU18)/2 -> 0 | DG18: =SUM(DH18:DK18) -> 0 | DL18: =SUM(DM18:DP18) -> 0 | DQ18: =SUM(DR18:DU18) -> 0 | DV18: =SUM(DW18:EK18)/2 -> 0 | DW18: =SUM(DX18:EA18) -> 0 | EB18: =SUM(EC18:EF18) -> 0 | EG18: =SUM(EH18:EK18) -> 0 | EL18: =SUM(EM18:GZ18)/4 -> 0 | EM18: =SUM(EN18:FS18)/3 -> 0 | EN18: =SUM(EO18:FC18)/2 -> 0 | EO18: =SUM(EP18:ES18) -> 0 | ET18: =SUM(EU18:EX18) -> 0 | EY18: =SUM(EZ18:FC18) -> 0 | FD18: =SUM(FE18:FS18)/2 -> 0 | FE18: =SUM(FF18:FI18) -> 0 | FJ18: =SUM(FK18:FN18) -> 0 | FO18: =SUM(FP18:FS18) -> 0 | FT18: =SUM(FU18:GZ18)/3 -> 0 | FU18: =SUM(FV18:GJ18)/2 -> 0 | FV18: =SUM(FW18:FZ18) -> 0 | GA18: =SUM(GB18:GE18) -> 0 | GF18: =SUM(GG18:GJ18) -> 0 | GK18: =SUM(GL18:GZ18)/2 -> 0 | GL18: =SUM(GM18:GP18) -> 0 | GQ18: =SUM(GR18:GU18) -> 0 | GV18: =SUM(GW18:GZ18) -> 0
E19: Fakt | G19: =SUM(H19:GZ19)/5 -> 0 | H19: =SUM(I19:BV19)/4 -> 0 | I19: =SUM(J19:AO19)/3 -> 0 | J19: =SUM(K19:Y19)/2 -> 0 | K19: =SUM(L19:O19) -> 0 | P19: =SUM(Q19:T19) -> 0 | U19: =SUM(V19:Y19) -> 0 | Z19: =SUM(AA19:AO19)/2 -> 0 | AA19: =SUM(AB19:AE19) -> 0 | AF19: =SUM(AG19:AJ19) -> 0 | AK19: =SUM(AL19:AO19) -> 0 | AP19: =SUM(AQ19:BV19)/3 -> 0 | AQ19: =SUM(AR19:BF19)/2 -> 0 | AR19: =SUM(AS19:AV19) -> 0 | AW19: =SUM(AX19:BA19) -> 0 | BB19: =SUM(BC19:BF19) -> 0 | BG19: =SUM(BH19:BV19)/2 -> 0 | BH19: =SUM(BI19:BL19) -> 0 | BM19: =SUM(BN19:BQ19) -> 0 | BR19: =SUM(BS19:BV19) -> 0 | BW19: =SUM(BX19:EK19)/4 -> 0 | BX19: =SUM(BY19:DD19)/3 -> 0 | BY19: =SUM(BZ19:CN19)/2 -> 0 | BZ19: =SUM(CA19:CD19) -> 0 | CE19: =SUM(CF19:CI19) -> 0 | CJ19: =SUM(CK19:CN19) -> 0 | CO19: =SUM(CP19:DD19)/2 -> 0 | CP19: =SUM(CQ19:CT19) -> 0 | CU19: =SUM(CV19:CY19) -> 0 | CZ19: =SUM(DA19:DD19) -> 0 | DE19: =SUM(DF19:EK19)/3 -> 0 | DF19: =SUM(DG19:DU19)/2 -> 0 | DG19: =SUM(DH19:DK19) -> 0 | DL19: =SUM(DM19:DP19) -> 0 | DQ19: =SUM(DR19:DU19) -> 0 | DV19: =SUM(DW19:EK19)/2 -> 0 | DW19: =SUM(DX19:EA19) -> 0 | EB19: =SUM(EC19:EF19) -> 0 | EG19: =SUM(EH19:EK19) -> 0 | EL19: =SUM(EM19:GZ19)/4 -> 0 | EM19: =SUM(EN19:FS19)/3 -> 0 | EN19: =SUM(EO19:FC19)/2 -> 0 | EO19: =SUM(EP19:ES19) -> 0 | ET19: =SUM(EU19:EX19) -> 0 | EY19: =SUM(EZ19:FC19) -> 0 | FD19: =SUM(FE19:FS19)/2 -> 0 | FE19: =SUM(FF19:FI19) -> 0 | FJ19: =SUM(FK19:FN19) -> 0 | FO19: =SUM(FP19:FS19) -> 0 | FT19: =SUM(FU19:GZ19)/3 -> 0 | FU19: =SUM(FV19:GJ19)/2 -> 0 | FV19: =SUM(FW19:FZ19) -> 0 | GA19: =SUM(GB19:GE19) -> 0 | GF19: =SUM(GG19:GJ19) -> 0 | GK19: =SUM(GL19:GZ19)/2 -> 0 | GL19: =SUM(GM19:GP19) -> 0 | GQ19: =SUM(GR19:GU19) -> 0 | GV19: =SUM(GW19:GZ19) -> 0
B20: Product | C20: 1 | D20: [Metrika] | E20: Reja | G20: =SUM(H20:GZ20)/5 -> 0 | H20: =SUM(I20:BV20)/4 -> 0 | I20: =SUM(J20:AO20)/3 -> 0 | J20: =SUM(K20:Y20)/2 -> 0 | K20: =SUM(L20:O20) -> 0 | P20: =SUM(Q20:T20) -> 0 | U20: =SUM(V20:Y20) -> 0 | Z20: =SUM(AA20:AO20)/2 -> 0 | AA20: =SUM(AB20:AE20) -> 0 | AF20: =SUM(AG20:AJ20) -> 0 | AK20: =SUM(AL20:AO20) -> 0 | AP20: =SUM(AQ20:BV20)/3 -> 0 | AQ20: =SUM(AR20:BF20)/2 -> 0 | AR20: =SUM(AS20:AV20) -> 0 | AW20: =SUM(AX20:BA20) -> 0 | BB20: =SUM(BC20:BF20) -> 0 | BG20: =SUM(BH20:BV20)/2 -> 0 | BH20: =SUM(BI20:BL20) -> 0 | BM20: =SUM(BN20:BQ20) -> 0 | BR20: =SUM(BS20:BV20) -> 0 | BW20: =SUM(BX20:EK20)/4 -> 0 | BX20: =SUM(BY20:DD20)/3 -> 0 | BY20: =SUM(BZ20:CN20)/2 -> 0 | BZ20: =SUM(CA20:CD20) -> 0 | CE20: =SUM(CF20:CI20) -> 0 | CJ20: =SUM(CK20:CN20) -> 0 | CO20: =SUM(CP20:DD20)/2 -> 0 | CP20: =SUM(CQ20:CT20) -> 0 | CU20: =SUM(CV20:CY20) -> 0 | CZ20: =SUM(DA20:DD20) -> 0 | DE20: =SUM(DF20:EK20)/3 -> 0 | DF20: =SUM(DG20:DU20)/2 -> 0 | DG20: =SUM(DH20:DK20) -> 0 | DL20: =SUM(DM20:DP20) -> 0 | DQ20: =SUM(DR20:DU20) -> 0 | DV20: =SUM(DW20:EK20)/2 -> 0 | DW20: =SUM(DX20:EA20) -> 0 | EB20: =SUM(EC20:EF20) -> 0 | EG20: =SUM(EH20:EK20) -> 0 | EL20: =SUM(EM20:GZ20)/4 -> 0 | EM20: =SUM(EN20:FS20)/3 -> 0 | EN20: =SUM(EO20:FC20)/2 -> 0 | EO20: =SUM(EP20:ES20) -> 0 | ET20: =SUM(EU20:EX20) -> 0 | EY20: =SUM(EZ20:FC20) -> 0 | FD20: =SUM(FE20:FS20)/2 -> 0 | FE20: =SUM(FF20:FI20) -> 0 | FJ20: =SUM(FK20:FN20) -> 0 | FO20: =SUM(FP20:FS20) -> 0 | FT20: =SUM(FU20:GZ20)/3 -> 0 | FU20: =SUM(FV20:GJ20)/2 -> 0 | FV20: =SUM(FW20:FZ20) -> 0 | GA20: =SUM(GB20:GE20) -> 0 | GF20: =SUM(GG20:GJ20) -> 0 | GK20: =SUM(GL20:GZ20)/2 -> 0 | GL20: =SUM(GM20:GP20) -> 0 | GQ20: =SUM(GR20:GU20) -> 0 | GV20: =SUM(GW20:GZ20) -> 0
E21: Fakt | G21: =SUM(H21:GZ21)/5 -> 0 | H21: =SUM(I21:BV21)/4 -> 0 | I21: =SUM(J21:AO21)/3 -> 0 | J21: =SUM(K21:Y21)/2 -> 0 | K21: =SUM(L21:O21) -> 0 | P21: =SUM(Q21:T21) -> 0 | U21: =SUM(V21:Y21) -> 0 | Z21: =SUM(AA21:AO21)/2 -> 0 | AA21: =SUM(AB21:AE21) -> 0 | AF21: =SUM(AG21:AJ21) -> 0 | AK21: =SUM(AL21:AO21) -> 0 | AP21: =SUM(AQ21:BV21)/3 -> 0 | AQ21: =SUM(AR21:BF21)/2 -> 0 | AR21: =SUM(AS21:AV21) -> 0 | AW21: =SUM(AX21:BA21) -> 0 | BB21: =SUM(BC21:BF21) -> 0 | BG21: =SUM(BH21:BV21)/2 -> 0 | BH21: =SUM(BI21:BL21) -> 0 | BM21: =SUM(BN21:BQ21) -> 0 | BR21: =SUM(BS21:BV21) -> 0 | BW21: =SUM(BX21:EK21)/4 -> 0 | BX21: =SUM(BY21:DD21)/3 -> 0 | BY21: =SUM(BZ21:CN21)/2 -> 0 | BZ21: =SUM(CA21:CD21) -> 0 | CE21: =SUM(CF21:CI21) -> 0 | CJ21: =SUM(CK21:CN21) -> 0 | CO21: =SUM(CP21:DD21)/2 -> 0 | CP21: =SUM(CQ21:CT21) -> 0 | CU21: =SUM(CV21:CY21) -> 0 | CZ21: =SUM(DA21:DD21) -> 0 | DE21: =SUM(DF21:EK21)/3 -> 0 | DF21: =SUM(DG21:DU21)/2 -> 0 | DG21: =SUM(DH21:DK21) -> 0 | DL21: =SUM(DM21:DP21) -> 0 | DQ21: =SUM(DR21:DU21) -> 0 | DV21: =SUM(DW21:EK21)/2 -> 0 | DW21: =SUM(DX21:EA21) -> 0 | EB21: =SUM(EC21:EF21) -> 0 | EG21: =SUM(EH21:EK21) -> 0 | EL21: =SUM(EM21:GZ21)/4 -> 0 | EM21: =SUM(EN21:FS21)/3 -> 0 | EN21: =SUM(EO21:FC21)/2 -> 0 | EO21: =SUM(EP21:ES21) -> 0 | ET21: =SUM(EU21:EX21) -> 0 | EY21: =SUM(EZ21:FC21) -> 0 | FD21: =SUM(FE21:FS21)/2 -> 0 | FE21: =SUM(FF21:FI21) -> 0 | FJ21: =SUM(FK21:FN21) -> 0 | FO21: =SUM(FP21:FS21) -> 0 | FT21: =SUM(FU21:GZ21)/3 -> 0 | FU21: =SUM(FV21:GJ21)/2 -> 0 | FV21: =SUM(FW21:FZ21) -> 0 | GA21: =SUM(GB21:GE21) -> 0 | GF21: =SUM(GG21:GJ21) -> 0 | GK21: =SUM(GL21:GZ21)/2 -> 0 | GL21: =SUM(GM21:GP21) -> 0 | GQ21: =SUM(GR21:GU21) -> 0 | GV21: =SUM(GW21:GZ21) -> 0
C22: 2 | D22: [Metrika] | E22: Reja | G22: =SUM(H22:GZ22)/5 -> 0 | H22: =SUM(I22:BV22)/4 -> 0 | I22: =SUM(J22:AO22)/3 -> 0 | J22: =SUM(K22:Y22)/2 -> 0 | K22: =SUM(L22:O22) -> 0 | P22: =SUM(Q22:T22) -> 0 | U22: =SUM(V22:Y22) -> 0 | Z22: =SUM(AA22:AO22)/2 -> 0 | AA22: =SUM(AB22:AE22) -> 0 | AF22: =SUM(AG22:AJ22) -> 0 | AK22: =SUM(AL22:AO22) -> 0 | AP22: =SUM(AQ22:BV22)/3 -> 0 | AQ22: =SUM(AR22:BF22)/2 -> 0 | AR22: =SUM(AS22:AV22) -> 0 | AW22: =SUM(AX22:BA22) -> 0 | BB22: =SUM(BC22:BF22) -> 0 | BG22: =SUM(BH22:BV22)/2 -> 0 | BH22: =SUM(BI22:BL22) -> 0 | BM22: =SUM(BN22:BQ22) -> 0 | BR22: =SUM(BS22:BV22) -> 0 | BW22: =SUM(BX22:EK22)/4 -> 0 | BX22: =SUM(BY22:DD22)/3 -> 0 | BY22: =SUM(BZ22:CN22)/2 -> 0 | BZ22: =SUM(CA22:CD22) -> 0 | CE22: =SUM(CF22:CI22) -> 0 | CJ22: =SUM(CK22:CN22) -> 0 | CO22: =SUM(CP22:DD22)/2 -> 0 | CP22: =SUM(CQ22:CT22) -> 0 | CU22: =SUM(CV22:CY22) -> 0 | CZ22: =SUM(DA22:DD22) -> 0 | DE22: =SUM(DF22:EK22)/3 -> 0 | DF22: =SUM(DG22:DU22)/2 -> 0 | DG22: =SUM(DH22:DK22) -> 0 | DL22: =SUM(DM22:DP22) -> 0 | DQ22: =SUM(DR22:DU22) -> 0 | DV22: =SUM(DW22:EK22)/2 -> 0 | DW22: =SUM(DX22:EA22) -> 0 | EB22: =SUM(EC22:EF22) -> 0 | EG22: =SUM(EH22:EK22) -> 0 | EL22: =SUM(EM22:GZ22)/4 -> 0 | EM22: =SUM(EN22:FS22)/3 -> 0 | EN22: =SUM(EO22:FC22)/2 -> 0 | EO22: =SUM(EP22:ES22) -> 0 | ET22: =SUM(EU22:EX22) -> 0 | EY22: =SUM(EZ22:FC22) -> 0 | FD22: =SUM(FE22:FS22)/2 -> 0 | FE22: =SUM(FF22:FI22) -> 0 | FJ22: =SUM(FK22:FN22) -> 0 | FO22: =SUM(FP22:FS22) -> 0 | FT22: =SUM(FU22:GZ22)/3 -> 0 | FU22: =SUM(FV22:GJ22)/2 -> 0 | FV22: =SUM(FW22:FZ22) -> 0 | GA22: =SUM(GB22:GE22) -> 0 | GF22: =SUM(GG22:GJ22) -> 0 | GK22: =SUM(GL22:GZ22)/2 -> 0 | GL22: =SUM(GM22:GP22) -> 0 | GQ22: =SUM(GR22:GU22) -> 0 | GV22: =SUM(GW22:GZ22) -> 0
E23: Fakt | G23: =SUM(H23:GZ23)/5 -> 0 | H23: =SUM(I23:BV23)/4 -> 0 | I23: =SUM(J23:AO23)/3 -> 0 | J23: =SUM(K23:Y23)/2 -> 0 | K23: =SUM(L23:O23) -> 0 | P23: =SUM(Q23:T23) -> 0 | U23: =SUM(V23:Y23) -> 0 | Z23: =SUM(AA23:AO23)/2 -> 0 | AA23: =SUM(AB23:AE23) -> 0 | AF23: =SUM(AG23:AJ23) -> 0 | AK23: =SUM(AL23:AO23) -> 0 | AP23: =SUM(AQ23:BV23)/3 -> 0 | AQ23: =SUM(AR23:BF23)/2 -> 0 | AR23: =SUM(AS23:AV23) -> 0 | AW23: =SUM(AX23:BA23) -> 0 | BB23: =SUM(BC23:BF23) -> 0 | BG23: =SUM(BH23:BV23)/2 -> 0 | BH23: =SUM(BI23:BL23) -> 0 | BM23: =SUM(BN23:BQ23) -> 0 | BR23: =SUM(BS23:BV23) -> 0 | BW23: =SUM(BX23:EK23)/4 -> 0 | BX23: =SUM(BY23:DD23)/3 -> 0 | BY23: =SUM(BZ23:CN23)/2 -> 0 | BZ23: =SUM(CA23:CD23) -> 0 | CE23: =SUM(CF23:CI23) -> 0 | CJ23: =SUM(CK23:CN23) -> 0 | CO23: =SUM(CP23:DD23)/2 -> 0 | CP23: =SUM(CQ23:CT23) -> 0 | CU23: =SUM(CV23:CY23) -> 0 | CZ23: =SUM(DA23:DD23) -> 0 | DE23: =SUM(DF23:EK23)/3 -> 0 | DF23: =SUM(DG23:DU23)/2 -> 0 | DG23: =SUM(DH23:DK23) -> 0 | DL23: =SUM(DM23:DP23) -> 0 | DQ23: =SUM(DR23:DU23) -> 0 | DV23: =SUM(DW23:EK23)/2 -> 0 | DW23: =SUM(DX23:EA23) -> 0 | EB23: =SUM(EC23:EF23) -> 0 | EG23: =SUM(EH23:EK23) -> 0 | EL23: =SUM(EM23:GZ23)/4 -> 0 | EM23: =SUM(EN23:FS23)/3 -> 0 | EN23: =SUM(EO23:FC23)/2 -> 0 | EO23: =SUM(EP23:ES23) -> 0 | ET23: =SUM(EU23:EX23) -> 0 | EY23: =SUM(EZ23:FC23) -> 0 | FD23: =SUM(FE23:FS23)/2 -> 0 | FE23: =SUM(FF23:FI23) -> 0 | FJ23: =SUM(FK23:FN23) -> 0 | FO23: =SUM(FP23:FS23) -> 0 | FT23: =SUM(FU23:GZ23)/3 -> 0 | FU23: =SUM(FV23:GJ23)/2 -> 0 | FV23: =SUM(FW23:FZ23) -> 0 | GA23: =SUM(GB23:GE23) -> 0 | GF23: =SUM(GG23:GJ23) -> 0 | GK23: =SUM(GL23:GZ23)/2 -> 0 | GL23: =SUM(GM23:GP23) -> 0 | GQ23: =SUM(GR23:GU23) -> 0 | GV23: =SUM(GW23:GZ23) -> 0
C24: 3 | D24: [Metrika] | E24: Reja | G24: =SUM(H24:GZ24)/5 -> 0 | H24: =SUM(I24:BV24)/4 -> 0 | I24: =SUM(J24:AO24)/3 -> 0 | J24: =SUM(K24:Y24)/2 -> 0 | K24: =SUM(L24:O24) -> 0 | P24: =SUM(Q24:T24) -> 0 | U24: =SUM(V24:Y24) -> 0 | Z24: =SUM(AA24:AO24)/2 -> 0 | AA24: =SUM(AB24:AE24) -> 0 | AF24: =SUM(AG24:AJ24) -> 0 | AK24: =SUM(AL24:AO24) -> 0 | AP24: =SUM(AQ24:BV24)/3 -> 0 | AQ24: =SUM(AR24:BF24)/2 -> 0 | AR24: =SUM(AS24:AV24) -> 0 | AW24: =SUM(AX24:BA24) -> 0 | BB24: =SUM(BC24:BF24) -> 0 | BG24: =SUM(BH24:BV24)/2 -> 0 | BH24: =SUM(BI24:BL24) -> 0 | BM24: =SUM(BN24:BQ24) -> 0 | BR24: =SUM(BS24:BV24) -> 0 | BW24: =SUM(BX24:EK24)/4 -> 0 | BX24: =SUM(BY24:DD24)/3 -> 0 | BY24: =SUM(BZ24:CN24)/2 -> 0 | BZ24: =SUM(CA24:CD24) -> 0 | CE24: =SUM(CF24:CI24) -> 0 | CJ24: =SUM(CK24:CN24) -> 0 | CO24: =SUM(CP24:DD24)/2 -> 0 | CP24: =SUM(CQ24:CT24) -> 0 | CU24: =SUM(CV24:CY24) -> 0 | CZ24: =SUM(DA24:DD24) -> 0 | DE24: =SUM(DF24:EK24)/3 -> 0 | DF24: =SUM(DG24:DU24)/2 -> 0 | DG24: =SUM(DH24:DK24) -> 0 | DL24: =SUM(DM24:DP24) -> 0 | DQ24: =SUM(DR24:DU24) -> 0 | DV24: =SUM(DW24:EK24)/2 -> 0 | DW24: =SUM(DX24:EA24) -> 0 | EB24: =SUM(EC24:EF24) -> 0 | EG24: =SUM(EH24:EK24) -> 0 | EL24: =SUM(EM24:GZ24)/4 -> 0 | EM24: =SUM(EN24:FS24)/3 -> 0 | EN24: =SUM(EO24:FC24)/2 -> 0 | EO24: =SUM(EP24:ES24) -> 0 | ET24: =SUM(EU24:EX24) -> 0 | EY24: =SUM(EZ24:FC24) -> 0 | FD24: =SUM(FE24:FS24)/2 -> 0 | FE24: =SUM(FF24:FI24) -> 0 | FJ24: =SUM(FK24:FN24) -> 0 | FO24: =SUM(FP24:FS24) -> 0 | FT24: =SUM(FU24:GZ24)/3 -> 0 | FU24: =SUM(FV24:GJ24)/2 -> 0 | FV24: =SUM(FW24:FZ24) -> 0 | GA24: =SUM(GB24:GE24) -> 0 | GF24: =SUM(GG24:GJ24) -> 0 | GK24: =SUM(GL24:GZ24)/2 -> 0 | GL24: =SUM(GM24:GP24) -> 0 | GQ24: =SUM(GR24:GU24) -> 0 | GV24: =SUM(GW24:GZ24) -> 0
E25: Fakt | G25: =SUM(H25:GZ25)/5 -> 0 | H25: =SUM(I25:BV25)/4 -> 0 | I25: =SUM(J25:AO25)/3 -> 0 | J25: =SUM(K25:Y25)/2 -> 0 | K25: =SUM(L25:O25) -> 0 | P25: =SUM(Q25:T25) -> 0 | U25: =SUM(V25:Y25) -> 0 | Z25: =SUM(AA25:AO25)/2 -> 0 | AA25: =SUM(AB25:AE25) -> 0 | AF25: =SUM(AG25:AJ25) -> 0 | AK25: =SUM(AL25:AO25) -> 0 | AP25: =SUM(AQ25:BV25)/3 -> 0 | AQ25: =SUM(AR25:BF25)/2 -> 0 | AR25: =SUM(AS25:AV25) -> 0 | AW25: =SUM(AX25:BA25) -> 0 | BB25: =SUM(BC25:BF25) -> 0 | BG25: =SUM(BH25:BV25)/2 -> 0 | BH25: =SUM(BI25:BL25) -> 0 | BM25: =SUM(BN25:BQ25) -> 0 | BR25: =SUM(BS25:BV25) -> 0 | BW25: =SUM(BX25:EK25)/4 -> 0 | BX25: =SUM(BY25:DD25)/3 -> 0 | BY25: =SUM(BZ25:CN25)/2 -> 0 | BZ25: =SUM(CA25:CD25) -> 0 | CE25: =SUM(CF25:CI25) -> 0 | CJ25: =SUM(CK25:CN25) -> 0 | CO25: =SUM(CP25:DD25)/2 -> 0 | CP25: =SUM(CQ25:CT25) -> 0 | CU25: =SUM(CV25:CY25) -> 0 | CZ25: =SUM(DA25:DD25) -> 0 | DE25: =SUM(DF25:EK25)/3 -> 0 | DF25: =SUM(DG25:DU25)/2 -> 0 | DG25: =SUM(DH25:DK25) -> 0 | DL25: =SUM(DM25:DP25) -> 0 | DQ25: =SUM(DR25:DU25) -> 0 | DV25: =SUM(DW25:EK25)/2 -> 0 | DW25: =SUM(DX25:EA25) -> 0 | EB25: =SUM(EC25:EF25) -> 0 | EG25: =SUM(EH25:EK25) -> 0 | EL25: =SUM(EM25:GZ25)/4 -> 0 | EM25: =SUM(EN25:FS25)/3 -> 0 | EN25: =SUM(EO25:FC25)/2 -> 0 | EO25: =SUM(EP25:ES25) -> 0 | ET25: =SUM(EU25:EX25) -> 0 | EY25: =SUM(EZ25:FC25) -> 0 | FD25: =SUM(FE25:FS25)/2 -> 0 | FE25: =SUM(FF25:FI25) -> 0 | FJ25: =SUM(FK25:FN25) -> 0 | FO25: =SUM(FP25:FS25) -> 0 | FT25: =SUM(FU25:GZ25)/3 -> 0 | FU25: =SUM(FV25:GJ25)/2 -> 0 | FV25: =SUM(FW25:FZ25) -> 0 | GA25: =SUM(GB25:GE25) -> 0 | GF25: =SUM(GG25:GJ25) -> 0 | GK25: =SUM(GL25:GZ25)/2 -> 0 | GL25: =SUM(GM25:GP25) -> 0 | GQ25: =SUM(GR25:GU25) -> 0 | GV25: =SUM(GW25:GZ25) -> 0
C26: 4 | D26: [Metrika] | E26: Reja | G26: =SUM(H26:GZ26)/5 -> 0 | H26: =SUM(I26:BV26)/4 -> 0 | I26: =SUM(J26:AO26)/3 -> 0 | J26: =SUM(K26:Y26)/2 -> 0 | K26: =SUM(L26:O26) -> 0 | P26: =SUM(Q26:T26) -> 0 | U26: =SUM(V26:Y26) -> 0 | Z26: =SUM(AA26:AO26)/2 -> 0 | AA26: =SUM(AB26:AE26) -> 0 | AF26: =SUM(AG26:AJ26) -> 0 | AK26: =SUM(AL26:AO26) -> 0 | AP26: =SUM(AQ26:BV26)/3 -> 0 | AQ26: =SUM(AR26:BF26)/2 -> 0 | AR26: =SUM(AS26:AV26) -> 0 | AW26: =SUM(AX26:BA26) -> 0 | BB26: =SUM(BC26:BF26) -> 0 | BG26: =SUM(BH26:BV26)/2 -> 0 | BH26: =SUM(BI26:BL26) -> 0 | BM26: =SUM(BN26:BQ26) -> 0 | BR26: =SUM(BS26:BV26) -> 0 | BW26: =SUM(BX26:EK26)/4 -> 0 | BX26: =SUM(BY26:DD26)/3 -> 0 | BY26: =SUM(BZ26:CN26)/2 -> 0 | BZ26: =SUM(CA26:CD26) -> 0 | CE26: =SUM(CF26:CI26) -> 0 | CJ26: =SUM(CK26:CN26) -> 0 | CO26: =SUM(CP26:DD26)/2 -> 0 | CP26: =SUM(CQ26:CT26) -> 0 | CU26: =SUM(CV26:CY26) -> 0 | CZ26: =SUM(DA26:DD26) -> 0 | DE26: =SUM(DF26:EK26)/3 -> 0 | DF26: =SUM(DG26:DU26)/2 -> 0 | DG26: =SUM(DH26:DK26) -> 0 | DL26: =SUM(DM26:DP26) -> 0 | DQ26: =SUM(DR26:DU26) -> 0 | DV26: =SUM(DW26:EK26)/2 -> 0 | DW26: =SUM(DX26:EA26) -> 0 | EB26: =SUM(EC26:EF26) -> 0 | EG26: =SUM(EH26:EK26) -> 0 | EL26: =SUM(EM26:GZ26)/4 -> 0 | EM26: =SUM(EN26:FS26)/3 -> 0 | EN26: =SUM(EO26:FC26)/2 -> 0 | EO26: =SUM(EP26:ES26) -> 0 | ET26: =SUM(EU26:EX26) -> 0 | EY26: =SUM(EZ26:FC26) -> 0 | FD26: =SUM(FE26:FS26)/2 -> 0 | FE26: =SUM(FF26:FI26) -> 0 | FJ26: =SUM(FK26:FN26) -> 0 | FO26: =SUM(FP26:FS26) -> 0 | FT26: =SUM(FU26:GZ26)/3 -> 0 | FU26: =SUM(FV26:GJ26)/2 -> 0 | FV26: =SUM(FW26:FZ26) -> 0 | GA26: =SUM(GB26:GE26) -> 0 | GF26: =SUM(GG26:GJ26) -> 0 | GK26: =SUM(GL26:GZ26)/2 -> 0 | GL26: =SUM(GM26:GP26) -> 0 | GQ26: =SUM(GR26:GU26) -> 0 | GV26: =SUM(GW26:GZ26) -> 0
E27: Fakt | G27: =SUM(H27:GZ27)/5 -> 0 | H27: =SUM(I27:BV27)/4 -> 0 | I27: =SUM(J27:AO27)/3 -> 0 | J27: =SUM(K27:Y27)/2 -> 0 | K27: =SUM(L27:O27) -> 0 | P27: =SUM(Q27:T27) -> 0 | U27: =SUM(V27:Y27) -> 0 | Z27: =SUM(AA27:AO27)/2 -> 0 | AA27: =SUM(AB27:AE27) -> 0 | AF27: =SUM(AG27:AJ27) -> 0 | AK27: =SUM(AL27:AO27) -> 0 | AP27: =SUM(AQ27:BV27)/3 -> 0 | AQ27: =SUM(AR27:BF27)/2 -> 0 | AR27: =SUM(AS27:AV27) -> 0 | AW27: =SUM(AX27:BA27) -> 0 | BB27: =SUM(BC27:BF27) -> 0 | BG27: =SUM(BH27:BV27)/2 -> 0 | BH27: =SUM(BI27:BL27) -> 0 | BM27: =SUM(BN27:BQ27) -> 0 | BR27: =SUM(BS27:BV27) -> 0 | BW27: =SUM(BX27:EK27)/4 -> 0 | BX27: =SUM(BY27:DD27)/3 -> 0 | BY27: =SUM(BZ27:CN27)/2 -> 0 | BZ27: =SUM(CA27:CD27) -> 0 | CE27: =SUM(CF27:CI27) -> 0 | CJ27: =SUM(CK27:CN27) -> 0 | CO27: =SUM(CP27:DD27)/2 -> 0 | CP27: =SUM(CQ27:CT27) -> 0 | CU27: =SUM(CV27:CY27) -> 0 | CZ27: =SUM(DA27:DD27) -> 0 | DE27: =SUM(DF27:EK27)/3 -> 0 | DF27: =SUM(DG27:DU27)/2 -> 0 | DG27: =SUM(DH27:DK27) -> 0 | DL27: =SUM(DM27:DP27) -> 0 | DQ27: =SUM(DR27:DU27) -> 0 | DV27: =SUM(DW27:EK27)/2 -> 0 | DW27: =SUM(DX27:EA27) -> 0 | EB27: =SUM(EC27:EF27) -> 0 | EG27: =SUM(EH27:EK27) -> 0 | EL27: =SUM(EM27:GZ27)/4 -> 0 | EM27: =SUM(EN27:FS27)/3 -> 0 | EN27: =SUM(EO27:FC27)/2 -> 0 | EO27: =SUM(EP27:ES27) -> 0 | ET27: =SUM(EU27:EX27) -> 0 | EY27: =SUM(EZ27:FC27) -> 0 | FD27: =SUM(FE27:FS27)/2 -> 0 | FE27: =SUM(FF27:FI27) -> 0 | FJ27: =SUM(FK27:FN27) -> 0 | FO27: =SUM(FP27:FS27) -> 0 | FT27: =SUM(FU27:GZ27)/3 -> 0 | FU27: =SUM(FV27:GJ27)/2 -> 0 | FV27: =SUM(FW27:FZ27) -> 0 | GA27: =SUM(GB27:GE27) -> 0 | GF27: =SUM(GG27:GJ27) -> 0 | GK27: =SUM(GL27:GZ27)/2 -> 0 | GL27: =SUM(GM27:GP27) -> 0 | GQ27: =SUM(GR27:GU27) -> 0 | GV27: =SUM(GW27:GZ27) -> 0
B28: Moliya | C28: 1 | D28: [Metrika] | E28: Reja | G28: =SUM(H28:GZ28)/5 -> 0 | H28: =SUM(I28:BV28)/4 -> 0 | I28: =SUM(J28:AO28)/3 -> 0 | J28: =SUM(K28:Y28)/2 -> 0 | K28: =SUM(L28:O28) -> 0 | P28: =SUM(Q28:T28) -> 0 | U28: =SUM(V28:Y28) -> 0 | Z28: =SUM(AA28:AO28)/2 -> 0 | AA28: =SUM(AB28:AE28) -> 0 | AF28: =SUM(AG28:AJ28) -> 0 | AK28: =SUM(AL28:AO28) -> 0 | AP28: =SUM(AQ28:BV28)/3 -> 0 | AQ28: =SUM(AR28:BF28)/2 -> 0 | AR28: =SUM(AS28:AV28) -> 0 | AW28: =SUM(AX28:BA28) -> 0 | BB28: =SUM(BC28:BF28) -> 0 | BG28: =SUM(BH28:BV28)/2 -> 0 | BH28: =SUM(BI28:BL28) -> 0 | BM28: =SUM(BN28:BQ28) -> 0 | BR28: =SUM(BS28:BV28) -> 0 | BW28: =SUM(BX28:EK28)/4 -> 0 | BX28: =SUM(BY28:DD28)/3 -> 0 | BY28: =SUM(BZ28:CN28)/2 -> 0 | BZ28: =SUM(CA28:CD28) -> 0 | CE28: =SUM(CF28:CI28) -> 0 | CJ28: =SUM(CK28:CN28) -> 0 | CO28: =SUM(CP28:DD28)/2 -> 0 | CP28: =SUM(CQ28:CT28) -> 0 | CU28: =SUM(CV28:CY28) -> 0 | CZ28: =SUM(DA28:DD28) -> 0 | DE28: =SUM(DF28:EK28)/3 -> 0 | DF28: =SUM(DG28:DU28)/2 -> 0 | DG28: =SUM(DH28:DK28) -> 0 | DL28: =SUM(DM28:DP28) -> 0 | DQ28: =SUM(DR28:DU28) -> 0 | DV28: =SUM(DW28:EK28)/2 -> 0 | DW28: =SUM(DX28:EA28) -> 0 | EB28: =SUM(EC28:EF28) -> 0 | EG28: =SUM(EH28:EK28) -> 0 | EL28: =SUM(EM28:GZ28)/4 -> 0 | EM28: =SUM(EN28:FS28)/3 -> 0 | EN28: =SUM(EO28:FC28)/2 -> 0 | EO28: =SUM(EP28:ES28) -> 0 | ET28: =SUM(EU28:EX28) -> 0 | EY28: =SUM(EZ28:FC28) -> 0 | FD28: =SUM(FE28:FS28)/2 -> 0 | FE28: =SUM(FF28:FI28) -> 0 | FJ28: =SUM(FK28:FN28) -> 0 | FO28: =SUM(FP28:FS28) -> 0 | FT28: =SUM(FU28:GZ28)/3 -> 0 | FU28: =SUM(FV28:GJ28)/2 -> 0 | FV28: =SUM(FW28:FZ28) -> 0 | GA28: =SUM(GB28:GE28) -> 0 | GF28: =SUM(GG28:GJ28) -> 0 | GK28: =SUM(GL28:GZ28)/2 -> 0 | GL28: =SUM(GM28:GP28) -> 0 | GQ28: =SUM(GR28:GU28) -> 0 | GV28: =SUM(GW28:GZ28) -> 0
E29: Fakt | G29: =SUM(H29:GZ29)/5 -> 0 | H29: =SUM(I29:BV29)/4 -> 0 | I29: =SUM(J29:AO29)/3 -> 0 | J29: =SUM(K29:Y29)/2 -> 0 | K29: =SUM(L29:O29) -> 0 | P29: =SUM(Q29:T29) -> 0 | U29: =SUM(V29:Y29) -> 0 | Z29: =SUM(AA29:AO29)/2 -> 0 | AA29: =SUM(AB29:AE29) -> 0 | AF29: =SUM(AG29:AJ29) -> 0 | AK29: =SUM(AL29:AO29) -> 0 | AP29: =SUM(AQ29:BV29)/3 -> 0 | AQ29: =SUM(AR29:BF29)/2 -> 0 | AR29: =SUM(AS29:AV29) -> 0 | AW29: =SUM(AX29:BA29) -> 0 | BB29: =SUM(BC29:BF29) -> 0 | BG29: =SUM(BH29:BV29)/2 -> 0 | BH29: =SUM(BI29:BL29) -> 0 | BM29: =SUM(BN29:BQ29) -> 0 | BR29: =SUM(BS29:BV29) -> 0 | BW29: =SUM(BX29:EK29)/4 -> 0 | BX29: =SUM(BY29:DD29)/3 -> 0 | BY29: =SUM(BZ29:CN29)/2 -> 0 | BZ29: =SUM(CA29:CD29) -> 0 | CE29: =SUM(CF29:CI29) -> 0 | CJ29: =SUM(CK29:CN29) -> 0 | CO29: =SUM(CP29:DD29)/2 -> 0 | CP29: =SUM(CQ29:CT29) -> 0 | CU29: =SUM(CV29:CY29) -> 0 | CZ29: =SUM(DA29:DD29) -> 0 | DE29: =SUM(DF29:EK29)/3 -> 0 | DF29: =SUM(DG29:DU29)/2 -> 0 | DG29: =SUM(DH29:DK29) -> 0 | DL29: =SUM(DM29:DP29) -> 0 | DQ29: =SUM(DR29:DU29) -> 0 | DV29: =SUM(DW29:EK29)/2 -> 0 | DW29: =SUM(DX29:EA29) -> 0 | EB29: =SUM(EC29:EF29) -> 0 | EG29: =SUM(EH29:EK29) -> 0 | EL29: =SUM(EM29:GZ29)/4 -> 0 | EM29: =SUM(EN29:FS29)/3 -> 0 | EN29: =SUM(EO29:FC29)/2 -> 0 | EO29: =SUM(EP29:ES29) -> 0 | ET29: =SUM(EU29:EX29) -> 0 | EY29: =SUM(EZ29:FC29) -> 0 | FD29: =SUM(FE29:FS29)/2 -> 0 | FE29: =SUM(FF29:FI29) -> 0 | FJ29: =SUM(FK29:FN29) -> 0 | FO29: =SUM(FP29:FS29) -> 0 | FT29: =SUM(FU29:GZ29)/3 -> 0 | FU29: =SUM(FV29:GJ29)/2 -> 0 | FV29: =SUM(FW29:FZ29) -> 0 | GA29: =SUM(GB29:GE29) -> 0 | GF29: =SUM(GG29:GJ29) -> 0 | GK29: =SUM(GL29:GZ29)/2 -> 0 | GL29: =SUM(GM29:GP29) -> 0 | GQ29: =SUM(GR29:GU29) -> 0 | GV29: =SUM(GW29:GZ29) -> 0
C30: 2 | D30: [Metrika] | E30: Reja | G30: =SUM(H30:GZ30)/5 -> 0 | H30: =SUM(I30:BV30)/4 -> 0 | I30: =SUM(J30:AO30)/3 -> 0 | J30: =SUM(K30:Y30)/2 -> 0 | K30: =SUM(L30:O30) -> 0 | P30: =SUM(Q30:T30) -> 0 | U30: =SUM(V30:Y30) -> 0 | Z30: =SUM(AA30:AO30)/2 -> 0 | AA30: =SUM(AB30:AE30) -> 0 | AF30: =SUM(AG30:AJ30) -> 0 | AK30: =SUM(AL30:AO30) -> 0 | AP30: =SUM(AQ30:BV30)/3 -> 0 | AQ30: =SUM(AR30:BF30)/2 -> 0 | AR30: =SUM(AS30:AV30) -> 0 | AW30: =SUM(AX30:BA30) -> 0 | BB30: =SUM(BC30:BF30) -> 0 | BG30: =SUM(BH30:BV30)/2 -> 0 | BH30: =SUM(BI30:BL30) -> 0 | BM30: =SUM(BN30:BQ30) -> 0 | BR30: =SUM(BS30:BV30) -> 0 | BW30: =SUM(BX30:EK30)/4 -> 0 | BX30: =SUM(BY30:DD30)/3 -> 0 | BY30: =SUM(BZ30:CN30)/2 -> 0 | BZ30: =SUM(CA30:CD30) -> 0 | CE30: =SUM(CF30:CI30) -> 0 | CJ30: =SUM(CK30:CN30) -> 0 | CO30: =SUM(CP30:DD30)/2 -> 0 | CP30: =SUM(CQ30:CT30) -> 0 | CU30: =SUM(CV30:CY30) -> 0 | CZ30: =SUM(DA30:DD30) -> 0 | DE30: =SUM(DF30:EK30)/3 -> 0 | DF30: =SUM(DG30:DU30)/2 -> 0 | DG30: =SUM(DH30:DK30) -> 0 | DL30: =SUM(DM30:DP30) -> 0 | DQ30: =SUM(DR30:DU30) -> 0 | DV30: =SUM(DW30:EK30)/2 -> 0 | DW30: =SUM(DX30:EA30) -> 0 | EB30: =SUM(EC30:EF30) -> 0 | EG30: =SUM(EH30:EK30) -> 0 | EL30: =SUM(EM30:GZ30)/4 -> 0 | EM30: =SUM(EN30:FS30)/3 -> 0 | EN30: =SUM(EO30:FC30)/2 -> 0 | EO30: =SUM(EP30:ES30) -> 0 | ET30: =SUM(EU30:EX30) -> 0 | EY30: =SUM(EZ30:FC30) -> 0 | FD30: =SUM(FE30:FS30)/2 -> 0 | FE30: =SUM(FF30:FI30) -> 0 | FJ30: =SUM(FK30:FN30) -> 0 | FO30: =SUM(FP30:FS30) -> 0 | FT30: =SUM(FU30:GZ30)/3 -> 0 | FU30: =SUM(FV30:GJ30)/2 -> 0 | FV30: =SUM(FW30:FZ30) -> 0 | GA30: =SUM(GB30:GE30) -> 0 | GF30: =SUM(GG30:GJ30) -> 0 | GK30: =SUM(GL30:GZ30)/2 -> 0 | GL30: =SUM(GM30:GP30) -> 0 | GQ30: =SUM(GR30:GU30) -> 0 | GV30: =SUM(GW30:GZ30) -> 0
E31: Fakt | G31: =SUM(H31:GZ31)/5 -> 0 | H31: =SUM(I31:BV31)/4 -> 0 | I31: =SUM(J31:AO31)/3 -> 0 | J31: =SUM(K31:Y31)/2 -> 0 | K31: =SUM(L31:O31) -> 0 | P31: =SUM(Q31:T31) -> 0 | U31: =SUM(V31:Y31) -> 0 | Z31: =SUM(AA31:AO31)/2 -> 0 | AA31: =SUM(AB31:AE31) -> 0 | AF31: =SUM(AG31:AJ31) -> 0 | AK31: =SUM(AL31:AO31) -> 0 | AP31: =SUM(AQ31:BV31)/3 -> 0 | AQ31: =SUM(AR31:BF31)/2 -> 0 | AR31: =SUM(AS31:AV31) -> 0 | AW31: =SUM(AX31:BA31) -> 0 | BB31: =SUM(BC31:BF31) -> 0 | BG31: =SUM(BH31:BV31)/2 -> 0 | BH31: =SUM(BI31:BL31) -> 0 | BM31: =SUM(BN31:BQ31) -> 0 | BR31: =SUM(BS31:BV31) -> 0 | BW31: =SUM(BX31:EK31)/4 -> 0 | BX31: =SUM(BY31:DD31)/3 -> 0 | BY31: =SUM(BZ31:CN31)/2 -> 0 | BZ31: =SUM(CA31:CD31) -> 0 | CE31: =SUM(CF31:CI31) -> 0 | CJ31: =SUM(CK31:CN31) -> 0 | CO31: =SUM(CP31:DD31)/2 -> 0 | CP31: =SUM(CQ31:CT31) -> 0 | CU31: =SUM(CV31:CY31) -> 0 | CZ31: =SUM(DA31:DD31) -> 0 | DE31: =SUM(DF31:EK31)/3 -> 0 | DF31: =SUM(DG31:DU31)/2 -> 0 | DG31: =SUM(DH31:DK31) -> 0 | DL31: =SUM(DM31:DP31) -> 0 | DQ31: =SUM(DR31:DU31) -> 0 | DV31: =SUM(DW31:EK31)/2 -> 0 | DW31: =SUM(DX31:EA31) -> 0 | EB31: =SUM(EC31:EF31) -> 0 | EG31: =SUM(EH31:EK31) -> 0 | EL31: =SUM(EM31:GZ31)/4 -> 0 | EM31: =SUM(EN31:FS31)/3 -> 0 | EN31: =SUM(EO31:FC31)/2 -> 0 | EO31: =SUM(EP31:ES31) -> 0 | ET31: =SUM(EU31:EX31) -> 0 | EY31: =SUM(EZ31:FC31) -> 0 | FD31: =SUM(FE31:FS31)/2 -> 0 | FE31: =SUM(FF31:FI31) -> 0 | FJ31: =SUM(FK31:FN31) -> 0 | FO31: =SUM(FP31:FS31) -> 0 | FT31: =SUM(FU31:GZ31)/3 -> 0 | FU31: =SUM(FV31:GJ31)/2 -> 0 | FV31: =SUM(FW31:FZ31) -> 0 | GA31: =SUM(GB31:GE31) -> 0 | GF31: =SUM(GG31:GJ31) -> 0 | GK31: =SUM(GL31:GZ31)/2 -> 0 | GL31: =SUM(GM31:GP31) -> 0 | GQ31: =SUM(GR31:GU31) -> 0 | GV31: =SUM(GW31:GZ31) -> 0
C32: 3 | D32: [Metrika] | E32: Reja | G32: =SUM(H32:GZ32)/5 -> 0 | H32: =SUM(I32:BV32)/4 -> 0 | I32: =SUM(J32:AO32)/3 -> 0 | J32: =SUM(K32:Y32)/2 -> 0 | K32: =SUM(L32:O32) -> 0 | P32: =SUM(Q32:T32) -> 0 | U32: =SUM(V32:Y32) -> 0 | Z32: =SUM(AA32:AO32)/2 -> 0 | AA32: =SUM(AB32:AE32) -> 0 | AF32: =SUM(AG32:AJ32) -> 0 | AK32: =SUM(AL32:AO32) -> 0 | AP32: =SUM(AQ32:BV32)/3 -> 0 | AQ32: =SUM(AR32:BF32)/2 -> 0 | AR32: =SUM(AS32:AV32) -> 0 | AW32: =SUM(AX32:BA32) -> 0 | BB32: =SUM(BC32:BF32) -> 0 | BG32: =SUM(BH32:BV32)/2 -> 0 | BH32: =SUM(BI32:BL32) -> 0 | BM32: =SUM(BN32:BQ32) -> 0 | BR32: =SUM(BS32:BV32) -> 0 | BW32: =SUM(BX32:EK32)/4 -> 0 | BX32: =SUM(BY32:DD32)/3 -> 0 | BY32: =SUM(BZ32:CN32)/2 -> 0 | BZ32: =SUM(CA32:CD32) -> 0 | CE32: =SUM(CF32:CI32) -> 0 | CJ32: =SUM(CK32:CN32) -> 0 | CO32: =SUM(CP32:DD32)/2 -> 0 | CP32: =SUM(CQ32:CT32) -> 0 | CU32: =SUM(CV32:CY32) -> 0 | CZ32: =SUM(DA32:DD32) -> 0 | DE32: =SUM(DF32:EK32)/3 -> 0 | DF32: =SUM(DG32:DU32)/2 -> 0 | DG32: =SUM(DH32:DK32) -> 0 | DL32: =SUM(DM32:DP32) -> 0 | DQ32: =SUM(DR32:DU32) -> 0 | DV32: =SUM(DW32:EK32)/2 -> 0 | DW32: =SUM(DX32:EA32) -> 0 | EB32: =SUM(EC32:EF32) -> 0 | EG32: =SUM(EH32:EK32) -> 0 | EL32: =SUM(EM32:GZ32)/4 -> 0 | EM32: =SUM(EN32:FS32)/3 -> 0 | EN32: =SUM(EO32:FC32)/2 -> 0 | EO32: =SUM(EP32:ES32) -> 0 | ET32: =SUM(EU32:EX32) -> 0 | EY32: =SUM(EZ32:FC32) -> 0 | FD32: =SUM(FE32:FS32)/2 -> 0 | FE32: =SUM(FF32:FI32) -> 0 | FJ32: =SUM(FK32:FN32) -> 0 | FO32: =SUM(FP32:FS32) -> 0 | FT32: =SUM(FU32:GZ32)/3 -> 0 | FU32: =SUM(FV32:GJ32)/2 -> 0 | FV32: =SUM(FW32:FZ32) -> 0 | GA32: =SUM(GB32:GE32) -> 0 | GF32: =SUM(GG32:GJ32) -> 0 | GK32: =SUM(GL32:GZ32)/2 -> 0 | GL32: =SUM(GM32:GP32) -> 0 | GQ32: =SUM(GR32:GU32) -> 0 | GV32: =SUM(GW32:GZ32) -> 0
E33: Fakt | G33: =SUM(H33:GZ33)/5 -> 0 | H33: =SUM(I33:BV33)/4 -> 0 | I33: =SUM(J33:AO33)/3 -> 0 | J33: =SUM(K33:Y33)/2 -> 0 | K33: =SUM(L33:O33) -> 0 | U33: =SUM(V33:Y33) -> 0 | Z33: =SUM(AA33:AO33)/2 -> 0 | AA33: =SUM(AB33:AE33) -> 0 | AK33: =SUM(AL33:AO33) -> 0 | AP33: =SUM(AQ33:BV33)/3 -> 0 | AQ33: =SUM(AR33:BF33)/2 -> 0 | AR33: =SUM(AS33:AV33) -> 0 | BB33: =SUM(BC33:BF33) -> 0 | BG33: =SUM(BH33:BV33)/2 -> 0 | BH33: =SUM(BI33:BL33) -> 0 | BR33: =SUM(BS33:BV33) -> 0 | BW33: =SUM(BX33:EK33)/4 -> 0 | BX33: =SUM(BY33:DD33)/3 -> 0 | BY33: =SUM(BZ33:CN33)/2 -> 0 | BZ33: =SUM(CA33:CD33) -> 0 | CJ33: =SUM(CK33:CN33) -> 0 | CO33: =SUM(CP33:DD33)/2 -> 0 | CP33: =SUM(CQ33:CT33) -> 0 | CZ33: =SUM(DA33:DD33) -> 0 | DE33: =SUM(DF33:EK33)/3 -> 0 | DF33: =SUM(DG33:DU33)/2 -> 0 | DG33: =SUM(DH33:DK33) -> 0 | DQ33: =SUM(DR33:DU33) -> 0 | DV33: =SUM(DW33:EK33)/2 -> 0 | DW33: =SUM(DX33:EA33) -> 0 | EG33: =SUM(EH33:EK33) -> 0 | EL33: =SUM(EM33:GZ33)/4 -> 0 | EM33: =SUM(EN33:FS33)/3 -> 0 | EN33: =SUM(EO33:FC33)/2 -> 0 | EO33: =SUM(EP33:ES33) -> 0 | EY33: =SUM(EZ33:FC33) -> 0 | FD33: =SUM(FE33:FS33)/2 -> 0 | FE33: =SUM(FF33:FI33) -> 0 | FO33: =SUM(FP33:FS33) -> 0 | FT33: =SUM(FU33:GZ33)/3 -> 0 | FU33: =SUM(FV33:GJ33)/2 -> 0 | FV33: =SUM(FW33:FZ33) -> 0 | GF33: =SUM(GG33:GJ33) -> 0 | GK33: =SUM(GL33:GZ33)/2 -> 0 | GL33: =SUM(GM33:GP33) -> 0 | GV33: =SUM(GW33:GZ33) -> 0

Sheet Foiz
G2: 3 yillik
G3: SUM | H3: Yillik 1 | BW3: Yillik 2 | EL3: Yillik 3
H4: SUM | I4: Yarim yillik 1 | AP4: Yarim yillik 2 | BW4: SUM | BX4: Yarim yillik 3 | DE4: Yarim yillik 4 | EL4: SUM | EM4: Yarim yillik 5 | FT4: Yarim yillik 6
I5: SUM | J5: Chorak 1 | Z5: Chorak 2 | AP5: SUM | AQ5: Chorak 3 | BG5: Chorak 4 | BX5: SUM | BY5: Chorak 5 | CO5: Chorak 6 | DE5: SUM | DF5: Chorak 7 | DV5: Chorak 8 | EM5: SUM | EN5: Chorak 9 | FD5: Chorak 10 | FT5: SUM | FU5: Chorak 11 | GK5: Chorak 12
J6: SUM | K6: Oy 1 | P6: Oy 2 | U6: Oy 3 | Z6: SUM | AA6: Oy 4 | AF6: Oy 5 | AK6: Oy 6 | AQ6: SUM | AR6: Oy 7 | AW6: Oy 8 | BB6: Oy 9 | BG6: SUM | BH6: Oy 10 | BM6: Oy 11 | BR6: Oy 12 | BY6: SUM | BZ6: Oy 13 | CE6: Oy 14 | CJ6: Oy 15 | CO6: SUM | CP6: Oy 16 | CU6: Oy 17 | CZ6: Oy 18 | DF6: SUM | DG6: Oy 19 | DL6: Oy 20 | DQ6: Oy 21 | DV6: SUM | DW6: Oy 22 | EB6: Oy 23 | EG6: Oy 24 | EN6: SUM | EO6: Oy 25 | ET6: Oy 26 | EY6: Oy 27 | FD6: SUM | FE6: Oy 28 | FJ6: Oy 29 | FO6: Oy 30 | FU6: SUM | FV6: Oy 31 | GA6: Oy 32 | GF6: Oy 33 | GK6: SUM | GL6: Oy 34 | GQ6: Oy 35 | GV6: Oy 36
D7: Metrika (ko'rsatkichlar) | G7: 3 yillik | H7: Yillik 1 | I7: Yarim yillik 1 | J7: Chorak 1 | K7: Oy 1 | L7: Hafta 1 | M7: Hafta 2 | N7: Hafta 3 | O7: Hafta 4 | P7: Oy 2 | Q7: Hafta 5 | R7: Hafta 6 | S7: Hafta 7 | T7: Hafta 8 | U7: Oy 3 | V7: Hafta 9 | W7: Hafta 10 | X7: Hafta 11 | Y7: Hafta 12 | Z7: Chorak 2 | AA7: Oy 4 | AB7: Hafta 13 | AC7: Hafta 14 | AD7: Hafta 15 | AE7: Hafta 16 | AF7: Oy 5 | AG7: Hafta 17 | AH7: Hafta 18 | AI7: Hafta 19 | AJ7: Hafta 20 | AK7: Oy 6 | AL7: Hafta 21 | AM7: Hafta 22 | AN7: Hafta 23 | AO7: Hafta 24 | AP7: Yarim yillik 2 | AQ7: Chorak 3 | AR7: Oy 7 | AS7: Hafta 25 | AT7: Hafta 26 | AU7: Hafta 27 | AV7: Hafta 28 | AW7: Oy 8 | AX7: Hafta 29 | AY7: Hafta 30 | AZ7: Hafta 31 | BA7: Hafta 32 | BB7: Oy 9 | BC7: Hafta 33 | BD7: Hafta 34 | BE7: Hafta 35 | BF7: Hafta 36 | BG7: Chorak 4 | BH7: Oy 10 | BI7: Hafta 37 | BJ7: Hafta 38 | BK7: Hafta 39 | BL7: Hafta 40 | BM7: Oy 11 | BN7: Hafta 41 | BO7: Hafta 42 | BP7: Hafta 43 | BQ7: Hafta 44 | BR7: Oy 12 | BS7: Hafta 45 | BT7: Hafta 46 | BU7: Hafta 47 | BV7: Hafta 48 | BW7: Yillik 2 | BX7: Yarim yillik 3 | BY7: Chorak 5 | BZ7: Oy 13 | CA7: Hafta 49 | CB7: Hafta 50 | CC7: Hafta 51 | CD7: Hafta 52 | CE7: Oy 14 | CF7: Hafta 53 | CG7: Hafta 54 | CH7: Hafta 55 | CI7: Hafta 56 | CJ7: Oy 15 | CK7: Hafta 57 | CL7: Hafta 58 | CM7: Hafta 59 | CN7: Hafta 60 | CO7: Chorak 6 | CP7: Oy 16 | CQ7: Hafta 61 | CR7: Hafta 62 | CS7: Hafta 63 | CT7: Hafta 64 | CU7: Oy 17 | CV7: Hafta 65 | CW7: Hafta 66 | CX7: Hafta 67 | CY7: Hafta 68 | CZ7: Oy 18 | DA7: Hafta 69 | DB7: Hafta 70 | DC7: Hafta 71 | DD7: Hafta 72 | DE7: Yarim yillik 4 | DF7: Chorak 7 | DG7: Oy 19 | DH7: Hafta 73 | DI7: Hafta 74 | DJ7: Hafta 75 | DK7: Hafta 76 | DL7: Oy 20 | DM7: Hafta 77 | DN7: Hafta 78 | DO7: Hafta 79 | DP7: Hafta 80 | DQ7: Oy 21 | DR7: Hafta 81 | DS7: Hafta 82 | DT7: Hafta 83 | DU7: Hafta 84 | DV7: Chorak 8 | DW7: Oy 22 | DX7: Hafta 85 | DY7: Hafta 86 | DZ7: Hafta 87 | EA7: Hafta 88 | EB7: Oy 23 | EC7: Hafta 89 | ED7: Hafta 90 | EE7: Hafta 91 | EF7: Hafta 92 | EG7: Oy 24 | EH7: Hafta 93 | EI7: Hafta 94 | EJ7: Hafta 95 | EK7: Hafta 96 | EL7: Yillik 3 | EM7: Yarim yillik 5 | EN7: Chorak 9 | EO7: Oy 25 | EP7: Hafta 97 | EQ7: Hafta 98 | ER7: Hafta 99 | ES7: Hafta 100 | ET7: Oy 26 | EU7: Hafta 101 | EV7: Hafta 102 | EW7: Hafta 103 | EX7: Hafta 104 | EY7: Oy 27 | EZ7: Hafta 105 | FA7: Hafta 106 | FB7: Hafta 107 | FC7: Hafta 108 | FD7: Chorak 10 | FE7: Oy 28 | FF7: Hafta 109 | FG7: Hafta 110 | FH7: Hafta 111 | FI7: Hafta 112 | FJ7: Oy 29 | FK7: Hafta 113 | FL7: Hafta 114 | FM7: Hafta 115 | FN7: Hafta 116 | FO7: Oy 30 | FP7: Hafta 117 | FQ7: Hafta 118 | FR7: Hafta 119 | FS7: Hafta 120 | FT7: Yarim yillik 6 | FU7: Chorak 11 | FV7: Oy 31 | FW7: Hafta 121 | FX7: Hafta 122 | FY7: Hafta 123 | FZ7: Hafta 124 | GA7: Oy 32 | GB7: Hafta 125 | GC7: Hafta 126 | GD7: Hafta 127 | GE7: Hafta 128 | GF7: Oy 33 | GG7: Hafta 129 | GH7: Hafta 130 | GI7: Hafta 131 | GJ7: Hafta 132 | GK7: Chorak 12 | GL7: Oy 34 | GM7: Hafta 133 | GN7: Hafta 134 | GO7: Hafta 135 | GP7: Hafta 136 | GQ7: Oy 35 | GR7: Hafta 137 | GS7: Hafta 138 | GT7: Hafta 139 | GU7: Hafta 140 | GV7: Oy 36 | GW7: Hafta 141 | GX7: Hafta 142 | GY7: Hafta 143 | GZ7: Hafta 144
B8: Marketing | C8: 1 | D8: [Metrika] | E8: Reja | G8: =Metrika!G9/Metrika!G8 -> #DIV/0! | H8: =Metrika!H9/Metrika!H8 -> #DIV/0! | I8: =Metrika!I9/Metrika!I8 -> #DIV/0! | J8: =Metrika!J9/Metrika!J8 -> #DIV/0! | K8: =Metrika!K9/Metrika!K8 -> #DIV/0! | L8: =Metrika!L9/Metrika!L8 -> #DIV/0! | M8: =Metrika!M9/Metrika!M8 -> #DIV/0! | N8: =Metrika!N9/Metrika!N8 -> #DIV/0! | ... GZ8: =Metrika!GZ9/Metrika!GZ8 -> #DIV/0!
E9: Fakt
C10: 2 | D10: [Metrika] | E10: Reja | G10: =Metrika!G11/Metrika!G10 -> #DIV/0! | H10: =Metrika!H11/Metrika!H10 -> #DIV/0! | I10: =Metrika!I11/Metrika!I10 -> #DIV/0! | J10: =Metrika!J11/Metrika!J10 -> #DIV/0! | K10: =Metrika!K11/Metrika!K10 -> #DIV/0! | L10: =Metrika!L11/Metrika!L10 -> #DIV/0! | M10: =Metrika!M11/Metrika!M10 -> #DIV/0! | N10: =Metrika!N11/Metrika!N10 -> #DIV/0! | ... GZ10: =Metrika!GZ11/Metrika!GZ10 -> #DIV/0!
E11: Fakt
C12: 3 | D12: [Metrika] | E12: Reja | G12: =Metrika!G13/Metrika!G12 -> #DIV/0! | H12: =Metrika!H13/Metrika!H12 -> #DIV/0! | I12: =Metrika!I13/Metrika!I12 -> #DIV/0! | J12: =Metrika!J13/Metrika!J12 -> #DIV/0! | K12: =Metrika!K13/Metrika!K12 -> #DIV/0! | L12: =Metrika!L13/Metrika!L12 -> #DIV/0! | M12: =Metrika!M13/Metrika!M12 -> #DIV/0! | N12: =Metrika!N13/Metrika!N12 -> #DIV/0! | ... GZ12: =Metrika!GZ13/Metrika!GZ12 -> #DIV/0!
E13: Fakt
B14: Sotuv | C14: 1 | D14: [Metrika] | E14: Reja | G14: =Metrika!G15/Metrika!G14 -> #DIV/0! | H14: =Metrika!H15/Metrika!H14 -> #DIV/0! | I14: =Metrika!I15/Metrika!I14 -> #DIV/0! | J14: =Metrika!J15/Metrika!J14 -> #DIV/0! | K14: =Metrika!K15/Metrika!K14 -> #DIV/0! | L14: =Metrika!L15/Metrika!L14 -> #DIV/0! | M14: =Metrika!M15/Metrika!M14 -> #DIV/0! | N14: =Metrika!N15/Metrika!N14 -> #DIV/0! | ... GZ14: =Metrika!GZ15/Metrika!GZ14 -> #DIV/0!
E15: Fakt
C16: 2 | D16: [Metrika] | E16: Reja | G16: =Metrika!G17/Metrika!G16 -> #DIV/0! | H16: =Metrika!H17/Metrika!H16 -> #DIV/0! | I16: =Metrika!I17/Metrika!I16 -> #DIV/0! | J16: =Metrika!J17/Metrika!J16 -> #DIV/0! | K16: =Metrika!K17/Metrika!K16 -> #DIV/0! | L16: =Metrika!L17/Metrika!L16 -> #DIV/0! | M16: =Metrika!M17/Metrika!M16 -> #DIV/0! | N16: =Metrika!N17/Metrika!N16 -> #DIV/0! | ... GZ16: =Metrika!GZ17/Metrika!GZ16 -> #DIV/0!
E17: Fakt
C18: 3 | D18: [Metrika] | E18: Reja | G18: =Metrika!G19/Metrika!G18 -> #DIV/0! | H18: =Metrika!H19/Metrika!H18 -> #DIV/0! | I18: =Metrika!I19/Metrika!I18 -> #DIV/0! | J18: =Metrika!J19/Metrika!J18 -> #DIV/0! | K18: =Metrika!K19/Metrika!K18 -> #DIV/0! | L18: =Metrika!L19/Metrika!L18 -> #DIV/0! | M18: =Metrika!M19/Metrika!M18 -> #DIV/0! | N18: =Metrika!N19/Metrika!N18 -> #DIV/0! | ... GZ18: =Metrika!GZ19/Metrika!GZ18 -> #DIV/0!
E19: Fakt
B20: Product | C20: 1 | D20: [Metrika] | E20: Reja | G20: =Metrika!G21/Metrika!G20 -> #DIV/0! | H20: =Metrika!H21/Metrika!H20 -> #DIV/0! | I20: =Metrika!I21/Metrika!I20 -> #DIV/0! | J20: =Metrika!J21/Metrika!J20 -> #DIV/0! | K20: =Metrika!K21/Metrika!K20 -> #DIV/0! | L20: =Metrika!L21/Metrika!L20 -> #DIV/0! | M20: =Metrika!M21/Metrika!M20 -> #DIV/0! | N20: =Metrika!N21/Metrika!N20 -> #DIV/0! | ... GZ20: =Metrika!GZ21/Metrika!GZ20 -> #DIV/0!
E21: Fakt
C22: 2 | D22: [Metrika] | E22: Reja | G22: =Metrika!G23/Metrika!G22 -> #DIV/0! | H22: =Metrika!H23/Metrika!H22 -> #DIV/0! | I22: =Metrika!I23/Metrika!I22 -> #DIV/0! | J22: =Metrika!J23/Metrika!J22 -> #DIV/0! | K22: =Metrika!K23/Metrika!K22 -> #DIV/0! | L22: =Metrika!L23/Metrika!L22 -> #DIV/0! | M22: =Metrika!M23/Metrika!M22 -> #DIV/0! | N22: =Metrika!N23/Metrika!N22 -> #DIV/0! | ... GZ22: =Metrika!GZ23/Metrika!GZ22 -> #DIV/0!
E23: Fakt
C24: 3 | D24: [Metrika] | E24: Reja | G24: =Metrika!G25/Metrika!G24 -> #DIV/0! | H24: =Metrika!H25/Metrika!H24 -> #DIV/0! | I24: =Metrika!I25/Metrika!I24 -> #DIV/0! | J24: =Metrika!J25/Metrika!J24 -> #DIV/0! | K24: =Metrika!K25/Metrika!K24 -> #DIV/0! | L24: =Metrika!L25/Metrika!L24 -> #DIV/0! | M24: =Metrika!M25/Metrika!M24 -> #DIV/0! | N24: =Metrika!N25/Metrika!N24 -> #DIV/0! | ... GZ24: =Metrika!GZ25/Metrika!GZ24 -> #DIV/0!
E25: Fakt
C26: 4 | D26: [Metrika] | E26: Reja | G26: =Metrika!G27/Metrika!G26 -> #DIV/0! | H26: =Metrika!H27/Metrika!H26 -> #DIV/0! | I26: =Metrika!I27/Metrika!I26 -> #DIV/0! | J26: =Metrika!J27/Metrika!J26 -> #DIV/0! | K26: =Metrika!K27/Metrika!K26 -> #DIV/0! | L26: =Metrika!L27/Metrika!L26 -> #DIV/0! | M26: =Metrika!M27/Metrika!M26 -> #DIV/0! | N26: =Metrika!N27/Metrika!N26 -> #DIV/0! | ... GZ26: =Metrika!GZ27/Metrika!GZ26 -> #DIV/0!
E27: Fakt
B28: Moliya | C28: 1 | D28: [Metrika] | E28: Reja | G28: =Metrika!G29/Metrika!G28 -> #DIV/0! | H28: =Metrika!H29/Metrika!H28 -> #DIV/0! | I28: =Metrika!I29/Metrika!I28 -> #DIV/0! | J28: =Metrika!J29/Metrika!J28 -> #DIV/0! | K28: =Metrika!K29/Metrika!K28 -> #DIV/0! | L28: =Metrika!L29/Metrika!L28 -> #DIV/0! | M28: =Metrika!M29/Metrika!M28 -> #DIV/0! | N28: =Metrika!N29/Metrika!N28 -> #DIV/0! | ... GZ28: =Metrika!GZ29/Metrika!GZ28 -> #DIV/0!
E29: Fakt
